Workbook

Sheet 伤害计算
B2: PS: 加攻, 减防, 弱点区的属性均填不含场内白值加成的初始白值 | S2: 便捷偏向计算 | Z2: 便捷od计算 | AH2: 加权破坏计算(打的时候未满破坏时用) hit往下填分布
Z3: 原始hit | AA3: 附加hit | AB3: 固定od% | AC3: 耳环系数 | AD3: 耳环实际系数 | AE3: od% | AF3: od hit | AH3: 原始/附加hit | AI3: hit分布 | AJ3: 技能dr | AK3: 破坏加成 | AL3: 初始dr | AM3: bossdr | AN3: maxdr | AO3: 加权破坏
C4: PS：模型请填写实际伤害模型，特殊为奏，吹雪的dp加伤(奏只有1.25)，弱点不包含1，类型为单体0，群体1 | S4: 力 | Z4: 5 | AB4: 30 | AC4: 15 | AD4: ==IF(Z4>9,AC4,IF(Z4=0,5,IF(AC4=0,0,((Z4-1)/9*(AC4-5)+5))))/100+1 -> 1.0944444 | AE4: ==(ROUNDDOWN(AB4*AD4,2)+(Z4+AA4)*ROUNDDOWN(AD4*2.5,2)) -> 46.48 | AF4: ==AE4*0.4 -> 18.592 | AH4: 原始 | AI4: 0.05 | AJ4: 18.75 | AK4: 1.3 | AL4: 5.483 | AM4: 7 | AN4: 8 | AO4: ==SUM(AK5:AK100)/(1+SUMIF(AH5:AH100,"附加",AI5:AI100)) -> 7.2939317
C5: sp | D5: 类型 | E5: 技能等级 | F5: 偏向 | G5: token | H5: 特殊 | I5: 宝珠 | J5: 基础差值 | K5: 白值加成 | L5: 当前加权（填写时自带士气骇入，暴击时骇入+50，不要+100） | M5: 敌方属性 | N5: 是否暴击（暴击1，不暴击0） | O5: 武器弱点 | P5: 属性弱点 | Q5: 技能hit数 | S5: 灵 | AB5: 30 | AC5: 15 | AD5: ==IF(Z5>9,AC5,IF(Z5=0,5,IF(AC5=0,0,((Z5-1)/9*(AC5-5)+5))))/100+1 -> 1.05 | AE5: ==(ROUNDDOWN(AB5*AD5,2)+(Z5+AA5)*ROUNDDOWN(AD5*2.5,2)) -> 31.5 | AF5: ==AE5*0.4 -> 12.6 | AH5: 原始 | AI5: 0.05 | AJ5: ==AL$4 -> 5.483 | AK5: ==AI5*AJ5 -> 0.27415
E6: 10 | F6: 1.5 | G6: 1 | H6: 1.25 | I6: 5 | J6: 155 | M6: 770 | N6: 1 | O6: 0 | P6: 1.5 | Q6: 3 | S6: 智 | AB6: 30 | AC6: 15 | AD6: ==IF(Z6>9,AC6,IF(Z6=0,5,IF(AC6=0,0,((Z6-1)/9*(AC6-5)+5))))/100+1 -> 1.05 | AE6: ==(ROUNDDOWN(AB6*AD6,2)+(Z6+AA6)*ROUNDDOWN(AD6*2.5,2)) -> 31.5 | AF6: ==AE6*0.4 -> 12.6 | AH6: 原始 | AI6: 0.05 | AJ6: ==MIN(AN$4,AJ5+IF(AH6="原始",$AJ$4/COUNTIF($AH$5:$AH$100,"原始")*$AM$4/100*$AK$4,AI6*$AJ$4*$AM$4/100*$AK$4)) -> 5.6725833 | AK6: ==AI6*AJ6 -> 0.28362917
K7: 有-100的话请在这+50 | S7: 运 | AB7: 30 | AC7: 15 | AD7: ==IF(Z7>9,AC7,IF(Z7=0,5,IF(AC7=0,0,((Z7-1)/9*(AC7-5)+5))))/100+1 -> 1.05 | AE7: ==(ROUNDDOWN(AB7*AD7,2)+(Z7+AA7)*ROUNDDOWN(AD7*2.5,2)) -> 31.5 | AF7: ==AE7*0.4 -> 12.6 | AH7: 原始 | AI7: 0.05 | AJ7: ==MIN(AN$4,AJ6+IF(AH7="原始",$AJ$4/COUNTIF($AH$5:$AH$100,"原始")*$AM$4/100*$AK$4,AI7*$AJ$4*$AM$4/100*$AK$4)) -> 5.8621667 | AK7: ==AI7*AJ7 -> 0.29310833
S8: hp偏 | T8: ==(T4*2+T5)/3 -> 0 | U8: ==(U4*2+U5)/3 -> 0 | V8: ==(V4*2+V5)/3 -> 0 | W8: ==(W4*2+W5)/3 -> 0 | X8: ==(X4*2+X5)/3 -> 0 | AH8: 原始 | AI8: 0.05 | AJ8: ==MIN(AN$4,AJ7+IF(AH8="原始",$AJ$4/COUNTIF($AH$5:$AH$100,"原始")*$AM$4/100*$AK$4,AI8*$AJ$4*$AM$4/100*$AK$4)) -> 6.05175 | AK8: ==AI8*AJ8 -> 0.3025875
C9: 最小威力 | D9: 最大威力 | E9: min | F9: max | G9: 当前 | I9: 宝珠威力 | J9: 超差值威力 | K9: 技能威力 | L9: 倍率 | S9: dp偏 | T9: ==(T5*2+T4)/3 -> 0 | U9: ==(U5*2+U4)/3 -> 0 | V9: ==(V5*2+V4)/3 -> 0 | W9: ==(W5*2+W4)/3 -> 0 | X9: ==(X5*2+X4)/3 -> 0 | AH9: 原始 | AI9: 0.05 | AJ9: ==MIN(AN$4,AJ8+IF(AH9="原始",$AJ$4/COUNTIF($AH$5:$AH$100,"原始")*$AM$4/100*$AK$4,AI9*$AJ$4*$AM$4/100*$AK$4)) -> 6.2413333 | AK9: ==AI9*AJ9 -> 0.31206667
C10: ==D10/2 -> 8542.5 | D10: 17085 | E10: ==C10*(1+0.05*(E6-1)) -> 12386.625 | F10: ==D10*(1+0.02*(E6-1)) -> 20160.3 | G10: ==IF((L6+K6+N6*50-J6-M6)>=0,F10,IF((L6+K6+N6*50-M6)>=0,E10+(F10-E10)*(L6+K6+N6*50-M6)/J6,IF((L6+K6+N6*50-M6+J6)>=0,(L6+K6+N6*50-M6+J6)/J6*(E10-1),1))) -> 1 | I10: ==IF((L6+K6+N6*50-J6-M6-I6*20)>=0,D10*0.02*I6,IF((L6+K6+N6*50-M6)>=0,((L6+K6+N6*50-M6)*((D10-C10)*0.02*I6)/(I6*20+J6)+C10*0.02*I6),IF((L6+K6+N6*50+J6-M6+I6*20)>=0,(L6+K6+N6*50+J6-M6+I6*20)/(J6+I6*20)*C10*0.02*I6,1))) -> 1 | J10: ==IF(L6+K6+N6*50-M6-J6>0,G10*25/10000*(L6+K6+N6*50-M6-J6),0) -> 0 | K10: ==G10+I10+J10 -> 2 | L10: ==K10*F6*G6*H6 -> 3.75 | S10: 智偏(降防, 弱点) | T10: ==(T6*2+T7)/3 -> 0 | U10: ==(U6*2+U7)/3 -> 0 | V10: ==(V6*2+V7)/3 -> 0 | W10: ==(W6*2+W7)/3 -> 0 | X10: ==(X6*2+X7)/3 -> 0 | AH10: 原始 | AI10: 0.05 | AJ10: ==MIN(AN$4,AJ9+IF(AH10="原始",$AJ$4/COUNTIF($AH$5:$AH$100,"原始")*$AM$4/100*$AK$4,AI10*$AJ$4*$AM$4/100*$AK$4)) -> 6.4309167 | AK10: ==AI10*AJ10 -> 0.32154583
D11: 不会sp模型就直接填1级最大威力 | S11: 运偏(脆弱) | T11: ==(T7*2+T6)/3 -> 0 | U11: ==(U7*2+U6)/3 -> 0 | V11: ==(V7*2+V6)/3 -> 0 | W11: ==(W7*2+W6)/3 -> 0 | X11: ==(X7*2+X6)/3 -> 0 | AH11: 原始 | AI11: 0.05 | AJ11: ==MIN(AN$4,AJ10+IF(AH11="原始",$AJ$4/COUNTIF($AH$5:$AH$100,"原始")*$AM$4/100*$AK$4,AI11*$AJ$4*$AM$4/100*$AK$4)) -> 6.6205 | AK11: ==AI11*AJ11 -> 0.331025
AH12: 原始 | AI12: 0.05 | AJ12: ==MIN(AN$4,AJ11+IF(AH12="原始",$AJ$4/COUNTIF($AH$5:$AH$100,"原始")*$AM$4/100*$AK$4,AI12*$AJ$4*$AM$4/100*$AK$4)) -> 6.8100833 | AK12: ==AI12*AJ12 -> 0.34050417
B13: 加攻区（不含被动） | AH13: 原始 | AI13: 0.55 | AJ13: ==MIN(AN$4,AJ12+IF(AH13="原始",$AJ$4/COUNTIF($AH$5:$AH$100,"原始")*$AM$4/100*$AK$4,AI13*$AJ$4*$AM$4/100*$AK$4)) -> 6.9996667 | AK13: ==AI13*AJ13 -> 3.8498167
B14: 备注 | C14: 技能名 | D14: 最大威力 | E14: 宝珠 | F14: 当前属性 | G14: 技能差值 | H14: 士气/斗志 | I14: 技能等级 | J14: 被动 | K14: 宝珠倍率 | L14: 超差倍率 | M14: 层数 | N14: 最终威力 | AH14: 附加 | AI14: 0.5 | AJ14: ==MIN(AN$4,AJ13+IF(AH14="原始",$AJ$4/COUNTIF($AH$5:$AH$100,"原始")*$AM$4/100*$AK$4,AI14*$AJ$4*$AM$4/100*$AK$4)) -> 7.8527917 | AK14: ==AI14*AJ14 -> 3.9263958
D15: ==VLOOKUP(C15,技能lookup表!A4:C30,2,FALSE) -> #N/A | G15: ==VLOOKUP(C15,技能lookup表!A4:C30,3,FALSE) -> #N/A | K15: ==D15*(E15*0.04) -> #N/A | L15: ==D15*(1+I15*0.02-0.02)*(F15+H15-G15)*2/10000 -> #N/A | N15: ==_xlfn.IFNA((D15*(1+I15*0.02-0.02)+K15+L15)*M15*J15,0) -> 0 | P15: PS：被动包含勿忘+，高阶增强，31f共鸣被动，机灵被动，填写时叠加，例如存在勿忘，填写1.2 | AH15: 附加 | AI15: 0.5 | AJ15: ==MIN(AN$4,AJ14+IF(AH15="原始",$AJ$4/COUNTIF($AH$5:$AH$100,"原始")*$AM$4/100*$AK$4,AI15*$AJ$4*$AM$4/100*$AK$4)) -> 8 | AK15: ==AI15*AJ15 -> 4
D16: ==VLOOKUP(C16,技能lookup表!A4:C30,2,FALSE) -> #N/A | G16: ==VLOOKUP(C16,技能lookup表!A4:C30,3,FALSE) -> #N/A | K16: ==D16*(E16*0.04) -> #N/A | L16: ==D16*(1+I16*0.02-0.02)*(F16+H16-G16)*2/10000 -> #N/A | N16: ==_xlfn.IFNA((D16*(1+I16*0.02-0.02)+K16+L16)*M16*J16,0) -> 0 | P16: 速查: 勿忘+：20％ 高阶增强/boost：20％ 机灵：25%，初始共鸣:15/18/20/22/25, 条件共鸣:20/22/25/27/30 | AH16: 附加 | AI16: 0.5 | AJ16: ==MIN(AN$4,AJ15+IF(AH16="原始",$AJ$4/COUNTIF($AH$5:$AH$100,"原始")*$AM$4/100*$AK$4,AI16*$AJ$4*$AM$4/100*$AK$4)) -> 8 | AK16: ==AI16*AJ16 -> 4
D17: ==VLOOKUP(C17,技能lookup表!A4:C30,2,FALSE) -> #N/A | G17: ==VLOOKUP(C17,技能lookup表!A4:C30,3,FALSE) -> #N/A | K17: ==D17*(E17*0.04) -> #N/A | L17: ==D17*(1+I17*0.02-0.02)*(F17+H17-G17)*2/10000 -> #N/A | N17: ==_xlfn.IFNA((D17*(1+I17*0.02-0.02)+K17+L17)*M17*J17,0) -> 0 | P17: 场地为固定值，不吃任何加成，请填写在加攻被动区 | AJ17: ==MIN(AN$4,AJ16+IF(AH17="原始",$AJ$4/COUNTIF($AH$5:$AH$100,"原始")*$AM$4/100*$AK$4,AI17*$AJ$4*$AM$4/100*$AK$4)) -> 8 | AK17: ==AI17*AJ17 -> 0
D18: ==VLOOKUP(C18,技能lookup表!A4:C30,2,FALSE) -> #N/A | G18: ==VLOOKUP(C18,技能lookup表!A4:C30,3,FALSE) -> #N/A | K18: ==D18*(E18*0.04) -> #N/A | L18: ==D18*(1+I18*0.02-0.02)*(F18+H18-G18)*2/10000 -> #N/A | N18: ==_xlfn.IFNA((D18*(1+I18*0.02-0.02)+K18+L18)*M18*J18,0) -> 0 | P18: 心眼不吃宝珠，被动 | AJ18: ==MIN(AN$4,AJ17+IF(AH18="原始",$AJ$4/COUNTIF($AH$5:$AH$100,"原始")*$AM$4/100*$AK$4,AI18*$AJ$4*$AM$4/100*$AK$4)) -> 8 | AK18: ==AI18*AJ18 -> 0
D19: ==VLOOKUP(C19,技能lookup表!A4:C30,2,FALSE) -> #N/A | G19: ==VLOOKUP(C19,技能lookup表!A4:C30,3,FALSE) -> #N/A | K19: ==D19*(E19*0.04) -> #N/A | L19: ==D19*(1+I19*0.02-0.02)*(F19+H19-G19)*2/10000 -> #N/A | N19: ==_xlfn.IFNA((D19*(1+I19*0.02-0.02)+K19+L19)*M19*J19,0) -> 0 | P19: 指挥, 蓄力可吃所有正常加攻吃的被动和宝珠 | AJ19: ==MIN(AN$4,AJ18+IF(AH19="原始",$AJ$4/COUNTIF($AH$5:$AH$100,"原始")*$AM$4/100*$AK$4,AI19*$AJ$4*$AM$4/100*$AK$4)) -> 8 | AK19: ==AI19*AJ19 -> 0
D20: ==VLOOKUP(C20,技能lookup表!A4:C30,2,FALSE) -> #N/A | G20: ==VLOOKUP(C20,技能lookup表!A4:C30,3,FALSE) -> #N/A | K20: ==D20*(E20*0.04) -> #N/A | L20: ==D20*(1+I20*0.02-0.02)*(F20+H20-G20)*2/10000 -> #N/A | N20: ==_xlfn.IFNA((D20*(1+I20*0.02-0.02)+K20+L20)*M20*J20,0) -> 0 | AJ20: ==MIN(AN$4,AJ19+IF(AH20="原始",$AJ$4/COUNTIF($AH$5:$AH$100,"原始")*$AM$4/100*$AK$4,AI20*$AJ$4*$AM$4/100*$AK$4)) -> 8 | AK20: ==AI20*AJ20 -> 0
D21: ==VLOOKUP(C21,技能lookup表!A4:C30,2,FALSE) -> #N/A | G21: ==VLOOKUP(C21,技能lookup表!A4:C30,3,FALSE) -> #N/A | K21: ==D21*(E21*0.04) -> #N/A | L21: ==D21*(1+I21*0.02-0.02)*(F21+H21-G21)*2/10000 -> #N/A | N21: ==_xlfn.IFNA((D21*(1+I21*0.02-0.02)+K21+L21)*M21*J21,0) -> 0 | AJ21: ==MIN(AN$4,AJ20+IF(AH21="原始",$AJ$4/COUNTIF($AH$5:$AH$100,"原始")*$AM$4/100*$AK$4,AI21*$AJ$4*$AM$4/100*$AK$4)) -> 8 | AK21: ==AI21*AJ21 -> 0
D22: ==VLOOKUP(C22,技能lookup表!A4:C30,2,FALSE) -> #N/A | G22: ==VLOOKUP(C22,技能lookup表!A4:C30,3,FALSE) -> #N/A | K22: ==D22*(E22*0.04) -> #N/A | L22: ==D22*(1+I22*0.02-0.02)*(F22+H22-G22)*2/10000 -> #N/A | N22: ==_xlfn.IFNA((D22*(1+I22*0.02-0.02)+K22+L22)*M22*J22,0) -> 0 | AJ22: ==MIN(AN$4,AJ21+IF(AH22="原始",$AJ$4/COUNTIF($AH$5:$AH$100,"原始")*$AM$4/100*$AK$4,AI22*$AJ$4*$AM$4/100*$AK$4)) -> 8 | AK22: ==AI22*AJ22 -> 0
D23: ==VLOOKUP(C23,技能lookup表!A4:C30,2,FALSE) -> #N/A | G23: ==VLOOKUP(C23,技能lookup表!A4:C30,3,FALSE) -> #N/A | K23: ==D23*(E23*0.04) -> #N/A | L23: ==D23*(1+I23*0.02-0.02)*(F23+H23-G23)*2/10000 -> #N/A | N23: ==_xlfn.IFNA((D23*(1+I23*0.02-0.02)+K23+L23)*M23*J23,0) -> 0 | AJ23: ==MIN(AN$4,AJ22+IF(AH23="原始",$AJ$4/COUNTIF($AH$5:$AH$100,"原始")*$AM$4/100*$AK$4,AI23*$AJ$4*$AM$4/100*$AK$4)) -> 8 | AK23: ==AI23*AJ23 -> 0
AJ24: ==MIN(AN$4,AJ23+IF(AH24="原始",$AJ$4/COUNTIF($AH$5:$AH$100,"原始")*$AM$4/100*$AK$4,AI24*$AJ$4*$AM$4/100*$AK$4)) -> 8 | AK24: ==AI24*AJ24 -> 0
B25: 减防区（不含被动） | AJ25: ==MIN(AN$4,AJ24+IF(AH25="原始",$AJ$4/COUNTIF($AH$5:$AH$100,"原始")*$AM$4/100*$AK$4,AI25*$AJ$4*$AM$4/100*$AK$4)) -> 8 | AK25: ==AI25*AJ25 -> 0
B26: 备注 | C26: 技能名 | D26: 最大威力 | E26: 最小威力 | F26: 宝珠 | G26: 当前属性 | H26: 灵符/灾厄/黑客 /士气/斗志(直接相加) | I26: 技能差值 | J26: 基础倍率 | K26: 宝珠倍率 | L26: 超差倍率 | M26: 技能等级 | N26: 被动 | O26: 层数 | P26: 最终威力 | AJ26: ==MIN(AN$4,AJ25+IF(AH26="原始",$AJ$4/COUNTIF($AH$5:$AH$100,"原始")*$AM$4/100*$AK$4,AI26*$AJ$4*$AM$4/100*$AK$4)) -> 8 | AK26: ==AI26*AJ26 -> 0
D27: ==VLOOKUP(C27,技能lookup表!D4:G30,2,FALSE) -> #N/A | E27: ==VLOOKUP(C27,技能lookup表!D4:G30,3,FALSE) -> #N/A | I27: ==VLOOKUP(C27,技能lookup表!D4:G30,4,FALSE) -> #N/A | J27: ==IF(G27+H27-$M$6<=0,E27*(0.95+M27*0.05),IF(G27+H27-$M$6<=I27,(G27+H27-$M$6)/I27*(D27*(0.98+M27*0.02)-E27*(0.95+M27*0.05))+E27*(0.95+M27*0.05),D27*(0.98+M27*0.02))) -> #N/A | K27: ==IF(G27+H27-$M$6<=0,E27*F27*0.02,IF(G27+H27-$M$6-100<=I27,(G27+H27-$M$6)/(I27+100)*(D27-E27)*F27*0.02+E27*F27*0.02,D27*0.02*F27)) -> #N/A | L27: ==IF(G27+H27-$M$6<=I27,0,(G27+H27-$M$6-I27)*(0.98+0.02*M27)*D27*10/10000) -> #N/A | P27: ==_xlfn.IFNA((J27+K27+L27)*N27*O27,0) -> 0 | R27: PS：被动包含月光+，高阶增强，31e共鸣被动，侵蚀被动，填写时叠加，例如存在侵蚀，填写1.25 | AJ27: ==MIN(AN$4,AJ26+IF(AH27="原始",$AJ$4/COUNTIF($AH$5:$AH$100,"原始")*$AM$4/100*$AK$4,AI27*$AJ$4*$AM$4/100*$AK$4)) -> 8 | AK27: ==AI27*AJ27 -> 0
D28: ==VLOOKUP(C28,技能lookup表!D4:G30,2,FALSE) -> #N/A | E28: ==VLOOKUP(C28,技能lookup表!D4:G30,3,FALSE) -> #N/A | I28: ==VLOOKUP(C28,技能lookup表!D4:G30,4,FALSE) -> #N/A | J28: ==IF(G28+H28-$M$6<=0,E28*(0.95+M28*0.05),IF(G28+H28-$M$6<=I28,(G28+H28-$M$6)/I28*(D28*(0.98+M28*0.02)-E28*(0.95+M28*0.05))+E28*(0.95+M28*0.05),D28*(0.98+M28*0.02))) -> #N/A | K28: ==IF(G28+H28-$M$6<=0,E28*F28*0.02,IF(G28+H28-$M$6-100<=I28,(G28+H28-$M$6)/(I28+100)*(D28-E28)*F28*0.02+E28*F28*0.02,D28*0.02*F28)) -> #N/A | L28: ==IF(G28+H28-$M$6<=I28,0,(G28+H28-$M$6-I28)*(0.98+0.02*M28)*D28*10/10000) -> #N/A | P28: ==_xlfn.IFNA((J28+K28+L28)*N28*O28,0) -> 0 | R28: 速查: 勿忘+：20％ 高阶增强/boost：20％ 机灵：25%，樱花箭: 20%, 初始共鸣:15/18/20/22/25, 条件共鸣:20/22/25/27/30 | AJ28: ==MIN(AN$4,AJ27+IF(AH28="原始",$AJ$4/COUNTIF($AH$5:$AH$100,"原始")*$AM$4/100*$AK$4,AI28*$AJ$4*$AM$4/100*$AK$4)) -> 8 | AK28: ==AI28*AJ28 -> 0
D29: ==VLOOKUP(C29,技能lookup表!D4:G30,2,FALSE) -> #N/A | E29: ==VLOOKUP(C29,技能lookup表!D4:G30,3,FALSE) -> #N/A | I29: ==VLOOKUP(C29,技能lookup表!D4:G30,4,FALSE) -> #N/A | J29: ==IF(G29+H29-$M$6<=0,E29*(0.95+M29*0.05),IF(G29+H29-$M$6<=I29,(G29+H29-$M$6)/I29*(D29*(0.98+M29*0.02)-E29*(0.95+M29*0.05))+E29*(0.95+M29*0.05),D29*(0.98+M29*0.02))) -> #N/A | K29: ==IF(G29+H29-$M$6<=0,E29*F29*0.02,IF(G29+H29-$M$6-100<=I29,(G29+H29-$M$6)/(I29+100)*(D29-E29)*F29*0.02+E29*F29*0.02,D29*0.02*F29)) -> #N/A | L29: ==IF(G29+H29-$M$6<=I29,0,(G29+H29-$M$6-I29)*(0.98+0.02*M29)*D29*10/10000) -> #N/A | P29: ==_xlfn.IFNA((J29+K29+L29)*N29*O29,0) -> 0 | R29: 脆弱可享受樱花箭, 宝珠, 月光+，高阶，boost, 不享受共鸣被动，侵蚀 | AJ29: ==MIN(AN$4,AJ28+IF(AH29="原始",$AJ$4/COUNTIF($AH$5:$AH$100,"原始")*$AM$4/100*$AK$4,AI29*$AJ$4*$AM$4/100*$AK$4)) -> 8 | AK29: ==AI29*AJ29 -> 0
D30: ==VLOOKUP(C30,技能lookup表!D4:G30,2,FALSE) -> #N/A | E30: ==VLOOKUP(C30,技能lookup表!D4:G30,3,FALSE) -> #N/A | I30: ==VLOOKUP(C30,技能lookup表!D4:G30,4,FALSE) -> #N/A | J30: ==IF(G30+H30-$M$6<=0,E30*(0.95+M30*0.05),IF(G30+H30-$M$6<=I30,(G30+H30-$M$6)/I30*(D30*(0.98+M30*0.02)-E30*(0.95+M30*0.05))+E30*(0.95+M30*0.05),D30*(0.98+M30*0.02))) -> #N/A | K30: ==IF(G30+H30-$M$6<=0,E30*F30*0.02,IF(G30+H30-$M$6-100<=I30,(G30+H30-$M$6)/(I30+100)*(D30-E30)*F30*0.02+E30*F30*0.02,D30*0.02*F30)) -> #N/A | L30: ==IF(G30+H30-$M$6<=I30,0,(G30+H30-$M$6-I30)*(0.98+0.02*M30)*D30*10/10000) -> #N/A | P30: ==_xlfn.IFNA((J30+K30+L30)*N30*O30,0) -> 0 | AJ30: ==MIN(AN$4,AJ29+IF(AH30="原始",$AJ$4/COUNTIF($AH$5:$AH$100,"原始")*$AM$4/100*$AK$4,AI30*$AJ$4*$AM$4/100*$AK$4)) -> 8 | AK30: ==AI30*AJ30 -> 0
D31: ==VLOOKUP(C31,技能lookup表!D4:G30,2,FALSE) -> #N/A | E31: ==VLOOKUP(C31,技能lookup表!D4:G30,3,FALSE) -> #N/A | I31: ==VLOOKUP(C31,技能lookup表!D4:G30,4,FALSE) -> #N/A | J31: ==IF(G31+H31-$M$6<=0,E31*(0.95+M31*0.05),IF(G31+H31-$M$6<=I31,(G31+H31-$M$6)/I31*(D31*(0.98+M31*0.02)-E31*(0.95+M31*0.05))+E31*(0.95+M31*0.05),D31*(0.98+M31*0.02))) -> #N/A | K31: ==IF(G31+H31-$M$6<=0,E31*F31*0.02,IF(G31+H31-$M$6-100<=I31,(G31+H31-$M$6)/(I31+100)*(D31-E31)*F31*0.02+E31*F31*0.02,D31*0.02*F31)) -> #N/A | L31: ==IF(G31+H31-$M$6<=I31,0,(G31+H31-$M$6-I31)*(0.98+0.02*M31)*D31*10/10000) -> #N/A | P31: ==_xlfn.IFNA((J31+K31+L31)*N31*O31,0) -> 0 | AJ31: ==MIN(AN$4,AJ30+IF(AH31="原始",$AJ$4/COUNTIF($AH$5:$AH$100,"原始")*$AM$4/100*$AK$4,AI31*$AJ$4*$AM$4/100*$AK$4)) -> 8 | AK31: ==AI31*AJ31 -> 0
D32: ==VLOOKUP(C32,技能lookup表!D4:G30,2,FALSE) -> #N/A | E32: ==VLOOKUP(C32,技能lookup表!D4:G30,3,FALSE) -> #N/A | I32: ==VLOOKUP(C32,技能lookup表!D4:G30,4,FALSE) -> #N/A | J32: ==IF(G32+H32-$M$6<=0,E32*(0.95+M32*0.05),IF(G32+H32-$M$6<=I32,(G32+H32-$M$6)/I32*(D32*(0.98+M32*0.02)-E32*(0.95+M32*0.05))+E32*(0.95+M32*0.05),D32*(0.98+M32*0.02))) -> #N/A | K32: ==IF(G32+H32-$M$6<=0,E32*F32*0.02,IF(G32+H32-$M$6-100<=I32,(G32+H32-$M$6)/(I32+100)*(D32-E32)*F32*0.02+E32*F32*0.02,D32*0.02*F32)) -> #N/A | L32: ==IF(G32+H32-$M$6<=I32,0,(G32+H32-$M$6-I32)*(0.98+0.02*M32)*D32*10/10000) -> #N/A | P32: ==_xlfn.IFNA((J32+K32+L32)*N32*O32,0) -> 0 | AJ32: ==MIN(AN$4,AJ31+IF(AH32="原始",$AJ$4/COUNTIF($AH$5:$AH$100,"原始")*$AM$4/100*$AK$4,AI32*$AJ$4*$AM$4/100*$AK$4)) -> 8 | AK32: ==AI32*AJ32 -> 0
D33: ==VLOOKUP(C33,技能lookup表!D4:G30,2,FALSE) -> #N/A | E33: ==VLOOKUP(C33,技能lookup表!D4:G30,3,FALSE) -> #N/A | I33: ==VLOOKUP(C33,技能lookup表!D4:G30,4,FALSE) -> #N/A | J33: ==IF(G33+H33-$M$6<=0,E33*(0.95+M33*0.05),IF(G33+H33-$M$6<=I33,(G33+H33-$M$6)/I33*(D33*(0.98+M33*0.02)-E33*(0.95+M33*0.05))+E33*(0.95+M33*0.05),D33*(0.98+M33*0.02))) -> #N/A | K33: ==IF(G33+H33-$M$6<=0,E33*F33*0.02,IF(G33+H33-$M$6-100<=I33,(G33+H33-$M$6)/(I33+100)*(D33-E33)*F33*0.02+E33*F33*0.02,D33*0.02*F33)) -> #N/A | L33: ==IF(G33+H33-$M$6<=I33,0,(G33+H33-$M$6-I33)*(0.98+0.02*M33)*D33*10/10000) -> #N/A | P33: ==_xlfn.IFNA((J33+K33+L33)*N33*O33,0) -> 0 | AJ33: ==MIN(AN$4,AJ32+IF(AH33="原始",$AJ$4/COUNTIF($AH$5:$AH$100,"原始")*$AM$4/100*$AK$4,AI33*$AJ$4*$AM$4/100*$AK$4)) -> 8 | AK33: ==AI33*AJ33 -> 0
D34: ==VLOOKUP(C34,技能lookup表!D4:G30,2,FALSE) -> #N/A | E34: ==VLOOKUP(C34,技能lookup表!D4:G30,3,FALSE) -> #N/A | I34: ==VLOOKUP(C34,技能lookup表!D4:G30,4,FALSE) -> #N/A | J34: ==IF(G34+H34-$M$6<=0,E34*(0.95+M34*0.05),IF(G34+H34-$M$6<=I34,(G34+H34-$M$6)/I34*(D34*(0.98+M34*0.02)-E34*(0.95+M34*0.05))+E34*(0.95+M34*0.05),D34*(0.98+M34*0.02))) -> #N/A | K34: ==IF(G34+H34-$M$6<=0,E34*F34*0.02,IF(G34+H34-$M$6-100<=I34,(G34+H34-$M$6)/(I34+100)*(D34-E34)*F34*0.02+E34*F34*0.02,D34*0.02*F34)) -> #N/A | L34: ==IF(G34+H34-$M$6<=I34,0,(G34+H34-$M$6-I34)*(0.98+0.02*M34)*D34*10/10000) -> #N/A | P34: ==_xlfn.IFNA((J34+K34+L34)*N34*O34,0) -> 0 | AJ34: ==MIN(AN$4,AJ33+IF(AH34="原始",$AJ$4/COUNTIF($AH$5:$AH$100,"原始")*$AM$4/100*$AK$4,AI34*$AJ$4*$AM$4/100*$AK$4)) -> 8 | AK34: ==AI34*AJ34 -> 0
AJ35: ==MIN(AN$4,AJ34+IF(AH35="原始",$AJ$4/COUNTIF($AH$5:$AH$100,"原始")*$AM$4/100*$AK$4,AI35*$AJ$4*$AM$4/100*$AK$4)) -> 8 | AK35: ==AI35*AJ35 -> 0
B36: 弱点（不含被动） | AJ36: ==MIN(AN$4,AJ35+IF(AH36="原始",$AJ$4/COUNTIF($AH$5:$AH$100,"原始")*$AM$4/100*$AK$4,AI36*$AJ$4*$AM$4/100*$AK$4)) -> 8 | AK36: ==AI36*AJ36 -> 0
B37: 备注 | C37: 技能名 | D37: 最大威力 | E37: 最小威力 | F37: 宝珠 | G37: 当前属性 | H37: 灵符/灾厄/黑客 /士气/斗志(直接相加) | I37: 技能差值 | J37: 基础倍率 | K37: 宝珠倍率 | L37: 超差倍率 | M37: 技能等级 | N37: 被动 | O37: 层数 | P37: 最终威力 | AJ37: ==MIN(AN$4,AJ36+IF(AH37="原始",$AJ$4/COUNTIF($AH$5:$AH$100,"原始")*$AM$4/100*$AK$4,AI37*$AJ$4*$AM$4/100*$AK$4)) -> 8 | AK37: ==AI37*AJ37 -> 0
D38: ==VLOOKUP(C38,技能lookup表!H4:K30,2,FALSE) -> #N/A | E38: ==VLOOKUP(C38,技能lookup表!H4:K30,3,FALSE) -> #N/A | I38: ==VLOOKUP(C38,技能lookup表!H4:K30,4,FALSE) -> #N/A | J38: ==IF(G38+H38-$M$6<=0,E38*(0.95+M38*0.05),IF(G38+H38-$M$6<=I38,(G38+H38-$M$6)/I38*(D38*(0.98+M38*0.02)-E38*(0.95+M38*0.05))+E38*(0.95+M38*0.05),D38*(0.98+M38*0.02))) -> #N/A | K38: ==IF(G38+H38-M$6<=0,E38*F38*0.02,IF(G38+H38-M$6-100<=I38,(G38+H38-$M$6)/(I38+100)*(D38-E38)*F38*0.02+E38*F38*0.02,D38*0.02*F38)) -> #N/A | L38: ==IF(G38+H38-M$6<=I38,0,(G38+H38-M$6-I38)*(0.98+0.02*M38)*D38*10/10000) -> #N/A | P38: ==_xlfn.IFNA((J38+K38+L38)*N38*O38,0) -> 0 | AJ38: ==MIN(AN$4,AJ37+IF(AH38="原始",$AJ$4/COUNTIF($AH$5:$AH$100,"原始")*$AM$4/100*$AK$4,AI38*$AJ$4*$AM$4/100*$AK$4)) -> 8 | AK38: ==AI38*AJ38 -> 0
D39: ==VLOOKUP(C39,技能lookup表!H4:K30,2,FALSE) -> #N/A | E39: ==VLOOKUP(C39,技能lookup表!H4:K30,3,FALSE) -> #N/A | I39: ==VLOOKUP(C39,技能lookup表!H4:K30,4,FALSE) -> #N/A | J39: ==IF(G39+H39-$M$6<=0,E39*(0.95+M39*0.05),IF(G39+H39-$M$6<=I39,(G39+H39-$M$6)/I39*(D39*(0.98+M39*0.02)-E39*(0.95+M39*0.05))+E39*(0.95+M39*0.05),D39*(0.98+M39*0.02))) -> #N/A | K39: ==IF(G39+H39-M$6<=0,E39*F39*0.02,IF(G39+H39-M$6-100<=I39,(G39+H39-$M$6)/(I39+100)*(D39-E39)*F39*0.02+E39*F39*0.02,D39*0.02*F39)) -> #N/A | L39: ==IF(G39+H39-M$6<=I39,0,(G39+H39-M$6-I39)*(0.98+0.02*M39)*D39*10/10000) -> #N/A | P39: ==_xlfn.IFNA((J39+K39+L39)*N39*O39,0) -> 0 | AJ39: ==MIN(AN$4,AJ38+IF(AH39="原始",$AJ$4/COUNTIF($AH$5:$AH$100,"原始")*$AM$4/100*$AK$4,AI39*$AJ$4*$AM$4/100*$AK$4)) -> 8 | AK39: ==AI39*AJ39 -> 0
AJ40: ==MIN(AN$4,AJ39+IF(AH40="原始",$AJ$4/COUNTIF($AH$5:$AH$100,"原始")*$AM$4/100*$AK$4,AI40*$AJ$4*$AM$4/100*$AK$4)) -> 8 | AK40: ==AI40*AJ40 -> 0
C41: 被动加攻区 | D41: 威力 | E41: 被动减防区 | F41: 威力 | G41: 爆伤区 | H41: 威力 | I41: 装备区 | J41: 是否佩戴(0/1) | K41: 对应加攻 | AJ41: ==MIN(AN$4,AJ40+IF(AH41="原始",$AJ$4/COUNTIF($AH$5:$AH$100,"原始")*$AM$4/100*$AK$4,AI41*$AJ$4*$AM$4/100*$AK$4)) -> 8 | AK41: ==AI41*AJ41 -> 0
...

Sheet 技能lookup表
A1: 数据请从 hbr.quest 查询, border即为技能差值, max均使用1级的数值; 填到这里来后即可在主表直接查询使用 | L1: 数据库链接
A2: buff区 | D2: Debuff区 | H2: 弱点区
A3: 名称 | B3: max | C3: border | D3: 名称 | E3: max | F3: min | G3: border | H3: 名称 | I3: max | J3: min | K3: border
A4: 胜利之弧-加攻 | B4: 180 | C4: 143 | D4: 光芒一闪 | E4: 30 | F4: 20 | G4: 138 | H4: 今宵 | I4: 60 | J4: 45 | K4: 138
A5: 胜利之弧-心眼 | B5: 120 | C5: 143 | D5: 冰华-永减 | E5: 30 | F5: 20 | G5: 144 | H5: 放学 | I5: 60 | J5: 45 | K5: 140
A6: 泪雨 | B6: 160 | C6: 256 | D6: 冰华-冰减 | E6: 20 | F6: 10 | G6: 144 | H6: 无限光晕 | I6: 60 | J6: 45 | K6: 143
A7: 蓄力珠 | B7: 30 | C7: 200 | D7: 美也单体脆弱 | E7: 60 | F7: 42 | G7: 120 | H7: 国土无双 | I7: 60 | J7: 45 | K7: 137
A8: 指挥 | B8: 15 | C8: 0 | D8: 软化珠 | E8: 45 | F8: 30 | G8: 200 | H8: 纯洁之吻 | I8: 60 | J8: 45 | K8: 141
A9: 圣女-加攻 | B9: 180 | C9: 147 | D9: 鲱鱼闹钟 | E9: 45 | F9: 30 | G9: 126 | H9: 再炸一波 | I9: 60 | J9: 45 | K9: 150
A10: 圣女-心眼 | B10: 120 | C10: 147 | D10: 灵符-冰减 | E10: 45 | F10: 30 | G10: 141
A11: 加速 | B11: 90 | C11: 232 | D11: 灵符-脆弱 | E11: 60 | F11: 42 | G11: 141
A12: 彩蛋 | B12: 160 | C12: 200 | D12: 惠 单减 | E12: 45 | F12: 30 | G12: 129
A13: 柳-蓄力 | B13: 30 | C13: 216 | D13: 惠 永属减 | E13: 30 | F13: 20 | G13: 150
A14: 伊甸园-加攻 | B14: 180 | C14: 304 | D14: 惠 脆弱 | E14: 60 | F14: 42 | G14: 132
A15: 伊甸园-心眼 | B15: 120 | C15: 304 | D15: 惠 永脆 | E15: 40 | F15: 30 | G15: 126
D16: 冰降珠 | E16: 45 | F16: 30 | G16: 200
D17: 国土-降防 | E17: 30 | F17: 20 | G17: 137
D18: 追风 | E18: 45 | F18: 30 | G18: 143
D19: 骇客-脆弱 | E19: 60 | F19: 42 | G19: 149
D20: 光晕-永减 | E20: 30 | F20: 20 | G20: 143
D21: 胭紅魔女-光减 | E21: 60 | F21: 45 | G21: 135
D22: 胭紅魔女-脆弱 | E22: 60 | F22: 42 | G22: 135
D23: 毁灭+ | E23: 55 | F23: 40 | G23: 147

Sheet 排轴
A1: 回合 | B1: 1 | C1: 行动 | G1: 2 | H1: 行动 | L1: 3 | M1: 行动 | Q1: 4 | S1: 5 | U1: 6 | W1: 牢房 | X1: 被动 OD | Y1: 当前OD（Assist） | Z1: 当前OD | AA1: 本回合DR | AB1: BOSS DR | AC1: 剩余 DR | AD1: helpers
B2: 当前SP | C2: 消耗 | D2: 获得 | E2: OD | F2: DR | G2: 当前SP | H2: 消耗 | I2: 获得 | J2: OD | K2: DR | L2: 当前SP | M2: 消耗 | N2: 获得 | O2: OD | P2: DR | Q2: 当前 | R2: 获得 | S2: 当前 | T2: 获得 | U2: 当前 | V2: 获得 | AC2: ==AB2-SUM(AA:AA) -> 0
A3: 入场 | Y3: \ | Z3: \ | AA3: \ | AB3: 请选择OD表达方式 | AD3: ==B3 -> 0 | AE3: ==G3 -> 0 | AF3: ==L3 -> 0 | AG3: ==Q3 -> 0 | AH3: ==S3 -> 0 | AI3: ==U3 -> 0
B4: \ | C4: \ | E4: \ | F4: \ | G4: \ | H4: \ | J4: \ | K4: \ | L4: \ | M4: \ | O4: \ | P4: \ | Q4: \ | S4: \ | U4: \ | AB4: 百分比 | AJ4: ==IF(AB4="hit数",120,300) -> 300
A5: 1 | Q5: ==IF(OR(COUNTIF(AD3:AI3,0)>0,COUNTIF(AD5:AF5,0)>0),"",INDEX(AD3:AI3,MATCH(TRUE,ISNA(MATCH(AD3:AI3,AD5:AF5,0)),0))) | S5: ==IF(OR(COUNTIF(AD3:AI3,0)>0,COUNTIF(AD5:AG5,0)>0),"",INDEX(AD3:AI3,MATCH(TRUE,ISNA(MATCH(AD3:AI3,AD5:AG5,0)),0))) | U5: ==IF(OR(COUNTIF(AD3:AI3,0)>0,COUNTIF(AD5:AH5,0)>0),"",INDEX(AD3:AI3,MATCH(TRUE,ISNA(MATCH(AD3:AI3,AD5:AH5,0)),0))) | Y5: ==W3+X3 -> 0 | Z5: ==IF(Y5<$AJ$4,Y5,$AJ$4) -> 0 | AA5: ==F6+K6+P6 -> 0 | AD5: ==B5 -> 0 | AE5: ==G5 -> 0 | AF5: ==L5 -> 0 | AG5: ==Q5 | AH5: ==S5 | AI5: ==U5
B6: ==CHOOSE(MATCH(B5,B3:U3,0),D4,0,0,0,0,I4,0,0,0,0,N4,0,0,0,0,R4,0,T4,0,V4) -> #N/A | G6: ==CHOOSE(MATCH(G5,B3:U3,0),D4,0,0,0,0,I4,0,0,0,0,N4,0,0,0,0,R4,0,T4,0,V4) -> #N/A | L6: ==CHOOSE(MATCH(L5,B3:U3,0),D4,0,0,0,0,I4,0,0,0,0,N4,0,0,0,0,R4,0,T4,0,V4) -> #N/A | Q6: ==CHOOSE(MATCH(Q5,B3:U3,0),D4,0,0,0,0,I4,0,0,0,0,N4,0,0,0,0,R4,0,T4,0,V4) -> #N/A | S6: ==CHOOSE(MATCH(S5,B3:U3,0),D4,0,0,0,0,I4,0,0,0,0,N4,0,0,0,0,R4,0,T4,0,V4) -> #N/A | U6: ==CHOOSE(MATCH(U5,B3:U3,0),D4,0,0,0,0,I4,0,0,0,0,N4,0,0,0,0,R4,0,T4,0,V4) -> #N/A
Q7: ==IF(OR(COUNTIF(AD5:AI5,0)>0,COUNTIF(AD7:AF7,0)>0),"",INDEX(AD5:AI5,MATCH(TRUE,ISNA(MATCH(AD5:AI5,AD7:AF7,0)),0))) | S7: ==IF(OR(COUNTIF(AD5:AI5,0)>0,COUNTIF(AD7:AG7,0)>0),"",INDEX(AD5:AI5,MATCH(TRUE,ISNA(MATCH(AD5:AI5,AD7:AG7,0)),0))) | U7: ==IF(OR(COUNTIF(AD5:AI5,0)>0,COUNTIF(AD7:AH7,0)>0),"",INDEX(AD5:AI5,MATCH(TRUE,ISNA(MATCH(AD5:AI5,AD7:AH7,0)),0))) | Y7: ==IF(OR(A5="前置OD1",A5="后置OD1"),AK7,IF(OR(A5="前置OD2",A5="后置OD2"),AL7,IF(OR(A5="前置OD3",A5="后置OD3"),AM7,IF(LEFT(A7,2)="后置",Y5+E6+J6+O6+W5,Y5+E6+J6+O6+W5+X5)))) -> 0 | Z7: ==IF(Y7<$AJ$4,Y7,$AJ$4) -> 0 | AA7: ==F8+K8+P8 -> 0 | AB7: 【Tencent Docs】Copy-OD计算表 | AD7: ==B7 -> 0 | AE7: ==G7 -> 0 | AF7: ==L7 -> 0 | AG7: ==Q7 | AH7: ==S7 | AI7: ==U7 | AK7: ==Z5-$AJ$4/3+E6+J6+O6+X5 -> -100 | AL7: ==Z5-$AJ$4/3*2+E6+J6+O6+X5 -> -200 | AM7: ==Z5-$AJ$4+E6+J6+O6+X5 -> -300
B8: ==CHOOSE(MATCH(B7,B5:U5,0),B6-C6+D6,0,0,0,0,G6-H6+I6,0,0,0,0,L6-M6+N6,0,0,0,0,Q6+R6,0,S6+T6,0,U6+V6) -> #N/A | G8: ==CHOOSE(MATCH(G7,B5:U5,0),B6-C6+D6,0,0,0,0,G6-H6+I6,0,0,0,0,L6-M6+N6,0,0,0,0,Q6+R6,0,S6+T6,0,U6+V6) -> #N/A | L8: ==CHOOSE(MATCH(L7,B5:U5,0),B6-C6+D6,0,0,0,0,G6-H6+I6,0,0,0,0,L6-M6+N6,0,0,0,0,Q6+R6,0,S6+T6,0,U6+V6) -> #N/A | Q8: ==CHOOSE(MATCH(Q7,B5:U5,0),B6-C6+D6,0,0,0,0,G6-H6+I6,0,0,0,0,L6-M6+N6,0,0,0,0,Q6+R6,0,S6+T6,0,U6+V6) -> #N/A | S8: ==CHOOSE(MATCH(S7,B5:U5,0),B6-C6+D6,0,0,0,0,G6-H6+I6,0,0,0,0,L6-M6+N6,0,0,0,0,Q6+R6,0,S6+T6,0,U6+V6) -> #N/A | U8: ==CHOOSE(MATCH(U7,B5:U5,0),B6-C6+D6,0,0,0,0,G6-H6+I6,0,0,0,0,L6-M6+N6,0,0,0,0,Q6+R6,0,S6+T6,0,U6+V6) -> #N/A | AB8: Copy-OD计算表
Q9: ==IF(OR(COUNTIF(AD7:AI7,0)>0,COUNTIF(AD9:AF9,0)>0),"",INDEX(AD7:AI7,MATCH(TRUE,ISNA(MATCH(AD7:AI7,AD9:AF9,0)),0))) | S9: ==IF(OR(COUNTIF(AD7:AI7,0)>0,COUNTIF(AD9:AG9,0)>0),"",INDEX(AD7:AI7,MATCH(TRUE,ISNA(MATCH(AD7:AI7,AD9:AG9,0)),0))) | U9: ==IF(OR(COUNTIF(AD7:AI7,0)>0,COUNTIF(AD9:AH9,0)>0),"",INDEX(AD7:AI7,MATCH(TRUE,ISNA(MATCH(AD7:AI7,AD9:AH9,0)),0))) | Y9: ==IF(OR(A7="前置OD1",A7="后置OD1"),AK9,IF(OR(A7="前置OD2",A7="后置OD2"),AL9,IF(OR(A7="前置OD3",A7="后置OD3"),AM9,IF(LEFT(A9,2)="后置",Y7+E8+J8+O8+W7,Y7+E8+J8+O8+W7+X7)))) -> 0 | Z9: ==IF(Y9<$AJ$4,Y9,$AJ$4) -> 0 | AA9: ==F10+K10+P10 -> 0 | AD9: ==B9 -> 0 | AE9: ==G9 -> 0 | AF9: ==L9 -> 0 | AG9: ==Q9 | AH9: ==S9 | AI9: ==U9 | AK9: ==Z7-$AJ$4/3+E8+J8+O8+X7 -> -100 | AL9: ==Z7-$AJ$4/3*2+E8+J8+O8+X7 -> -200 | AM9: ==Z7-$AJ$4+E8+J8+O8+X7 -> -300
B10: ==CHOOSE(MATCH(B9,B7:U7,0),B8-C8+D8,0,0,0,0,G8-H8+I8,0,0,0,0,L8-M8+N8,0,0,0,0,Q8+R8,0,S8+T8,0,U8+V8) -> #N/A | G10: ==CHOOSE(MATCH(G9,B7:U7,0),B8-C8+D8,0,0,0,0,G8-H8+I8,0,0,0,0,L8-M8+N8,0,0,0,0,Q8+R8,0,S8+T8,0,U8+V8) -> #N/A | L10: ==CHOOSE(MATCH(L9,B7:U7,0),B8-C8+D8,0,0,0,0,G8-H8+I8,0,0,0,0,L8-M8+N8,0,0,0,0,Q8+R8,0,S8+T8,0,U8+V8) -> #N/A | Q10: ==CHOOSE(MATCH(Q9,B7:U7,0),B8-C8+D8,0,0,0,0,G8-H8+I8,0,0,0,0,L8-M8+N8,0,0,0,0,Q8+R8,0,S8+T8,0,U8+V8) -> #N/A | S10: ==CHOOSE(MATCH(S9,B7:U7,0),B8-C8+D8,0,0,0,0,G8-H8+I8,0,0,0,0,L8-M8+N8,0,0,0,0,Q8+R8,0,S8+T8,0,U8+V8) -> #N/A | U10: ==CHOOSE(MATCH(U9,B7:U7,0),B8-C8+D8,0,0,0,0,G8-H8+I8,0,0,0,0,L8-M8+N8,0,0,0,0,Q8+R8,0,S8+T8,0,U8+V8) -> #N/A
Q11: ==IF(OR(COUNTIF(AD9:AI9,0)>0,COUNTIF(AD11:AF11,0)>0),"",INDEX(AD9:AI9,MATCH(TRUE,ISNA(MATCH(AD9:AI9,AD11:AF11,0)),0))) | S11: ==IF(OR(COUNTIF(AD9:AI9,0)>0,COUNTIF(AD11:AG11,0)>0),"",INDEX(AD9:AI9,MATCH(TRUE,ISNA(MATCH(AD9:AI9,AD11:AG11,0)),0))) | U11: ==IF(OR(COUNTIF(AD9:AI9,0)>0,COUNTIF(AD11:AH11,0)>0),"",INDEX(AD9:AI9,MATCH(TRUE,ISNA(MATCH(AD9:AI9,AD11:AH11,0)),0))) | Y11: ==IF(OR(A9="前置OD1",A9="后置OD1"),AK11,IF(OR(A9="前置OD2",A9="后置OD2"),AL11,IF(OR(A9="前置OD3",A9="后置OD3"),AM11,IF(LEFT(A11,2)="后置",Y9+E10+J10+O10+W9,Y9+E10+J10+O10+W9+X9)))) -> 0 | Z11: ==IF(Y11<$AJ$4,Y11,$AJ$4) -> 0 | AA11: ==F12+K12+P12 -> 0 | AD11: ==B11 -> 0 | AE11: ==G11 -> 0 | AF11: ==L11 -> 0 | AG11: ==Q11 | AH11: ==S11 | AI11: ==U11 | AK11: ==Z9-$AJ$4/3+E10+J10+O10+X9 -> -100 | AL11: ==Z9-$AJ$4/3*2+E10+J10+O10+X9 -> -200 | AM11: ==Z9-$AJ$4+E10+J10+O10+X9 -> -300
B12: ==CHOOSE(MATCH(B11,B9:U9,0),B10-C10+D10,0,0,0,0,G10-H10+I10,0,0,0,0,L10-M10+N10,0,0,0,0,Q10+R10,0,S10+T10,0,U10+V10) -> #N/A | G12: ==CHOOSE(MATCH(G11,B9:U9,0),B10-C10+D10,0,0,0,0,G10-H10+I10,0,0,0,0,L10-M10+N10,0,0,0,0,Q10+R10,0,S10+T10,0,U10+V10) -> #N/A | L12: ==CHOOSE(MATCH(L11,B9:U9,0),B10-C10+D10,0,0,0,0,G10-H10+I10,0,0,0,0,L10-M10+N10,0,0,0,0,Q10+R10,0,S10+T10,0,U10+V10) -> #N/A | Q12: ==CHOOSE(MATCH(Q11,B9:U9,0),B10-C10+D10,0,0,0,0,G10-H10+I10,0,0,0,0,L10-M10+N10,0,0,0,0,Q10+R10,0,S10+T10,0,U10+V10) -> #N/A | S12: ==CHOOSE(MATCH(S11,B9:U9,0),B10-C10+D10,0,0,0,0,G10-H10+I10,0,0,0,0,L10-M10+N10,0,0,0,0,Q10+R10,0,S10+T10,0,U10+V10) -> #N/A | U12: ==CHOOSE(MATCH(U11,B9:U9,0),B10-C10+D10,0,0,0,0,G10-H10+I10,0,0,0,0,L10-M10+N10,0,0,0,0,Q10+R10,0,S10+T10,0,U10+V10) -> #N/A
Q13: ==IF(OR(COUNTIF(AD11:AI11,0)>0,COUNTIF(AD13:AF13,0)>0),"",INDEX(AD11:AI11,MATCH(TRUE,ISNA(MATCH(AD11:AI11,AD13:AF13,0)),0))) | S13: ==IF(OR(COUNTIF(AD11:AI11,0)>0,COUNTIF(AD13:AG13,0)>0),"",INDEX(AD11:AI11,MATCH(TRUE,ISNA(MATCH(AD11:AI11,AD13:AG13,0)),0))) | U13: ==IF(OR(COUNTIF(AD11:AI11,0)>0,COUNTIF(AD13:AH13,0)>0),"",INDEX(AD11:AI11,MATCH(TRUE,ISNA(MATCH(AD11:AI11,AD13:AH13,0)),0))) | Y13: ==IF(OR(A11="前置OD1",A11="后置OD1"),AK13,IF(OR(A11="前置OD2",A11="后置OD2"),AL13,IF(OR(A11="前置OD3",A11="后置OD3"),AM13,IF(LEFT(A13,2)="后置",Y11+E12+J12+O12+W11,Y11+E12+J12+O12+W11+X11)))) -> 0 | Z13: ==IF(Y13<$AJ$4,Y13,$AJ$4) -> 0 | AA13: ==F14+K14+P14 -> 0 | AD13: ==B13 -> 0 | AE13: ==G13 -> 0 | AF13: ==L13 -> 0 | AG13: ==Q13 | AH13: ==S13 | AI13: ==U13 | AK13: ==Z11-$AJ$4/3+E12+J12+O12+X11 -> -100 | AL13: ==Z11-$AJ$4/3*2+E12+J12+O12+X11 -> -200 | AM13: ==Z11-$AJ$4+E12+J12+O12+X11 -> -300
B14: ==CHOOSE(MATCH(B13,B11:U11,0),B12-C12+D12,0,0,0,0,G12-H12+I12,0,0,0,0,L12-M12+N12,0,0,0,0,Q12+R12,0,S12+T12,0,U12+V12) -> #N/A | G14: ==CHOOSE(MATCH(G13,B11:U11,0),B12-C12+D12,0,0,0,0,G12-H12+I12,0,0,0,0,L12-M12+N12,0,0,0,0,Q12+R12,0,S12+T12,0,U12+V12) -> #N/A | L14: ==CHOOSE(MATCH(L13,B11:U11,0),B12-C12+D12,0,0,0,0,G12-H12+I12,0,0,0,0,L12-M12+N12,0,0,0,0,Q12+R12,0,S12+T12,0,U12+V12) -> #N/A | Q14: ==CHOOSE(MATCH(Q13,B11:U11,0),B12-C12+D12,0,0,0,0,G12-H12+I12,0,0,0,0,L12-M12+N12,0,0,0,0,Q12+R12,0,S12+T12,0,U12+V12) -> #N/A | S14: ==CHOOSE(MATCH(S13,B11:U11,0),B12-C12+D12,0,0,0,0,G12-H12+I12,0,0,0,0,L12-M12+N12,0,0,0,0,Q12+R12,0,S12+T12,0,U12+V12) -> #N/A | U14: ==CHOOSE(MATCH(U13,B11:U11,0),B12-C12+D12,0,0,0,0,G12-H12+I12,0,0,0,0,L12-M12+N12,0,0,0,0,Q12+R12,0,S12+T12,0,U12+V12) -> #N/A
Q15: ==IF(OR(COUNTIF(AD13:AI13,0)>0,COUNTIF(AD15:AF15,0)>0),"",INDEX(AD13:AI13,MATCH(TRUE,ISNA(MATCH(AD13:AI13,AD15:AF15,0)),0))) | S15: ==IF(OR(COUNTIF(AD13:AI13,0)>0,COUNTIF(AD15:AG15,0)>0),"",INDEX(AD13:AI13,MATCH(TRUE,ISNA(MATCH(AD13:AI13,AD15:AG15,0)),0))) | U15: ==IF(OR(COUNTIF(AD13:AI13,0)>0,COUNTIF(AD15:AH15,0)>0),"",INDEX(AD13:AI13,MATCH(TRUE,ISNA(MATCH(AD13:AI13,AD15:AH15,0)),0))) | Y15: ==IF(OR(A13="前置OD1",A13="后置OD1"),AK15,IF(OR(A13="前置OD2",A13="后置OD2"),AL15,IF(OR(A13="前置OD3",A13="后置OD3"),AM15,IF(LEFT(A15,2)="后置",Y13+E14+J14+O14+W13,Y13+E14+J14+O14+W13+X13)))) -> 0 | Z15: ==IF(Y15<$AJ$4,Y15,$AJ$4) -> 0 | AA15: ==F16+K16+P16 -> 0 | AD15: ==B15 -> 0 | AE15: ==G15 -> 0 | AF15: ==L15 -> 0 | AG15: ==Q15 | AH15: ==S15 | AI15: ==U15 | AK15: ==Z13-$AJ$4/3+E14+J14+O14+X13 -> -100 | AL15: ==Z13-$AJ$4/3*2+E14+J14+O14+X13 -> -200 | AM15: ==Z13-$AJ$4+E14+J14+O14+X13 -> -300
B16: ==CHOOSE(MATCH(B15,B13:U13,0),B14-C14+D14,0,0,0,0,G14-H14+I14,0,0,0,0,L14-M14+N14,0,0,0,0,Q14+R14,0,S14+T14,0,U14+V14) -> #N/A | G16: ==CHOOSE(MATCH(G15,B13:U13,0),B14-C14+D14,0,0,0,0,G14-H14+I14,0,0,0,0,L14-M14+N14,0,0,0,0,Q14+R14,0,S14+T14,0,U14+V14) -> #N/A | L16: ==CHOOSE(MATCH(L15,B13:U13,0),B14-C14+D14,0,0,0,0,G14-H14+I14,0,0,0,0,L14-M14+N14,0,0,0,0,Q14+R14,0,S14+T14,0,U14+V14) -> #N/A | Q16: ==CHOOSE(MATCH(Q15,B13:U13,0),B14-C14+D14,0,0,0,0,G14-H14+I14,0,0,0,0,L14-M14+N14,0,0,0,0,Q14+R14,0,S14+T14,0,U14+V14) -> #N/A | S16: ==CHOOSE(MATCH(S15,B13:U13,0),B14-C14+D14,0,0,0,0,G14-H14+I14,0,0,0,0,L14-M14+N14,0,0,0,0,Q14+R14,0,S14+T14,0,U14+V14) -> #N/A | U16: ==CHOOSE(MATCH(U15,B13:U13,0),B14-C14+D14,0,0,0,0,G14-H14+I14,0,0,0,0,L14-M14+N14,0,0,0,0,Q14+R14,0,S14+T14,0,U14+V14) -> #N/A
A17: 7 | Q17: ==IF(OR(COUNTIF(AD15:AI15,0)>0,COUNTIF(AD17:AF17,0)>0),"",INDEX(AD15:AI15,MATCH(TRUE,ISNA(MATCH(AD15:AI15,AD17:AF17,0)),0))) | S17: ==IF(OR(COUNTIF(AD15:AI15,0)>0,COUNTIF(AD17:AG17,0)>0),"",INDEX(AD15:AI15,MATCH(TRUE,ISNA(MATCH(AD15:AI15,AD17:AG17,0)),0))) | U17: ==IF(OR(COUNTIF(AD15:AI15,0)>0,COUNTIF(AD17:AH17,0)>0),"",INDEX(AD15:AI15,MATCH(TRUE,ISNA(MATCH(AD15:AI15,AD17:AH17,0)),0))) | Y17: ==IF(OR(A15="前置OD1",A15="后置OD1"),AK17,IF(OR(A15="前置OD2",A15="后置OD2"),AL17,IF(OR(A15="前置OD3",A15="后置OD3"),AM17,IF(LEFT(A17,2)="后置",Y15+E16+J16+O16+W15,Y15+E16+J16+O16+W15+X15)))) -> 0 | Z17: ==IF(Y17<$AJ$4,Y17,$AJ$4) -> 0 | AA17: ==F18+K18+P18 -> 0 | AD17: ==B17 -> 0 | AE17: ==G17 -> 0 | AF17: ==L17 -> 0 | AG17: ==Q17 | AH17: ==S17 | AI17: ==U17 | AK17: ==Z15-$AJ$4/3+E16+J16+O16+X15 -> -100 | AL17: ==Z15-$AJ$4/3*2+E16+J16+O16+X15 -> -200 | AM17: ==Z15-$AJ$4+E16+J16+O16+X15 -> -300
B18: ==CHOOSE(MATCH(B17,B15:U15,0),B16-C16+D16,0,0,0,0,G16-H16+I16,0,0,0,0,L16-M16+N16,0,0,0,0,Q16+R16,0,S16+T16,0,U16+V16) -> #N/A | G18: ==CHOOSE(MATCH(G17,B15:U15,0),B16-C16+D16,0,0,0,0,G16-H16+I16,0,0,0,0,L16-M16+N16,0,0,0,0,Q16+R16,0,S16+T16,0,U16+V16) -> #N/A | L18: ==CHOOSE(MATCH(L17,B15:U15,0),B16-C16+D16,0,0,0,0,G16-H16+I16,0,0,0,0,L16-M16+N16,0,0,0,0,Q16+R16,0,S16+T16,0,U16+V16) -> #N/A | Q18: ==CHOOSE(MATCH(Q17,B15:U15,0),B16-C16+D16,0,0,0,0,G16-H16+I16,0,0,0,0,L16-M16+N16,0,0,0,0,Q16+R16,0,S16+T16,0,U16+V16) -> #N/A | S18: ==CHOOSE(MATCH(S17,B15:U15,0),B16-C16+D16,0,0,0,0,G16-H16+I16,0,0,0,0,L16-M16+N16,0,0,0,0,Q16+R16,0,S16+T16,0,U16+V16) -> #N/A | U18: ==CHOOSE(MATCH(U17,B15:U15,0),B16-C16+D16,0,0,0,0,G16-H16+I16,0,0,0,0,L16-M16+N16,0,0,0,0,Q16+R16,0,S16+T16,0,U16+V16) -> #N/A
A19: 8 | Q19: ==IF(OR(COUNTIF(AD17:AI17,0)>0,COUNTIF(AD19:AF19,0)>0),"",INDEX(AD17:AI17,MATCH(TRUE,ISNA(MATCH(AD17:AI17,AD19:AF19,0)),0))) | S19: ==IF(OR(COUNTIF(AD17:AI17,0)>0,COUNTIF(AD19:AG19,0)>0),"",INDEX(AD17:AI17,MATCH(TRUE,ISNA(MATCH(AD17:AI17,AD19:AG19,0)),0))) | U19: ==IF(OR(COUNTIF(AD17:AI17,0)>0,COUNTIF(AD19:AH19,0)>0),"",INDEX(AD17:AI17,MATCH(TRUE,ISNA(MATCH(AD17:AI17,AD19:AH19,0)),0))) | Y19: ==IF(OR(A17="前置OD1",A17="后置OD1"),AK19,IF(OR(A17="前置OD2",A17="后置OD2"),AL19,IF(OR(A17="前置OD3",A17="后置OD3"),AM19,IF(LEFT(A19,2)="后置",Y17+E18+J18+O18+W17,Y17+E18+J18+O18+W17+X17)))) -> 0 | Z19: ==IF(Y19<$AJ$4,Y19,$AJ$4) -> 0 | AA19: ==F20+K20+P20 -> 0 | AD19: ==B19 -> 0 | AE19: ==G19 -> 0 | AF19: ==L19 -> 0 | AG19: ==Q19 | AH19: ==S19 | AI19: ==U19 | AK19: ==Z17-$AJ$4/3+E18+J18+O18+X17 -> -100 | AL19: ==Z17-$AJ$4/3*2+E18+J18+O18+X17 -> -200 | AM19: ==Z17-$AJ$4+E18+J18+O18+X17 -> -300
B20: ==CHOOSE(MATCH(B19,B17:U17,0),B18-C18+D18,0,0,0,0,G18-H18+I18,0,0,0,0,L18-M18+N18,0,0,0,0,Q18+R18,0,S18+T18,0,U18+V18) -> #N/A | G20: ==CHOOSE(MATCH(G19,B17:U17,0),B18-C18+D18,0,0,0,0,G18-H18+I18,0,0,0,0,L18-M18+N18,0,0,0,0,Q18+R18,0,S18+T18,0,U18+V18) -> #N/A | L20: ==CHOOSE(MATCH(L19,B17:U17,0),B18-C18+D18,0,0,0,0,G18-H18+I18,0,0,0,0,L18-M18+N18,0,0,0,0,Q18+R18,0,S18+T18,0,U18+V18) -> #N/A | Q20: ==CHOOSE(MATCH(Q19,B17:U17,0),B18-C18+D18,0,0,0,0,G18-H18+I18,0,0,0,0,L18-M18+N18,0,0,0,0,Q18+R18,0,S18+T18,0,U18+V18) -> #N/A | S20: ==CHOOSE(MATCH(S19,B17:U17,0),B18-C18+D18,0,0,0,0,G18-H18+I18,0,0,0,0,L18-M18+N18,0,0,0,0,Q18+R18,0,S18+T18,0,U18+V18) -> #N/A | U20: ==CHOOSE(MATCH(U19,B17:U17,0),B18-C18+D18,0,0,0,0,G18-H18+I18,0,0,0,0,L18-M18+N18,0,0,0,0,Q18+R18,0,S18+T18,0,U18+V18) -> #N/A
A21: 9 | Q21: ==IF(OR(COUNTIF(AD19:AI19,0)>0,COUNTIF(AD21:AF21,0)>0),"",INDEX(AD19:AI19,MATCH(TRUE,ISNA(MATCH(AD19:AI19,AD21:AF21,0)),0))) | S21: ==IF(OR(COUNTIF(AD19:AI19,0)>0,COUNTIF(AD21:AG21,0)>0),"",INDEX(AD19:AI19,MATCH(TRUE,ISNA(MATCH(AD19:AI19,AD21:AG21,0)),0))) | U21: ==IF(OR(COUNTIF(AD19:AI19,0)>0,COUNTIF(AD21:AH21,0)>0),"",INDEX(AD19:AI19,MATCH(TRUE,ISNA(MATCH(AD19:AI19,AD21:AH21,0)),0))) | Y21: ==IF(OR(A19="前置OD1",A19="后置OD1"),AK21,IF(OR(A19="前置OD2",A19="后置OD2"),AL21,IF(OR(A19="前置OD3",A19="后置OD3"),AM21,IF(LEFT(A21,2)="后置",Y19+E20+J20+O20+W19,Y19+E20+J20+O20+W19+X19)))) -> 0 | Z21: ==IF(Y21<$AJ$4,Y21,$AJ$4) -> 0 | AA21: ==F22+K22+P22 -> 0 | AD21: ==B21 -> 0 | AE21: ==G21 -> 0 | AF21: ==L21 -> 0 | AG21: ==Q21 | AH21: ==S21 | AI21: ==U21 | AK21: ==Z19-$AJ$4/3+E20+J20+O20+X19 -> -100 | AL21: ==Z19-$AJ$4/3*2+E20+J20+O20+X19 -> -200 | AM21: ==Z19-$AJ$4+E20+J20+O20+X19 -> -300
B22: ==CHOOSE(MATCH(B21,B19:U19,0),B20-C20+D20,0,0,0,0,G20-H20+I20,0,0,0,0,L20-M20+N20,0,0,0,0,Q20+R20,0,S20+T20,0,U20+V20) -> #N/A | G22: ==CHOOSE(MATCH(G21,B19:U19,0),B20-C20+D20,0,0,0,0,G20-H20+I20,0,0,0,0,L20-M20+N20,0,0,0,0,Q20+R20,0,S20+T20,0,U20+V20) -> #N/A | L22: ==CHOOSE(MATCH(L21,B19:U19,0),B20-C20+D20,0,0,0,0,G20-H20+I20,0,0,0,0,L20-M20+N20,0,0,0,0,Q20+R20,0,S20+T20,0,U20+V20) -> #N/A | Q22: ==CHOOSE(MATCH(Q21,B19:U19,0),B20-C20+D20,0,0,0,0,G20-H20+I20,0,0,0,0,L20-M20+N20,0,0,0,0,Q20+R20,0,S20+T20,0,U20+V20) -> #N/A | S22: ==CHOOSE(MATCH(S21,B19:U19,0),B20-C20+D20,0,0,0,0,G20-H20+I20,0,0,0,0,L20-M20+N20,0,0,0,0,Q20+R20,0,S20+T20,0,U20+V20) -> #N/A | U22: ==CHOOSE(MATCH(U21,B19:U19,0),B20-C20+D20,0,0,0,0,G20-H20+I20,0,0,0,0,L20-M20+N20,0,0,0,0,Q20+R20,0,S20+T20,0,U20+V20) -> #N/A
A23: 10 | Q23: ==IF(OR(COUNTIF(AD21:AI21,0)>0,COUNTIF(AD23:AF23,0)>0),"",INDEX(AD21:AI21,MATCH(TRUE,ISNA(MATCH(AD21:AI21,AD23:AF23,0)),0))) | S23: ==IF(OR(COUNTIF(AD21:AI21,0)>0,COUNTIF(AD23:AG23,0)>0),"",INDEX(AD21:AI21,MATCH(TRUE,ISNA(MATCH(AD21:AI21,AD23:AG23,0)),0))) | U23: ==IF(OR(COUNTIF(AD21:AI21,0)>0,COUNTIF(AD23:AH23,0)>0),"",INDEX(AD21:AI21,MATCH(TRUE,ISNA(MATCH(AD21:AI21,AD23:AH23,0)),0))) | Y23: ==IF(OR(A21="前置OD1",A21="后置OD1"),AK23,IF(OR(A21="前置OD2",A21="后置OD2"),AL23,IF(OR(A21="前置OD3",A21="后置OD3"),AM23,IF(LEFT(A23,2)="后置",Y21+E22+J22+O22+W21,Y21+E22+J22+O22+W21+X21)))) -> 0 | Z23: ==IF(Y23<$AJ$4,Y23,$AJ$4) -> 0 | AA23: ==F24+K24+P24 -> 0 | AD23: ==B23 -> 0 | AE23: ==G23 -> 0 | AF23: ==L23 -> 0 | AG23: ==Q23 | AH23: ==S23 | AI23: ==U23 | AK23: ==Z21-$AJ$4/3+E22+J22+O22+X21 -> -100 | AL23: ==Z21-$AJ$4/3*2+E22+J22+O22+X21 -> -200 | AM23: ==Z21-$AJ$4+E22+J22+O22+X21 -> -300
B24: ==CHOOSE(MATCH(B23,B21:U21,0),B22-C22+D22,0,0,0,0,G22-H22+I22,0,0,0,0,L22-M22+N22,0,0,0,0,Q22+R22,0,S22+T22,0,U22+V22) -> #N/A | G24: ==CHOOSE(MATCH(G23,B21:U21,0),B22-C22+D22,0,0,0,0,G22-H22+I22,0,0,0,0,L22-M22+N22,0,0,0,0,Q22+R22,0,S22+T22,0,U22+V22) -> #N/A | L24: ==CHOOSE(MATCH(L23,B21:U21,0),B22-C22+D22,0,0,0,0,G22-H22+I22,0,0,0,0,L22-M22+N22,0,0,0,0,Q22+R22,0,S22+T22,0,U22+V22) -> #N/A | Q24: ==CHOOSE(MATCH(Q23,B21:U21,0),B22-C22+D22,0,0,0,0,G22-H22+I22,0,0,0,0,L22-M22+N22,0,0,0,0,Q22+R22,0,S22+T22,0,U22+V22) -> #N/A | S24: ==CHOOSE(MATCH(S23,B21:U21,0),B22-C22+D22,0,0,0,0,G22-H22+I22,0,0,0,0,L22-M22+N22,0,0,0,0,Q22+R22,0,S22+T22,0,U22+V22) -> #N/A | U24: ==CHOOSE(MATCH(U23,B21:U21,0),B22-C22+D22,0,0,0,0,G22-H22+I22,0,0,0,0,L22-M22+N22,0,0,0,0,Q22+R22,0,S22+T22,0,U22+V22) -> #N/A
A25: 11 | Q25: ==IF(OR(COUNTIF(AD23:AI23,0)>0,COUNTIF(AD25:AF25,0)>0),"",INDEX(AD23:AI23,MATCH(TRUE,ISNA(MATCH(AD23:AI23,AD25:AF25,0)),0))) | S25: ==IF(OR(COUNTIF(AD23:AI23,0)>0,COUNTIF(AD25:AG25,0)>0),"",INDEX(AD23:AI23,MATCH(TRUE,ISNA(MATCH(AD23:AI23,AD25:AG25,0)),0))) | U25: ==IF(OR(COUNTIF(AD23:AI23,0)>0,COUNTIF(AD25:AH25,0)>0),"",INDEX(AD23:AI23,MATCH(TRUE,ISNA(MATCH(AD23:AI23,AD25:AH25,0)),0))) | Y25: ==IF(OR(A23="前置OD1",A23="后置OD1"),AK25,IF(OR(A23="前置OD2",A23="后置OD2"),AL25,IF(OR(A23="前置OD3",A23="后置OD3"),AM25,IF(LEFT(A25,2)="后置",Y23+E24+J24+O24+W23,Y23+E24+J24+O24+W23+X23)))) -> 0 | Z25: ==IF(Y25<$AJ$4,Y25,$AJ$4) -> 0 | AA25: ==F26+K26+P26 -> 0 | AD25: ==B25 -> 0 | AE25: ==G25 -> 0 | AF25: ==L25 -> 0 | AG25: ==Q25 | AH25: ==S25 | AI25: ==U25 | AK25: ==Z23-$AJ$4/3+E24+J24+O24+X23 -> -100 | AL25: ==Z23-$AJ$4/3*2+E24+J24+O24+X23 -> -200 | AM25: ==Z23-$AJ$4+E24+J24+O24+X23 -> -300
B26: ==CHOOSE(MATCH(B25,B23:U23,0),B24-C24+D24,0,0,0,0,G24-H24+I24,0,0,0,0,L24-M24+N24,0,0,0,0,Q24+R24,0,S24+T24,0,U24+V24) -> #N/A | G26: ==CHOOSE(MATCH(G25,B23:U23,0),B24-C24+D24,0,0,0,0,G24-H24+I24,0,0,0,0,L24-M24+N24,0,0,0,0,Q24+R24,0,S24+T24,0,U24+V24) -> #N/A | L26: ==CHOOSE(MATCH(L25,B23:U23,0),B24-C24+D24,0,0,0,0,G24-H24+I24,0,0,0,0,L24-M24+N24,0,0,0,0,Q24+R24,0,S24+T24,0,U24+V24) -> #N/A | Q26: ==CHOOSE(MATCH(Q25,B23:U23,0),B24-C24+D24,0,0,0,0,G24-H24+I24,0,0,0,0,L24-M24+N24,0,0,0,0,Q24+R24,0,S24+T24,0,U24+V24) -> #N/A | S26: ==CHOOSE(MATCH(S25,B23:U23,0),B24-C24+D24,0,0,0,0,G24-H24+I24,0,0,0,0,L24-M24+N24,0,0,0,0,Q24+R24,0,S24+T24,0,U24+V24) -> #N/A | U26: ==CHOOSE(MATCH(U25,B23:U23,0),B24-C24+D24,0,0,0,0,G24-H24+I24,0,0,0,0,L24-M24+N24,0,0,0,0,Q24+R24,0,S24+T24,0,U24+V24) -> #N/A
A27: 12 | Q27: ==IF(OR(COUNTIF(AD25:AI25,0)>0,COUNTIF(AD27:AF27,0)>0),"",INDEX(AD25:AI25,MATCH(TRUE,ISNA(MATCH(AD25:AI25,AD27:AF27,0)),0))) | S27: ==IF(OR(COUNTIF(AD25:AI25,0)>0,COUNTIF(AD27:AG27,0)>0),"",INDEX(AD25:AI25,MATCH(TRUE,ISNA(MATCH(AD25:AI25,AD27:AG27,0)),0))) | U27: ==IF(OR(COUNTIF(AD25:AI25,0)>0,COUNTIF(AD27:AH27,0)>0),"",INDEX(AD25:AI25,MATCH(TRUE,ISNA(MATCH(AD25:AI25,AD27:AH27,0)),0))) | Y27: ==IF(OR(A25="前置OD1",A25="后置OD1"),AK27,IF(OR(A25="前置OD2",A25="后置OD2"),AL27,IF(OR(A25="前置OD3",A25="后置OD3"),AM27,IF(LEFT(A27,2)="后置",Y25+E26+J26+O26+W25,Y25+E26+J26+O26+W25+X25)))) -> 0 | Z27: ==IF(Y27<$AJ$4,Y27,$AJ$4) -> 0 | AA27: ==F28+K28+P28 -> 0 | AD27: ==B27 -> 0 | AE27: ==G27 -> 0 | AF27: ==L27 -> 0 | AG27: ==Q27 | AH27: ==S27 | AI27: ==U27 | AK27: ==Z25-$AJ$4/3+E26+J26+O26+X25 -> -100 | AL27: ==Z25-$AJ$4/3*2+E26+J26+O26+X25 -> -200 | AM27: ==Z25-$AJ$4+E26+J26+O26+X25 -> -300
B28: ==CHOOSE(MATCH(B27,B25:U25,0),B26-C26+D26,0,0,0,0,G26-H26+I26,0,0,0,0,L26-M26+N26,0,0,0,0,Q26+R26,0,S26+T26,0,U26+V26) -> #N/A | G28: ==CHOOSE(MATCH(G27,B25:U25,0),B26-C26+D26,0,0,0,0,G26-H26+I26,0,0,0,0,L26-M26+N26,0,0,0,0,Q26+R26,0,S26+T26,0,U26+V26) -> #N/A | L28: ==CHOOSE(MATCH(L27,B25:U25,0),B26-C26+D26,0,0,0,0,G26-H26+I26,0,0,0,0,L26-M26+N26,0,0,0,0,Q26+R26,0,S26+T26,0,U26+V26) -> #N/A | Q28: ==CHOOSE(MATCH(Q27,B25:U25,0),B26-C26+D26,0,0,0,0,G26-H26+I26,0,0,0,0,L26-M26+N26,0,0,0,0,Q26+R26,0,S26+T26,0,U26+V26) -> #N/A | S28: ==CHOOSE(MATCH(S27,B25:U25,0),B26-C26+D26,0,0,0,0,G26-H26+I26,0,0,0,0,L26-M26+N26,0,0,0,0,Q26+R26,0,S26+T26,0,U26+V26) -> #N/A | U28: ==CHOOSE(MATCH(U27,B25:U25,0),B26-C26+D26,0,0,0,0,G26-H26+I26,0,0,0,0,L26-M26+N26,0,0,0,0,Q26+R26,0,S26+T26,0,U26+V26) -> #N/A
A29: 13 | Q29: ==IF(OR(COUNTIF(AD27:AI27,0)>0,COUNTIF(AD29:AF29,0)>0),"",INDEX(AD27:AI27,MATCH(TRUE,ISNA(MATCH(AD27:AI27,AD29:AF29,0)),0))) | S29: ==IF(OR(COUNTIF(AD27:AI27,0)>0,COUNTIF(AD29:AG29,0)>0),"",INDEX(AD27:AI27,MATCH(TRUE,ISNA(MATCH(AD27:AI27,AD29:AG29,0)),0))) | U29: ==IF(OR(COUNTIF(AD27:AI27,0)>0,COUNTIF(AD29:AH29,0)>0),"",INDEX(AD27:AI27,MATCH(TRUE,ISNA(MATCH(AD27:AI27,AD29:AH29,0)),0))) | Y29: ==IF(OR(A27="前置OD1",A27="后置OD1"),AK29,IF(OR(A27="前置OD2",A27="后置OD2"),AL29,IF(OR(A27="前置OD3",A27="后置OD3"),AM29,IF(LEFT(A29,2)="后置",Y27+E28+J28+O28+W27,Y27+E28+J28+O28+W27+X27)))) -> 0 | Z29: ==IF(Y29<$AJ$4,Y29,$AJ$4) -> 0 | AA29: ==F30+K30+P30 -> 0 | AD29: ==B29 -> 0 | AE29: ==G29 -> 0 | AF29: ==L29 -> 0 | AG29: ==Q29 | AH29: ==S29 | AI29: ==U29 | AK29: ==Z27-$AJ$4/3+E28+J28+O28+X27 -> -100 | AL29: ==Z27-$AJ$4/3*2+E28+J28+O28+X27 -> -200 | AM29: ==Z27-$AJ$4+E28+J28+O28+X27 -> -300
B30: ==CHOOSE(MATCH(B29,B27:U27,0),B28-C28+D28,0,0,0,0,G28-H28+I28,0,0,0,0,L28-M28+N28,0,0,0,0,Q28+R28,0,S28+T28,0,U28+V28) -> #N/A | G30: ==CHOOSE(MATCH(G29,B27:U27,0),B28-C28+D28,0,0,0,0,G28-H28+I28,0,0,0,0,L28-M28+N28,0,0,0,0,Q28+R28,0,S28+T28,0,U28+V28) -> #N/A | L30: ==CHOOSE(MATCH(L29,B27:U27,0),B28-C28+D28,0,0,0,0,G28-H28+I28,0,0,0,0,L28-M28+N28,0,0,0,0,Q28+R28,0,S28+T28,0,U28+V28) -> #N/A | Q30: ==CHOOSE(MATCH(Q29,B27:U27,0),B28-C28+D28,0,0,0,0,G28-H28+I28,0,0,0,0,L28-M28+N28,0,0,0,0,Q28+R28,0,S28+T28,0,U28+V28) -> #N/A | S30: ==CHOOSE(MATCH(S29,B27:U27,0),B28-C28+D28,0,0,0,0,G28-H28+I28,0,0,0,0,L28-M28+N28,0,0,0,0,Q28+R28,0,S28+T28,0,U28+V28) -> #N/A | U30: ==CHOOSE(MATCH(U29,B27:U27,0),B28-C28+D28,0,0,0,0,G28-H28+I28,0,0,0,0,L28-M28+N28,0,0,0,0,Q28+R28,0,S28+T28,0,U28+V28) -> #N/A
A31: 14 | Q31: ==IF(OR(COUNTIF(AD29:AI29,0)>0,COUNTIF(AD31:AF31,0)>0),"",INDEX(AD29:AI29,MATCH(TRUE,ISNA(MATCH(AD29:AI29,AD31:AF31,0)),0))) | S31: ==IF(OR(COUNTIF(AD29:AI29,0)>0,COUNTIF(AD31:AG31,0)>0),"",INDEX(AD29:AI29,MATCH(TRUE,ISNA(MATCH(AD29:AI29,AD31:AG31,0)),0))) | U31: ==IF(OR(COUNTIF(AD29:AI29,0)>0,COUNTIF(AD31:AH31,0)>0),"",INDEX(AD29:AI29,MATCH(TRUE,ISNA(MATCH(AD29:AI29,AD31:AH31,0)),0))) | Y31: ==IF(OR(A29="前置OD1",A29="后置OD1"),AK31,IF(OR(A29="前置OD2",A29="后置OD2"),AL31,IF(OR(A29="前置OD3",A29="后置OD3"),AM31,IF(LEFT(A31,2)="后置",Y29+E30+J30+O30+W29,Y29+E30+J30+O30+W29+X29)))) -> 0 | Z31: ==IF(Y31<$AJ$4,Y31,$AJ$4) -> 0 | AA31: ==F32+K32+P32 -> 0 | AD31: ==B31 -> 0 | AE31: ==G31 -> 0 | AF31: ==L31 -> 0 | AG31: ==Q31 | AH31: ==S31 | AI31: ==U31 | AK31: ==Z29-$AJ$4/3+E30+J30+O30+X29 -> -100 | AL31: ==Z29-$AJ$4/3*2+E30+J30+O30+X29 -> -200 | AM31: ==Z29-$AJ$4+E30+J30+O30+X29 -> -300
B32: ==CHOOSE(MATCH(B31,B29:U29,0),B30-C30+D30,0,0,0,0,G30-H30+I30,0,0,0,0,L30-M30+N30,0,0,0,0,Q30+R30,0,S30+T30,0,U30+V30) -> #N/A | G32: ==CHOOSE(MATCH(G31,B29:U29,0),B30-C30+D30,0,0,0,0,G30-H30+I30,0,0,0,0,L30-M30+N30,0,0,0,0,Q30+R30,0,S30+T30,0,U30+V30) -> #N/A | L32: ==CHOOSE(MATCH(L31,B29:U29,0),B30-C30+D30,0,0,0,0,G30-H30+I30,0,0,0,0,L30-M30+N30,0,0,0,0,Q30+R30,0,S30+T30,0,U30+V30) -> #N/A | Q32: ==CHOOSE(MATCH(Q31,B29:U29,0),B30-C30+D30,0,0,0,0,G30-H30+I30,0,0,0,0,L30-M30+N30,0,0,0,0,Q30+R30,0,S30+T30,0,U30+V30) -> #N/A | S32: ==CHOOSE(MATCH(S31,B29:U29,0),B30-C30+D30,0,0,0,0,G30-H30+I30,0,0,0,0,L30-M30+N30,0,0,0,0,Q30+R30,0,S30+T30,0,U30+V30) -> #N/A | U32: ==CHOOSE(MATCH(U31,B29:U29,0),B30-C30+D30,0,0,0,0,G30-H30+I30,0,0,0,0,L30-M30+N30,0,0,0,0,Q30+R30,0,S30+T30,0,U30+V30) -> #N/A
A33: 15 | Q33: ==IF(OR(COUNTIF(AD31:AI31,0)>0,COUNTIF(AD33:AF33,0)>0),"",INDEX(AD31:AI31,MATCH(TRUE,ISNA(MATCH(AD31:AI31,AD33:AF33,0)),0))) | S33: ==IF(OR(COUNTIF(AD31:AI31,0)>0,COUNTIF(AD33:AG33,0)>0),"",INDEX(AD31:AI31,MATCH(TRUE,ISNA(MATCH(AD31:AI31,AD33:AG33,0)),0))) | U33: ==IF(OR(COUNTIF(AD31:AI31,0)>0,COUNTIF(AD33:AH33,0)>0),"",INDEX(AD31:AI31,MATCH(TRUE,ISNA(MATCH(AD31:AI31,AD33:AH33,0)),0))) | Y33: ==IF(OR(A31="前置OD1",A31="后置OD1"),AK33,IF(OR(A31="前置OD2",A31="后置OD2"),AL33,IF(OR(A31="前置OD3",A31="后置OD3"),AM33,IF(LEFT(A33,2)="后置",Y31+E32+J32+O32+W31,Y31+E32+J32+O32+W31+X31)))) -> 0 | Z33: ==IF(Y33<$AJ$4,Y33,$AJ$4) -> 0 | AA33: ==F34+K34+P34 -> 0 | AD33: ==B33 -> 0 | AE33: ==G33 -> 0 | AF33: ==L33 -> 0 | AG33: ==Q33 | AH33: ==S33 | AI33: ==U33 | AK33: ==Z31-$AJ$4/3+E32+J32+O32+X31 -> -100 | AL33: ==Z31-$AJ$4/3*2+E32+J32+O32+X31 -> -200 | AM33: ==Z31-$AJ$4+E32+J32+O32+X31 -> -300
B34: ==CHOOSE(MATCH(B33,B31:U31,0),B32-C32+D32,0,0,0,0,G32-H32+I32,0,0,0,0,L32-M32+N32,0,0,0,0,Q32+R32,0,S32+T32,0,U32+V32) -> #N/A | G34: ==CHOOSE(MATCH(G33,B31:U31,0),B32-C32+D32,0,0,0,0,G32-H32+I32,0,0,0,0,L32-M32+N32,0,0,0,0,Q32+R32,0,S32+T32,0,U32+V32) -> #N/A | L34: ==CHOOSE(MATCH(L33,B31:U31,0),B32-C32+D32,0,0,0,0,G32-H32+I32,0,0,0,0,L32-M32+N32,0,0,0,0,Q32+R32,0,S32+T32,0,U32+V32) -> #N/A | Q34: ==CHOOSE(MATCH(Q33,B31:U31,0),B32-C32+D32,0,0,0,0,G32-H32+I32,0,0,0,0,L32-M32+N32,0,0,0,0,Q32+R32,0,S32+T32,0,U32+V32) -> #N/A | S34: ==CHOOSE(MATCH(S33,B31:U31,0),B32-C32+D32,0,0,0,0,G32-H32+I32,0,0,0,0,L32-M32+N32,0,0,0,0,Q32+R32,0,S32+T32,0,U32+V32) -> #N/A | U34: ==CHOOSE(MATCH(U33,B31:U31,0),B32-C32+D32,0,0,0,0,G32-H32+I32,0,0,0,0,L32-M32+N32,0,0,0,0,Q32+R32,0,S32+T32,0,U32+V32) -> #N/A
A35: 16 | Q35: ==IF(OR(COUNTIF(AD33:AI33,0)>0,COUNTIF(AD35:AF35,0)>0),"",INDEX(AD33:AI33,MATCH(TRUE,ISNA(MATCH(AD33:AI33,AD35:AF35,0)),0))) | S35: ==IF(OR(COUNTIF(AD33:AI33,0)>0,COUNTIF(AD35:AG35,0)>0),"",INDEX(AD33:AI33,MATCH(TRUE,ISNA(MATCH(AD33:AI33,AD35:AG35,0)),0))) | U35: ==IF(OR(COUNTIF(AD33:AI33,0)>0,COUNTIF(AD35:AH35,0)>0),"",INDEX(AD33:AI33,MATCH(TRUE,ISNA(MATCH(AD33:AI33,AD35:AH35,0)),0))) | Y35: ==IF(OR(A33="前置OD1",A33="后置OD1"),AK35,IF(OR(A33="前置OD2",A33="后置OD2"),AL35,IF(OR(A33="前置OD3",A33="后置OD3"),AM35,IF(LEFT(A35,2)="后置",Y33+E34+J34+O34+W33,Y33+E34+J34+O34+W33+X33)))) -> 0 | Z35: ==IF(Y35<$AJ$4,Y35,$AJ$4) -> 0 | AA35: ==F36+K36+P36 -> 0 | AD35: ==B35 -> 0 | AE35: ==G35 -> 0 | AF35: ==L35 -> 0 | AG35: ==Q35 | AH35: ==S35 | AI35: ==U35 | AK35: ==Z33-$AJ$4/3+E34+J34+O34+X33 -> -100 | AL35: ==Z33-$AJ$4/3*2+E34+J34+O34+X33 -> -200 | AM35: ==Z33-$AJ$4+E34+J34+O34+X33 -> -300
B36: ==CHOOSE(MATCH(B35,B33:U33,0),B34-C34+D34,0,0,0,0,G34-H34+I34,0,0,0,0,L34-M34+N34,0,0,0,0,Q34+R34,0,S34+T34,0,U34+V34) -> #N/A | G36: ==CHOOSE(MATCH(G35,B33:U33,0),B34-C34+D34,0,0,0,0,G34-H34+I34,0,0,0,0,L34-M34+N34,0,0,0,0,Q34+R34,0,S34+T34,0,U34+V34) -> #N/A | L36: ==CHOOSE(MATCH(L35,B33:U33,0),B34-C34+D34,0,0,0,0,G34-H34+I34,0,0,0,0,L34-M34+N34,0,0,0,0,Q34+R34,0,S34+T34,0,U34+V34) -> #N/A | Q36: ==CHOOSE(MATCH(Q35,B33:U33,0),B34-C34+D34,0,0,0,0,G34-H34+I34,0,0,0,0,L34-M34+N34,0,0,0,0,Q34+R34,0,S34+T34,0,U34+V34) -> #N/A | S36: ==CHOOSE(MATCH(S35,B33:U33,0),B34-C34+D34,0,0,0,0,G34-H34+I34,0,0,0,0,L34-M34+N34,0,0,0,0,Q34+R34,0,S34+T34,0,U34+V34) -> #N/A | U36: ==CHOOSE(MATCH(U35,B33:U33,0),B34-C34+D34,0,0,0,0,G34-H34+I34,0,0,0,0,L34-M34+N34,0,0,0,0,Q34+R34,0,S34+T34,0,U34+V34) -> #N/A
A37: 17 | Q37: ==IF(OR(COUNTIF(AD35:AI35,0)>0,COUNTIF(AD37:AF37,0)>0),"",INDEX(AD35:AI35,MATCH(TRUE,ISNA(MATCH(AD35:AI35,AD37:AF37,0)),0))) | S37: ==IF(OR(COUNTIF(AD35:AI35,0)>0,COUNTIF(AD37:AG37,0)>0),"",INDEX(AD35:AI35,MATCH(TRUE,ISNA(MATCH(AD35:AI35,AD37:AG37,0)),0))) | U37: ==IF(OR(COUNTIF(AD35:AI35,0)>0,COUNTIF(AD37:AH37,0)>0),"",INDEX(AD35:AI35,MATCH(TRUE,ISNA(MATCH(AD35:AI35,AD37:AH37,0)),0))) | Y37: ==IF(OR(A35="前置OD1",A35="后置OD1"),AK37,IF(OR(A35="前置OD2",A35="后置OD2"),AL37,IF(OR(A35="前置OD3",A35="后置OD3"),AM37,IF(LEFT(A37,2)="后置",Y35+E36+J36+O36+W35,Y35+E36+J36+O36+W35+X35)))) -> 0 | Z37: ==IF(Y37<$AJ$4,Y37,$AJ$4) -> 0 | AA37: ==F38+K38+P38 -> 0 | AD37: ==B37 -> 0 | AE37: ==G37 -> 0 | AF37: ==L37 -> 0 | AG37: ==Q37 | AH37: ==S37 | AI37: ==U37 | AK37: ==Z35-$AJ$4/3+E36+J36+O36+X35 -> -100 | AL37: ==Z35-$AJ$4/3*2+E36+J36+O36+X35 -> -200 | AM37: ==Z35-$AJ$4+E36+J36+O36+X35 -> -300
B38: ==CHOOSE(MATCH(B37,B35:U35,0),B36-C36+D36,0,0,0,0,G36-H36+I36,0,0,0,0,L36-M36+N36,0,0,0,0,Q36+R36,0,S36+T36,0,U36+V36) -> #N/A | G38: ==CHOOSE(MATCH(G37,B35:U35,0),B36-C36+D36,0,0,0,0,G36-H36+I36,0,0,0,0,L36-M36+N36,0,0,0,0,Q36+R36,0,S36+T36,0,U36+V36) -> #N/A | L38: ==CHOOSE(MATCH(L37,B35:U35,0),B36-C36+D36,0,0,0,0,G36-H36+I36,0,0,0,0,L36-M36+N36,0,0,0,0,Q36+R36,0,S36+T36,0,U36+V36) -> #N/A | Q38: ==CHOOSE(MATCH(Q37,B35:U35,0),B36-C36+D36,0,0,0,0,G36-H36+I36,0,0,0,0,L36-M36+N36,0,0,0,0,Q36+R36,0,S36+T36,0,U36+V36) -> #N/A | S38: ==CHOOSE(MATCH(S37,B35:U35,0),B36-C36+D36,0,0,0,0,G36-H36+I36,0,0,0,0,L36-M36+N36,0,0,0,0,Q36+R36,0,S36+T36,0,U36+V36) -> #N/A | U38: ==CHOOSE(MATCH(U37,B35:U35,0),B36-C36+D36,0,0,0,0,G36-H36+I36,0,0,0,0,L36-M36+N36,0,0,0,0,Q36+R36,0,S36+T36,0,U36+V36) -> #N/A
A39: 18 | Q39: ==IF(OR(COUNTIF(AD37:AI37,0)>0,COUNTIF(AD39:AF39,0)>0),"",INDEX(AD37:AI37,MATCH(TRUE,ISNA(MATCH(AD37:AI37,AD39:AF39,0)),0))) | S39: ==IF(OR(COUNTIF(AD37:AI37,0)>0,COUNTIF(AD39:AG39,0)>0),"",INDEX(AD37:AI37,MATCH(TRUE,ISNA(MATCH(AD37:AI37,AD39:AG39,0)),0))) | U39: ==IF(OR(COUNTIF(AD37:AI37,0)>0,COUNTIF(AD39:AH39,0)>0),"",INDEX(AD37:AI37,MATCH(TRUE,ISNA(MATCH(AD37:AI37,AD39:AH39,0)),0))) | Y39: ==IF(OR(A37="前置OD1",A37="后置OD1"),AK39,IF(OR(A37="前置OD2",A37="后置OD2"),AL39,IF(OR(A37="前置OD3",A37="后置OD3"),AM39,IF(LEFT(A39,2)="后置",Y37+E38+J38+O38+W37,Y37+E38+J38+O38+W37+X37)))) -> 0 | Z39: ==IF(Y39<$AJ$4,Y39,$AJ$4) -> 0 | AA39: ==F40+K40+P40 -> 0 | AD39: ==B39 -> 0 | AE39: ==G39 -> 0 | AF39: ==L39 -> 0 | AG39: ==Q39 | AH39: ==S39 | AI39: ==U39 | AK39: ==Z37-$AJ$4/3+E38+J38+O38+X37 -> -100 | AL39: ==Z37-$AJ$4/3*2+E38+J38+O38+X37 -> -200 | AM39: ==Z37-$AJ$4+E38+J38+O38+X37 -> -300
B40: ==CHOOSE(MATCH(B39,B37:U37,0),B38-C38+D38,0,0,0,0,G38-H38+I38,0,0,0,0,L38-M38+N38,0,0,0,0,Q38+R38,0,S38+T38,0,U38+V38) -> #N/A | G40: ==CHOOSE(MATCH(G39,B37:U37,0),B38-C38+D38,0,0,0,0,G38-H38+I38,0,0,0,0,L38-M38+N38,0,0,0,0,Q38+R38,0,S38+T38,0,U38+V38) -> #N/A | L40: ==CHOOSE(MATCH(L39,B37:U37,0),B38-C38+D38,0,0,0,0,G38-H38+I38,0,0,0,0,L38-M38+N38,0,0,0,0,Q38+R38,0,S38+T38,0,U38+V38) -> #N/A | Q40: ==CHOOSE(MATCH(Q39,B37:U37,0),B38-C38+D38,0,0,0,0,G38-H38+I38,0,0,0,0,L38-M38+N38,0,0,0,0,Q38+R38,0,S38+T38,0,U38+V38) -> #N/A | S40: ==CHOOSE(MATCH(S39,B37:U37,0),B38-C38+D38,0,0,0,0,G38-H38+I38,0,0,0,0,L38-M38+N38,0,0,0,0,Q38+R38,0,S38+T38,0,U38+V38) -> #N/A | U40: ==CHOOSE(MATCH(U39,B37:U37,0),B38-C38+D38,0,0,0,0,G38-H38+I38,0,0,0,0,L38-M38+N38,0,0,0,0,Q38+R38,0,S38+T38,0,U38+V38) -> #N/A
...

Sheet 简轴
A1: 【标题】（比如 第xx期打分 xx队 无限od流） | G1: 轴作者
A2: 队伍组成（前 | 后） | C2: ==_xlfn.TEXTJOIN(" ",TRUE,排轴!B3,排轴!G3,排轴!L3) | E2: ==_xlfn.TEXTJOIN(" ",TRUE,排轴!Q3,排轴!S3,排轴!U3)
A3: 【注意事项】（比如耳环、突破要求等）
A6: 回合 | B6: 行动轴 | H6: 当前OD | I6: P
A7: ==排轴!A5 -> 1 | B7: ==排轴!B5 -> 0 | C7: ==排轴!C5 -> 0 | D7: ==排轴!G5 -> 0 | E7: ==排轴!H5 -> 0 | F7: ==排轴!L5 -> 0 | G7: ==排轴!M5 -> 0 | H7: ==排轴!Y5 -> 0 | I7: ☐
A8: ==排轴!A7 -> 0 | B8: ==排轴!B7 -> 0 | C8: ==排轴!C7 -> 0 | D8: ==排轴!G7 -> 0 | E8: ==排轴!H7 -> 0 | F8: ==排轴!L7 -> 0 | G8: ==排轴!M7 -> 0 | H8: ==排轴!Y7 -> 0 | I8: ☐
A9: ==排轴!A9 -> 0 | B9: ==排轴!B9 -> 0 | C9: ==排轴!C9 -> 0 | D9: ==排轴!G9 -> 0 | E9: ==排轴!H9 -> 0 | F9: ==排轴!L9 -> 0 | G9: ==排轴!M9 -> 0 | H9: ==排轴!Y9 -> 0 | I9: ☐
A10: ==排轴!A11 -> 0 | B10: ==排轴!B11 -> 0 | C10: ==排轴!C11 -> 0 | D10: ==排轴!G11 -> 0 | E10: ==排轴!H11 -> 0 | F10: ==排轴!L11 -> 0 | G10: ==排轴!M11 -> 0 | H10: ==排轴!Y11 -> 0 | I10: ☐
A11: ==排轴!A13 -> 0 | B11: ==排轴!B13 -> 0 | C11: ==排轴!C13 -> 0 | D11: ==排轴!G13 -> 0 | E11: ==排轴!H13 -> 0 | F11: ==排轴!L13 -> 0 | G11: ==排轴!M13 -> 0 | H11: ==排轴!Y13 -> 0 | I11: ☐
A12: ==排轴!A15 -> 0 | B12: ==排轴!B15 -> 0 | C12: ==排轴!C15 -> 0 | D12: ==排轴!G15 -> 0 | E12: ==排轴!H15 -> 0 | F12: ==排轴!L15 -> 0 | G12: ==排轴!M15 -> 0 | H12: ==排轴!Y15 -> 0 | I12: ☐
A13: ==排轴!A17 -> 7 | B13: ==排轴!B17 -> 0 | C13: ==排轴!C17 -> 0 | D13: ==排轴!G17 -> 0 | E13: ==排轴!H17 -> 0 | F13: ==排轴!L17 -> 0 | G13: ==排轴!M17 -> 0 | H13: ==排轴!Y17 -> 0 | I13: ☐
A14: ==排轴!A19 -> 8 | B14: ==排轴!B19 -> 0 | C14: ==排轴!C19 -> 0 | D14: ==排轴!G19 -> 0 | E14: ==排轴!H19 -> 0 | F14: ==排轴!L19 -> 0 | G14: ==排轴!M19 -> 0 | H14: ==排轴!Y19 -> 0 | I14: ☐
A15: ==排轴!A21 -> 9 | B15: ==排轴!B21 -> 0 | C15: ==排轴!C21 -> 0 | D15: ==排轴!G21 -> 0 | E15: ==排轴!H21 -> 0 | F15: ==排轴!L21 -> 0 | G15: ==排轴!M21 -> 0 | H15: ==排轴!Y21 -> 0 | I15: ☐
A16: ==排轴!A23 -> 10 | B16: ==排轴!B23 -> 0 | C16: ==排轴!C23 -> 0 | D16: ==排轴!G23 -> 0 | E16: ==排轴!H23 -> 0 | F16: ==排轴!L23 -> 0 | G16: ==排轴!M23 -> 0 | H16: ==排轴!Y23 -> 0 | I16: ☐
A17: ==排轴!A25 -> 11 | B17: ==排轴!B25 -> 0 | C17: ==排轴!C25 -> 0 | D17: ==排轴!G25 -> 0 | E17: ==排轴!H25 -> 0 | F17: ==排轴!L25 -> 0 | G17: ==排轴!M25 -> 0 | H17: ==排轴!Y25 -> 0 | I17: ☐
A18: ==排轴!A27 -> 12 | B18: ==排轴!B27 -> 0 | C18: ==排轴!C27 -> 0 | D18: ==排轴!G27 -> 0 | E18: ==排轴!H27 -> 0 | F18: ==排轴!L27 -> 0 | G18: ==排轴!M27 -> 0 | H18: ==排轴!Y27 -> 0 | I18: ☐
A19: ==排轴!A29 -> 13 | B19: ==排轴!B29 -> 0 | C19: ==排轴!C29 -> 0 | D19: ==排轴!G29 -> 0 | E19: ==排轴!H29 -> 0 | F19: ==排轴!L29 -> 0 | G19: ==排轴!M29 -> 0 | H19: ==排轴!Y29 -> 0 | I19: ☐
A20: ==排轴!A31 -> 14 | B20: ==排轴!B31 -> 0 | C20: ==排轴!C31 -> 0 | D20: ==排轴!G31 -> 0 | E20: ==排轴!H31 -> 0 | F20: ==排轴!L31 -> 0 | G20: ==排轴!M31 -> 0 | H20: ==排轴!Y31 -> 0 | I20: ☐
A21: ==排轴!A33 -> 15 | B21: ==排轴!B33 -> 0 | C21: ==排轴!C33 -> 0 | D21: ==排轴!G33 -> 0 | E21: ==排轴!H33 -> 0 | F21: ==排轴!L33 -> 0 | G21: ==排轴!M33 -> 0 | H21: ==排轴!Y33 -> 0 | I21: ☐
A22: ==排轴!A35 -> 16 | B22: ==排轴!B35 -> 0 | C22: ==排轴!C35 -> 0 | D22: ==排轴!G35 -> 0 | E22: ==排轴!H35 -> 0 | F22: ==排轴!L35 -> 0 | G22: ==排轴!M35 -> 0 | H22: ==排轴!Y35 -> 0 | I22: ☐
A23: ==排轴!A37 -> 17 | B23: ==排轴!B37 -> 0 | C23: ==排轴!C37 -> 0 | D23: ==排轴!G37 -> 0 | E23: ==排轴!H37 -> 0 | F23: ==排轴!L37 -> 0 | G23: ==排轴!M37 -> 0 | H23: ==排轴!Y37 -> 0 | I23: ☐
A24: ==排轴!A39 -> 18 | B24: ==排轴!B39 -> 0 | C24: ==排轴!C39 -> 0 | D24: ==排轴!G39 -> 0 | E24: ==排轴!H39 -> 0 | F24: ==排轴!L39 -> 0 | G24: ==排轴!M39 -> 0 | H24: ==排轴!Y39 -> 0 | I24: ☐
A25: ==排轴!A41 -> 19 | B25: ==排轴!B41 -> 0 | C25: ==排轴!C41 -> 0 | D25: ==排轴!G41 -> 0 | E25: ==排轴!H41 -> 0 | F25: ==排轴!L41 -> 0 | G25: ==排轴!M41 -> 0 | H25: ==排轴!Y41 -> 0 | I25: ☐
A26: ==排轴!A43 -> 20 | B26: ==排轴!B43 -> 0 | C26: ==排轴!C43 -> 0 | D26: ==排轴!G43 -> 0 | E26: ==排轴!H43 -> 0 | F26: ==排轴!L43 -> 0 | G26: ==排轴!M43 -> 0 | H26: ==排轴!Y43 -> 0 | I26: ☐
