Workbook
Name pre: 预置配装!$A$5:$A$15

Sheet 白值计算
D1: Power | E1: Dexterity | F1: Toughness | G1: Spirit | H1: Wisdom | I1: Luck
A2: 说明：默认A-S战术型态全持有且满破满强化，若不符合条件请在基础值修正行中手动修正
C5: ID | D5: 71 | E5: 请输入2-71 | G5: 请在SS偏向统计中查询角色ID
C6: Label | F6: 选填
D7: MinPower | E7: MaxPower | F7: MinDexterity | G7: MaxDexterity | H7: MinToughness | I7: MaxToughness | J7: MinSpirit | K7: MaxSpirit | L7: MinWisdom | M7: MaxWisdom | N7: MinLuck | O7: MaxLuck
D8: {=_xlfn.SWITCH(D5,2,全角色白值成长!E2,3,全角色白值成长!E3,4,全角色白值成长!E4,5,全角色白值成长!E5,6,全角色白值成长!E6,7,全角色白值成长!E7,8,全角色白值成长!E8,9,全角色白值成长!E9,10,全角色白值成长!E10,11,全角色白值成长!E11,12,全角色白值成长!E12,13,全角色白值成长!E13,14,全角色白值成长!E14,15,全角色白值成长!E15,16,全角色白值成长!E16,17,全角色白值成长!E17,18,全角色白值成长!E18,19,全角色白值成长!E19,20,全角色白值成长!E20,21,全角色白值成长!E21,22,全角色白值成长!E22,23,全角色白值成长!E23,24,全角色白值成长!E24,25,全角色白值成长!E25,26,全角色白值成长!E26,27,全角色白值成长!E27,28,全角色白值成长!E28,29,全角色白值成长!E29,30,全角色白值成长!E30,31,全角色白值成长!E31,32,全角色白值成长!E32,33,全角色白值成长!E33,34,全角色白值成长!E34,35,全角色白值成长!E35,36,全角色白值成长!E36,37,全角色白值成长!E37,38,全角色白值成长!E38,39,全角色白值成长!E39,40,全角色白值成长!E40,41,全角色白值成长!E41,42,全角色白值成长!E42,43,全角色白值成长!E43,44,全角色白值成长!E44,45,全角色白值成长!E45,46,全角色白值成长!E46,47,全角色白值成长!E47,48,全角色白值成长!E48,49,全角色白值成长!E49,50,全角色白值成长!E50,51,全角色白值成长!E51,52,全角色白值成长!E52,53,全角色白值成长!E53,54,全角色白值成长!E54,55,全角色白值成长!E55,56,全角色白值成长!E56,57,全角色白值成长!E57,58,全角色白值成长!E58,59,全角色白值成长!E59,60,全角色白值成长!E60,61,全角色白值成长!E61,62,全角色白值成长!E62,63,全角色白值成长!E63,64,全角色白值成长!E64,65,全角色白值成长!E65,66,全角色白值成长!E66,67,全角色白值成长!E67,68,全角色白值成长!E68,69,全角色白值成长!E69,70,全角色白值成长!E70,71,全角色白值成长!E71)} -> 9 | E8: {=_xlfn.SWITCH(D5,2,全角色白值成长!F2,3,全角色白值成长!F3,4,全角色白值成长!F4,5,全角色白值成长!F5,6,全角色白值成长!F6,7,全角色白值成长!F7,8,全角色白值成长!F8,9,全角色白值成长!F9,10,全角色白值成长!F10,11,全角色白值成长!F11,12,全角色白值成长!F12,13,全角色白值成长!F13,14,全角色白值成长!F14,15,全角色白值成长!F15,16,全角色白值成长!F16,17,全角色白值成长!F17,18,全角色白值成长!F18,19,全角色白值成长!F19,20,全角色白值成长!F20,21,全角色白值成长!F21,22,全角色白值成长!F22,23,全角色白值成长!F23,24,全角色白值成长!F24,25,全角色白值成长!F25,26,全角色白值成长!F26,27,全角色白值成长!F27,28,全角色白值成长!F28,29,全角色白值成长!F29,30,全角色白值成长!F30,31,全角色白值成长!F31,32,全角色白值成长!F32,33,全角色白值成长!F33,34,全角色白值成长!F34,35,全角色白值成长!F35,36,全角色白值成长!F36,37,全角色白值成长!F37,38,全角色白值成长!F38,39,全角色白值成长!F39,40,全角色白值成长!F40,41,全角色白值成长!F41,42,全角色白值成长!F42,43,全角色白值成长!F43,44,全角色白值成长!F44,45,全角色白值成长!F45,46,全角色白值成长!F46,47,全角色白值成长!F47,48,全角色白值成长!F48,49,全角色白值成长!F49,50,全角色白值成长!F50,51,全角色白值成长!F51,52,全角色白值成长!F52,53,全角色白值成长!F53,54,全角色白值成长!F54,55,全角色白值成长!F55,56,全角色白值成长!F56,57,全角色白值成长!F57,58,全角色白值成长!F58,59,全角色白值成长!F59,60,全角色白值成长!F60,61,全角色白值成长!F61,62,全角色白值成长!F62,63,全角色白值成长!F63,64,全角色白值成长!F64,65,全角色白值成长!F65,66,全角色白值成长!F66,67,全角色白值成长!F67,68,全角色白值成长!F68,69,全角色白值成长!F69,70,全角色白值成长!F70,71,全角色白值成长!F71)} -> 214 | F8: {=_xlfn.SWITCH(D5,2,全角色白值成长!G2,3,全角色白值成长!G3,4,全角色白值成长!G4,5,全角色白值成长!G5,6,全角色白值成长!G6,7,全角色白值成长!G7,8,全角色白值成长!G8,9,全角色白值成长!G9,10,全角色白值成长!G10,11,全角色白值成长!G11,12,全角色白值成长!G12,13,全角色白值成长!G13,14,全角色白值成长!G14,15,全角色白值成长!G15,16,全角色白值成长!G16,17,全角色白值成长!G17,18,全角色白值成长!G18,19,全角色白值成长!G19,20,全角色白值成长!G20,21,全角色白值成长!G21,22,全角色白值成长!G22,23,全角色白值成长!G23,24,全角色白值成长!G24,25,全角色白值成长!G25,26,全角色白值成长!G26,27,全角色白值成长!G27,28,全角色白值成长!G28,29,全角色白值成长!G29,30,全角色白值成长!G30,31,全角色白值成长!G31,32,全角色白值成长!G32,33,全角色白值成长!G33,34,全角色白值成长!G34,35,全角色白值成长!G35,36,全角色白值成长!G36,37,全角色白值成长!G37,38,全角色白值成长!G38,39,全角色白值成长!G39,40,全角色白值成长!G40,41,全角色白值成长!G41,42,全角色白值成长!G42,43,全角色白值成长!G43,44,全角色白值成长!G44,45,全角色白值成长!G45,46,全角色白值成长!G46,47,全角色白值成长!G47,48,全角色白值成长!G48,49,全角色白值成长!G49,50,全角色白值成长!G50,51,全角色白值成长!G51,52,全角色白值成长!G52,53,全角色白值成长!G53,54,全角色白值成长!G54,55,全角色白值成长!G55,56,全角色白值成长!G56,57,全角色白值成长!G57,58,全角色白值成长!G58,59,全角色白值成长!G59,60,全角色白值成长!G60,61,全角色白值成长!G61,62,全角色白值成长!G62,63,全角色白值成长!G63,64,全角色白值成长!G64,65,全角色白值成长!G65,66,全角色白值成长!G66,67,全角色白值成长!G67,68,全角色白值成长!G68,69,全角色白值成长!G69,70,全角色白值成长!G70,71,全角色白值成长!G71)} -> 7 | G8: {=_xlfn.SWITCH(D5,2,全角色白值成长!H2,3,全角色白值成长!H3,4,全角色白值成长!H4,5,全角色白值成长!H5,6,全角色白值成长!H6,7,全角色白值成长!H7,8,全角色白值成长!H8,9,全角色白值成长!H9,10,全角色白值成长!H10,11,全角色白值成长!H11,12,全角色白值成长!H12,13,全角色白值成长!H13,14,全角色白值成长!H14,15,全角色白值成长!H15,16,全角色白值成长!H16,17,全角色白值成长!H17,18,全角色白值成长!H18,19,全角色白值成长!H19,20,全角色白值成长!H20,21,全角色白值成长!H21,22,全角色白值成长!H22,23,全角色白值成长!H23,24,全角色白值成长!H24,25,全角色白值成长!H25,26,全角色白值成长!H26,27,全角色白值成长!H27,28,全角色白值成长!H28,29,全角色白值成长!H29,30,全角色白值成长!H30,31,全角色白值成长!H31,32,全角色白值成长!H32,33,全角色白值成长!H33,34,全角色白值成长!H34,35,全角色白值成长!H35,36,全角色白值成长!H36,37,全角色白值成长!H37,38,全角色白值成长!H38,39,全角色白值成长!H39,40,全角色白值成长!H40,41,全角色白值成长!H41,42,全角色白值成长!H42,43,全角色白值成长!H43,44,全角色白值成长!H44,45,全角色白值成长!H45,46,全角色白值成长!H46,47,全角色白值成长!H47,48,全角色白值成长!H48,49,全角色白值成长!H49,50,全角色白值成长!H50,51,全角色白值成长!H51,52,全角色白值成长!H52,53,全角色白值成长!H53,54,全角色白值成长!H54,55,全角色白值成长!H55,56,全角色白值成长!H56,57,全角色白值成长!H57,58,全角色白值成长!H58,59,全角色白值成长!H59,60,全角色白值成长!H60,61,全角色白值成长!H61,62,全角色白值成长!H62,63,全角色白值成长!H63,64,全角色白值成长!H64,65,全角色白值成长!H65,66,全角色白值成长!H66,67,全角色白值成长!H67,68,全角色白值成长!H68,69,全角色白值成长!H69,70,全角色白值成长!H70,71,全角色白值成长!H71)} -> 206 | H8: {=_xlfn.SWITCH(D5,2,全角色白值成长!I2,3,全角色白值成长!I3,4,全角色白值成长!I4,5,全角色白值成长!I5,6,全角色白值成长!I6,7,全角色白值成长!I7,8,全角色白值成长!I8,9,全角色白值成长!I9,10,全角色白值成长!I10,11,全角色白值成长!I11,12,全角色白值成长!I12,13,全角色白值成长!I13,14,全角色白值成长!I14,15,全角色白值成长!I15,16,全角色白值成长!I16,17,全角色白值成长!I17,18,全角色白值成长!I18,19,全角色白值成长!I19,20,全角色白值成长!I20,21,全角色白值成长!I21,22,全角色白值成长!I22,23,全角色白值成长!I23,24,全角色白值成长!I24,25,全角色白值成长!I25,26,全角色白值成长!I26,27,全角色白值成长!I27,28,全角色白值成长!I28,29,全角色白值成长!I29,30,全角色白值成长!I30,31,全角色白值成长!I31,32,全角色白值成长!I32,33,全角色白值成长!I33,34,全角色白值成长!I34,35,全角色白值成长!I35,36,全角色白值成长!I36,37,全角色白值成长!I37,38,全角色白值成长!I38,39,全角色白值成长!I39,40,全角色白值成长!I40,41,全角色白值成长!I41,42,全角色白值成长!I42,43,全角色白值成长!I43,44,全角色白值成长!I44,45,全角色白值成长!I45,46,全角色白值成长!I46,47,全角色白值成长!I47,48,全角色白值成长!I48,49,全角色白值成长!I49,50,全角色白值成长!I50,51,全角色白值成长!I51,52,全角色白值成长!I52,53,全角色白值成长!I53,54,全角色白值成长!I54,55,全角色白值成长!I55,56,全角色白值成长!I56,57,全角色白值成长!I57,58,全角色白值成长!I58,59,全角色白值成长!I59,60,全角色白值成长!I60,61,全角色白值成长!I61,62,全角色白值成长!I62,63,全角色白值成长!I63,64,全角色白值成长!I64,65,全角色白值成长!I65,66,全角色白值成长!I66,67,全角色白值成长!I67,68,全角色白值成长!I68,69,全角色白值成长!I69,70,全角色白值成长!I70,71,全角色白值成长!I71)} -> 8 | I8: {=_xlfn.SWITCH(D5,2,全角色白值成长!J2,3,全角色白值成长!J3,4,全角色白值成长!J4,5,全角色白值成长!J5,6,全角色白值成长!J6,7,全角色白值成长!J7,8,全角色白值成长!J8,9,全角色白值成长!J9,10,全角色白值成长!J10,11,全角色白值成长!J11,12,全角色白值成长!J12,13,全角色白值成长!J13,14,全角色白值成长!J14,15,全角色白值成长!J15,16,全角色白值成长!J16,17,全角色白值成长!J17,18,全角色白值成长!J18,19,全角色白值成长!J19,20,全角色白值成长!J20,21,全角色白值成长!J21,22,全角色白值成长!J22,23,全角色白值成长!J23,24,全角色白值成长!J24,25,全角色白值成长!J25,26,全角色白值成长!J26,27,全角色白值成长!J27,28,全角色白值成长!J28,29,全角色白值成长!J29,30,全角色白值成长!J30,31,全角色白值成长!J31,32,全角色白值成长!J32,33,全角色白值成长!J33,34,全角色白值成长!J34,35,全角色白值成长!J35,36,全角色白值成长!J36,37,全角色白值成长!J37,38,全角色白值成长!J38,39,全角色白值成长!J39,40,全角色白值成长!J40,41,全角色白值成长!J41,42,全角色白值成长!J42,43,全角色白值成长!J43,44,全角色白值成长!J44,45,全角色白值成长!J45,46,全角色白值成长!J46,47,全角色白值成长!J47,48,全角色白值成长!J48,49,全角色白值成长!J49,50,全角色白值成长!J50,51,全角色白值成长!J51,52,全角色白值成长!J52,53,全角色白值成长!J53,54,全角色白值成长!J54,55,全角色白值成长!J55,56,全角色白值成长!J56,57,全角色白值成长!J57,58,全角色白值成长!J58,59,全角色白值成长!J59,60,全角色白值成长!J60,61,全角色白值成长!J61,62,全角色白值成长!J62,63,全角色白值成长!J63,64,全角色白值成长!J64,65,全角色白值成长!J65,66,全角色白值成长!J66,67,全角色白值成长!J67,68,全角色白值成长!J68,69,全角色白值成长!J69,70,全角色白值成长!J70,71,全角色白值成长!J71)} -> 210 | J8: {=_xlfn.SWITCH(D5,2,全角色白值成长!K2,3,全角色白值成长!K3,4,全角色白值成长!K4,5,全角色白值成长!K5,6,全角色白值成长!K6,7,全角色白值成长!K7,8,全角色白值成长!K8,9,全角色白值成长!K9,10,全角色白值成长!K10,11,全角色白值成长!K11,12,全角色白值成长!K12,13,全角色白值成长!K13,14,全角色白值成长!K14,15,全角色白值成长!K15,16,全角色白值成长!K16,17,全角色白值成长!K17,18,全角色白值成长!K18,19,全角色白值成长!K19,20,全角色白值成长!K20,21,全角色白值成长!K21,22,全角色白值成长!K22,23,全角色白值成长!K23,24,全角色白值成长!K24,25,全角色白值成长!K25,26,全角色白值成长!K26,27,全角色白值成长!K27,28,全角色白值成长!K28,29,全角色白值成长!K29,30,全角色白值成长!K30,31,全角色白值成长!K31,32,全角色白值成长!K32,33,全角色白值成长!K33,34,全角色白值成长!K34,35,全角色白值成长!K35,36,全角色白值成长!K36,37,全角色白值成长!K37,38,全角色白值成长!K38,39,全角色白值成长!K39,40,全角色白值成长!K40,41,全角色白值成长!K41,42,全角色白值成长!K42,43,全角色白值成长!K43,44,全角色白值成长!K44,45,全角色白值成长!K45,46,全角色白值成长!K46,47,全角色白值成长!K47,48,全角色白值成长!K48,49,全角色白值成长!K49,50,全角色白值成长!K50,51,全角色白值成长!K51,52,全角色白值成长!K52,53,全角色白值成长!K53,54,全角色白值成长!K54,55,全角色白值成长!K55,56,全角色白值成长!K56,57,全角色白值成长!K57,58,全角色白值成长!K58,59,全角色白值成长!K59,60,全角色白值成长!K60,61,全角色白值成长!K61,62,全角色白值成长!K62,63,全角色白值成长!K63,64,全角色白值成长!K64,65,全角色白值成长!K65,66,全角色白值成长!K66,67,全角色白值成长!K67,68,全角色白值成长!K68,69,全角色白值成长!K69,70,全角色白值成长!K70,71,全角色白值成长!K71)} -> 8 | K8: {=_xlfn.SWITCH(D5,2,全角色白值成长!L2,3,全角色白值成长!L3,4,全角色白值成长!L4,5,全角色白值成长!L5,6,全角色白值成长!L6,7,全角色白值成长!L7,8,全角色白值成长!L8,9,全角色白值成长!L9,10,全角色白值成长!L10,11,全角色白值成长!L11,12,全角色白值成长!L12,13,全角色白值成长!L13,14,全角色白值成长!L14,15,全角色白值成长!L15,16,全角色白值成长!L16,17,全角色白值成长!L17,18,全角色白值成长!L18,19,全角色白值成长!L19,20,全角色白值成长!L20,21,全角色白值成长!L21,22,全角色白值成长!L22,23,全角色白值成长!L23,24,全角色白值成长!L24,25,全角色白值成长!L25,26,全角色白值成长!L26,27,全角色白值成长!L27,28,全角色白值成长!L28,29,全角色白值成长!L29,30,全角色白值成长!L30,31,全角色白值成长!L31,32,全角色白值成长!L32,33,全角色白值成长!L33,34,全角色白值成长!L34,35,全角色白值成长!L35,36,全角色白值成长!L36,37,全角色白值成长!L37,38,全角色白值成长!L38,39,全角色白值成长!L39,40,全角色白值成长!L40,41,全角色白值成长!L41,42,全角色白值成长!L42,43,全角色白值成长!L43,44,全角色白值成长!L44,45,全角色白值成长!L45,46,全角色白值成长!L46,47,全角色白值成长!L47,48,全角色白值成长!L48,49,全角色白值成长!L49,50,全角色白值成长!L50,51,全角色白值成长!L51,52,全角色白值成长!L52,53,全角色白值成长!L53,54,全角色白值成长!L54,55,全角色白值成长!L55,56,全角色白值成长!L56,57,全角色白值成长!L57,58,全角色白值成长!L58,59,全角色白值成长!L59,60,全角色白值成长!L60,61,全角色白值成长!L61,62,全角色白值成长!L62,63,全角色白值成长!L63,64,全角色白值成长!L64,65,全角色白值成长!L65,66,全角色白值成长!L66,67,全角色白值成长!L67,68,全角色白值成长!L68,69,全角色白值成长!L69,70,全角色白值成长!L70,71,全角色白值成长!L71)} -> 210 | L8: {=_xlfn.SWITCH(D5,2,全角色白值成长!M2,3,全角色白值成长!M3,4,全角色白值成长!M4,5,全角色白值成长!M5,6,全角色白值成长!M6,7,全角色白值成长!M7,8,全角色白值成长!M8,9,全角色白值成长!M9,10,全角色白值成长!M10,11,全角色白值成长!M11,12,全角色白值成长!M12,13,全角色白值成长!M13,14,全角色白值成长!M14,15,全角色白值成长!M15,16,全角色白值成长!M16,17,全角色白值成长!M17,18,全角色白值成长!M18,19,全角色白值成长!M19,20,全角色白值成长!M20,21,全角色白值成长!M21,22,全角色白值成长!M22,23,全角色白值成长!M23,24,全角色白值成长!M24,25,全角色白值成长!M25,26,全角色白值成长!M26,27,全角色白值成长!M27,28,全角色白值成长!M28,29,全角色白值成长!M29,30,全角色白值成长!M30,31,全角色白值成长!M31,32,全角色白值成长!M32,33,全角色白值成长!M33,34,全角色白值成长!M34,35,全角色白值成长!M35,36,全角色白值成长!M36,37,全角色白值成长!M37,38,全角色白值成长!M38,39,全角色白值成长!M39,40,全角色白值成长!M40,41,全角色白值成长!M41,42,全角色白值成长!M42,43,全角色白值成长!M43,44,全角色白值成长!M44,45,全角色白值成长!M45,46,全角色白值成长!M46,47,全角色白值成长!M47,48,全角色白值成长!M48,49,全角色白值成长!M49,50,全角色白值成长!M50,51,全角色白值成长!M51,52,全角色白值成长!M52,53,全角色白值成长!M53,54,全角色白值成长!M54,55,全角色白值成长!M55,56,全角色白值成长!M56,57,全角色白值成长!M57,58,全角色白值成长!M58,59,全角色白值成长!M59,60,全角色白值成长!M60,61,全角色白值成长!M61,62,全角色白值成长!M62,63,全角色白值成长!M63,64,全角色白值成长!M64,65,全角色白值成长!M65,66,全角色白值成长!M66,67,全角色白值成长!M67,68,全角色白值成长!M68,69,全角色白值成长!M69,70,全角色白值成长!M70,71,全角色白值成长!M71)} -> 8 | M8: {=_xlfn.SWITCH(D5,2,全角色白值成长!N2,3,全角色白值成长!N3,4,全角色白值成长!N4,5,全角色白值成长!N5,6,全角色白值成长!N6,7,全角色白值成长!N7,8,全角色白值成长!N8,9,全角色白值成长!N9,10,全角色白值成长!N10,11,全角色白值成长!N11,12,全角色白值成长!N12,13,全角色白值成长!N13,14,全角色白值成长!N14,15,全角色白值成长!N15,16,全角色白值成长!N16,17,全角色白值成长!N17,18,全角色白值成长!N18,19,全角色白值成长!N19,20,全角色白值成长!N20,21,全角色白值成长!N21,22,全角色白值成长!N22,23,全角色白值成长!N23,24,全角色白值成长!N24,25,全角色白值成长!N25,26,全角色白值成长!N26,27,全角色白值成长!N27,28,全角色白值成长!N28,29,全角色白值成长!N29,30,全角色白值成长!N30,31,全角色白值成长!N31,32,全角色白值成长!N32,33,全角色白值成长!N33,34,全角色白值成长!N34,35,全角色白值成长!N35,36,全角色白值成长!N36,37,全角色白值成长!N37,38,全角色白值成长!N38,39,全角色白值成长!N39,40,全角色白值成长!N40,41,全角色白值成长!N41,42,全角色白值成长!N42,43,全角色白值成长!N43,44,全角色白值成长!N44,45,全角色白值成长!N45,46,全角色白值成长!N46,47,全角色白值成长!N47,48,全角色白值成长!N48,49,全角色白值成长!N49,50,全角色白值成长!N50,51,全角色白值成长!N51,52,全角色白值成长!N52,53,全角色白值成长!N53,54,全角色白值成长!N54,55,全角色白值成长!N55,56,全角色白值成长!N56,57,全角色白值成长!N57,58,全角色白值成长!N58,59,全角色白值成长!N59,60,全角色白值成长!N60,61,全角色白值成长!N61,62,全角色白值成长!N62,63,全角色白值成长!N63,64,全角色白值成长!N64,65,全角色白值成长!N65,66,全角色白值成长!N66,67,全角色白值成长!N67,68,全角色白值成长!N68,69,全角色白值成长!N69,70,全角色白值成长!N70,71,全角色白值成长!N71)} -> 212 | N8: {=_xlfn.SWITCH(D5,2,全角色白值成长!O2,3,全角色白值成长!O3,4,全角色白值成长!O4,5,全角色白值成长!O5,6,全角色白值成长!O6,7,全角色白值成长!O7,8,全角色白值成长!O8,9,全角色白值成长!O9,10,全角色白值成长!O10,11,全角色白值成长!O11,12,全角色白值成长!O12,13,全角色白值成长!O13,14,全角色白值成长!O14,15,全角色白值成长!O15,16,全角色白值成长!O16,17,全角色白值成长!O17,18,全角色白值成长!O18,19,全角色白值成长!O19,20,全角色白值成长!O20,21,全角色白值成长!O21,22,全角色白值成长!O22,23,全角色白值成长!O23,24,全角色白值成长!O24,25,全角色白值成长!O25,26,全角色白值成长!O26,27,全角色白值成长!O27,28,全角色白值成长!O28,29,全角色白值成长!O29,30,全角色白值成长!O30,31,全角色白值成长!O31,32,全角色白值成长!O32,33,全角色白值成长!O33,34,全角色白值成长!O34,35,全角色白值成长!O35,36,全角色白值成长!O36,37,全角色白值成长!O37,38,全角色白值成长!O38,39,全角色白值成长!O39,40,全角色白值成长!O40,41,全角色白值成长!O41,42,全角色白值成长!O42,43,全角色白值成长!O43,44,全角色白值成长!O44,45,全角色白值成长!O45,46,全角色白值成长!O46,47,全角色白值成长!O47,48,全角色白值成长!O48,49,全角色白值成长!O49,50,全角色白值成长!O50,51,全角色白值成长!O51,52,全角色白值成长!O52,53,全角色白值成长!O53,54,全角色白值成长!O54,55,全角色白值成长!O55,56,全角色白值成长!O56,57,全角色白值成长!O57,58,全角色白值成长!O58,59,全角色白值成长!O59,60,全角色白值成长!O60,61,全角色白值成长!O61,62,全角色白值成长!O62,63,全角色白值成长!O63,64,全角色白值成长!O64,65,全角色白值成长!O65,66,全角色白值成长!O66,67,全角色白值成长!O67,68,全角色白值成长!O68,69,全角色白值成长!O69,70,全角色白值成长!O70,71,全角色白值成长!O71)} -> 8 | O8: {=_xlfn.SWITCH(D5,2,全角色白值成长!P2,3,全角色白值成长!P3,4,全角色白值成长!P4,5,全角色白值成长!P5,6,全角色白值成长!P6,7,全角色白值成长!P7,8,全角色白值成长!P8,9,全角色白值成长!P9,10,全角色白值成长!P10,11,全角色白值成长!P11,12,全角色白值成长!P12,13,全角色白值成长!P13,14,全角色白值成长!P14,15,全角色白值成长!P15,16,全角色白值成长!P16,17,全角色白值成长!P17,18,全角色白值成长!P18,19,全角色白值成长!P19,20,全角色白值成长!P20,21,全角色白值成长!P21,22,全角色白值成长!P22,23,全角色白值成长!P23,24,全角色白值成长!P24,25,全角色白值成长!P25,26,全角色白值成长!P26,27,全角色白值成长!P27,28,全角色白值成长!P28,29,全角色白值成长!P29,30,全角色白值成长!P30,31,全角色白值成长!P31,32,全角色白值成长!P32,33,全角色白值成长!P33,34,全角色白值成长!P34,35,全角色白值成长!P35,36,全角色白值成长!P36,37,全角色白值成长!P37,38,全角色白值成长!P38,39,全角色白值成长!P39,40,全角色白值成长!P40,41,全角色白值成长!P41,42,全角色白值成长!P42,43,全角色白值成长!P43,44,全角色白值成长!P44,45,全角色白值成长!P45,46,全角色白值成长!P46,47,全角色白值成长!P47,48,全角色白值成长!P48,49,全角色白值成长!P49,50,全角色白值成长!P50,51,全角色白值成长!P51,52,全角色白值成长!P52,53,全角色白值成长!P53,54,全角色白值成长!P54,55,全角色白值成长!P55,56,全角色白值成长!P56,57,全角色白值成长!P57,58,全角色白值成长!P58,59,全角色白值成长!P59,60,全角色白值成长!P60,61,全角色白值成长!P61,62,全角色白值成长!P62,63,全角色白值成长!P63,64,全角色白值成长!P64,65,全角色白值成长!P65,66,全角色白值成长!P66,67,全角色白值成长!P67,68,全角色白值成长!P68,69,全角色白值成长!P69,70,全角色白值成长!P70,71,全角色白值成长!P71)} -> 208
C9: A-S Gen | D9: Power | E9: Dexterity | F9: Toughness | G9: Spirit | H9: Wisdom | I9: Luck
D10: {=_xlfn.SWITCH(D5,2,AS通用白值!E2,3,AS通用白值!E3,4,AS通用白值!E4,5,AS通用白值!E5,6,AS通用白值!E6,7,AS通用白值!E7,8,AS通用白值!E8,9,AS通用白值!E9,10,AS通用白值!E10,11,AS通用白值!E11,12,AS通用白值!E12,13,AS通用白值!E13,14,AS通用白值!E14,15,AS通用白值!E15,16,AS通用白值!E16,17,AS通用白值!E17,18,AS通用白值!E18,19,AS通用白值!E19,20,AS通用白值!E20,21,AS通用白值!E21,22,AS通用白值!E22,23,AS通用白值!E23,24,AS通用白值!E24,25,AS通用白值!E25,26,AS通用白值!E26,27,AS通用白值!E27,28,AS通用白值!E28,29,AS通用白值!E29,30,AS通用白值!E30,31,AS通用白值!E31,32,AS通用白值!E32,33,AS通用白值!E33,34,AS通用白值!E34,35,AS通用白值!E35,36,AS通用白值!E36,37,AS通用白值!E37,38,AS通用白值!E38,39,AS通用白值!E39,40,AS通用白值!E40,41,AS通用白值!E41,42,AS通用白值!E42,43,AS通用白值!E43,44,AS通用白值!E44,45,AS通用白值!E45,46,AS通用白值!E46,47,AS通用白值!E47,48,AS通用白值!E48,49,AS通用白值!E49,50,AS通用白值!E50,51,AS通用白值!E51,52,AS通用白值!E52,53,AS通用白值!E53,54,AS通用白值!E54,55,AS通用白值!E55,56,AS通用白值!E56,57,AS通用白值!E57,58,AS通用白值!E58,59,AS通用白值!E59,60,AS通用白值!E60,61,AS通用白值!E61,62,AS通用白值!E62,63,AS通用白值!E63,64,AS通用白值!E64,65,AS通用白值!E65,66,AS通用白值!E66,67,AS通用白值!E67,68,AS通用白值!E68,69,AS通用白值!E69,70,AS通用白值!E70,71,AS通用白值!E71)} -> 0 | E10: {=_xlfn.SWITCH(D5,2,AS通用白值!F2,3,AS通用白值!F3,4,AS通用白值!F4,5,AS通用白值!F5,6,AS通用白值!F6,7,AS通用白值!F7,8,AS通用白值!F8,9,AS通用白值!F9,10,AS通用白值!F10,11,AS通用白值!F11,12,AS通用白值!F12,13,AS通用白值!F13,14,AS通用白值!F14,15,AS通用白值!F15,16,AS通用白值!F16,17,AS通用白值!F17,18,AS通用白值!F18,19,AS通用白值!F19,20,AS通用白值!F20,21,AS通用白值!F21,22,AS通用白值!F22,23,AS通用白值!F23,24,AS通用白值!F24,25,AS通用白值!F25,26,AS通用白值!F26,27,AS通用白值!F27,28,AS通用白值!F28,29,AS通用白值!F29,30,AS通用白值!F30,31,AS通用白值!F31,32,AS通用白值!F32,33,AS通用白值!F33,34,AS通用白值!F34,35,AS通用白值!F35,36,AS通用白值!F36,37,AS通用白值!F37,38,AS通用白值!F38,39,AS通用白值!F39,40,AS通用白值!F40,41,AS通用白值!F41,42,AS通用白值!F42,43,AS通用白值!F43,44,AS通用白值!F44,45,AS通用白值!F45,46,AS通用白值!F46,47,AS通用白值!F47,48,AS通用白值!F48,49,AS通用白值!F49,50,AS通用白值!F50,51,AS通用白值!F51,52,AS通用白值!F52,53,AS通用白值!F53,54,AS通用白值!F54,55,AS通用白值!F55,56,AS通用白值!F56,57,AS通用白值!F57,58,AS通用白值!F58,59,AS通用白值!F59,60,AS通用白值!F60,61,AS通用白值!F61,62,AS通用白值!F62,63,AS通用白值!F63,64,AS通用白值!F64,65,AS通用白值!F65,66,AS通用白值!F66,67,AS通用白值!F67,68,AS通用白值!F68,69,AS通用白值!F69,70,AS通用白值!F70,71,AS通用白值!F71)} -> 0 | F10: {=_xlfn.SWITCH(D5,2,AS通用白值!G2,3,AS通用白值!G3,4,AS通用白值!G4,5,AS通用白值!G5,6,AS通用白值!G6,7,AS通用白值!G7,8,AS通用白值!G8,9,AS通用白值!G9,10,AS通用白值!G10,11,AS通用白值!G11,12,AS通用白值!G12,13,AS通用白值!G13,14,AS通用白值!G14,15,AS通用白值!G15,16,AS通用白值!G16,17,AS通用白值!G17,18,AS通用白值!G18,19,AS通用白值!G19,20,AS通用白值!G20,21,AS通用白值!G21,22,AS通用白值!G22,23,AS通用白值!G23,24,AS通用白值!G24,25,AS通用白值!G25,26,AS通用白值!G26,27,AS通用白值!G27,28,AS通用白值!G28,29,AS通用白值!G29,30,AS通用白值!G30,31,AS通用白值!G31,32,AS通用白值!G32,33,AS通用白值!G33,34,AS通用白值!G34,35,AS通用白值!G35,36,AS通用白值!G36,37,AS通用白值!G37,38,AS通用白值!G38,39,AS通用白值!G39,40,AS通用白值!G40,41,AS通用白值!G41,42,AS通用白值!G42,43,AS通用白值!G43,44,AS通用白值!G44,45,AS通用白值!G45,46,AS通用白值!G46,47,AS通用白值!G47,48,AS通用白值!G48,49,AS通用白值!G49,50,AS通用白值!G50,51,AS通用白值!G51,52,AS通用白值!G52,53,AS通用白值!G53,54,AS通用白值!G54,55,AS通用白值!G55,56,AS通用白值!G56,57,AS通用白值!G57,58,AS通用白值!G58,59,AS通用白值!G59,60,AS通用白值!G60,61,AS通用白值!G61,62,AS通用白值!G62,63,AS通用白值!G63,64,AS通用白值!G64,65,AS通用白值!G65,66,AS通用白值!G66,67,AS通用白值!G67,68,AS通用白值!G68,69,AS通用白值!G69,70,AS通用白值!G70,71,AS通用白值!G71)} -> 0 | G10: {=_xlfn.SWITCH(D5,2,AS通用白值!H2,3,AS通用白值!H3,4,AS通用白值!H4,5,AS通用白值!H5,6,AS通用白值!H6,7,AS通用白值!H7,8,AS通用白值!H8,9,AS通用白值!H9,10,AS通用白值!H10,11,AS通用白值!H11,12,AS通用白值!H12,13,AS通用白值!H13,14,AS通用白值!H14,15,AS通用白值!H15,16,AS通用白值!H16,17,AS通用白值!H17,18,AS通用白值!H18,19,AS通用白值!H19,20,AS通用白值!H20,21,AS通用白值!H21,22,AS通用白值!H22,23,AS通用白值!H23,24,AS通用白值!H24,25,AS通用白值!H25,26,AS通用白值!H26,27,AS通用白值!H27,28,AS通用白值!H28,29,AS通用白值!H29,30,AS通用白值!H30,31,AS通用白值!H31,32,AS通用白值!H32,33,AS通用白值!H33,34,AS通用白值!H34,35,AS通用白值!H35,36,AS通用白值!H36,37,AS通用白值!H37,38,AS通用白值!H38,39,AS通用白值!H39,40,AS通用白值!H40,41,AS通用白值!H41,42,AS通用白值!H42,43,AS通用白值!H43,44,AS通用白值!H44,45,AS通用白值!H45,46,AS通用白值!H46,47,AS通用白值!H47,48,AS通用白值!H48,49,AS通用白值!H49,50,AS通用白值!H50,51,AS通用白值!H51,52,AS通用白值!H52,53,AS通用白值!H53,54,AS通用白值!H54,55,AS通用白值!H55,56,AS通用白值!H56,57,AS通用白值!H57,58,AS通用白值!H58,59,AS通用白值!H59,60,AS通用白值!H60,61,AS通用白值!H61,62,AS通用白值!H62,63,AS通用白值!H63,64,AS通用白值!H64,65,AS通用白值!H65,66,AS通用白值!H66,67,AS通用白值!H67,68,AS通用白值!H68,69,AS通用白值!H69,70,AS通用白值!H70,71,AS通用白值!H71)} -> 0 | H10: {=_xlfn.SWITCH(D5,2,AS通用白值!I2,3,AS通用白值!I3,4,AS通用白值!I4,5,AS通用白值!I5,6,AS通用白值!I6,7,AS通用白值!I7,8,AS通用白值!I8,9,AS通用白值!I9,10,AS通用白值!I10,11,AS通用白值!I11,12,AS通用白值!I12,13,AS通用白值!I13,14,AS通用白值!I14,15,AS通用白值!I15,16,AS通用白值!I16,17,AS通用白值!I17,18,AS通用白值!I18,19,AS通用白值!I19,20,AS通用白值!I20,21,AS通用白值!I21,22,AS通用白值!I22,23,AS通用白值!I23,24,AS通用白值!I24,25,AS通用白值!I25,26,AS通用白值!I26,27,AS通用白值!I27,28,AS通用白值!I28,29,AS通用白值!I29,30,AS通用白值!I30,31,AS通用白值!I31,32,AS通用白值!I32,33,AS通用白值!I33,34,AS通用白值!I34,35,AS通用白值!I35,36,AS通用白值!I36,37,AS通用白值!I37,38,AS通用白值!I38,39,AS通用白值!I39,40,AS通用白值!I40,41,AS通用白值!I41,42,AS通用白值!I42,43,AS通用白值!I43,44,AS通用白值!I44,45,AS通用白值!I45,46,AS通用白值!I46,47,AS通用白值!I47,48,AS通用白值!I48,49,AS通用白值!I49,50,AS通用白值!I50,51,AS通用白值!I51,52,AS通用白值!I52,53,AS通用白值!I53,54,AS通用白值!I54,55,AS通用白值!I55,56,AS通用白值!I56,57,AS通用白值!I57,58,AS通用白值!I58,59,AS通用白值!I59,60,AS通用白值!I60,61,AS通用白值!I61,62,AS通用白值!I62,63,AS通用白值!I63,64,AS通用白值!I64,65,AS通用白值!I65,66,AS通用白值!I66,67,AS通用白值!I67,68,AS通用白值!I68,69,AS通用白值!I69,70,AS通用白值!I70,71,AS通用白值!I71)} -> 0 | I10: {=_xlfn.SWITCH(D5,2,AS通用白值!J2,3,AS通用白值!J3,4,AS通用白值!J4,5,AS通用白值!J5,6,AS通用白值!J6,7,AS通用白值!J7,8,AS通用白值!J8,9,AS通用白值!J9,10,AS通用白值!J10,11,AS通用白值!J11,12,AS通用白值!J12,13,AS通用白值!J13,14,AS通用白值!J14,15,AS通用白值!J15,16,AS通用白值!J16,17,AS通用白值!J17,18,AS通用白值!J18,19,AS通用白值!J19,20,AS通用白值!J20,21,AS通用白值!J21,22,AS通用白值!J22,23,AS通用白值!J23,24,AS通用白值!J24,25,AS通用白值!J25,26,AS通用白值!J26,27,AS通用白值!J27,28,AS通用白值!J28,29,AS通用白值!J29,30,AS通用白值!J30,31,AS通用白值!J31,32,AS通用白值!J32,33,AS通用白值!J33,34,AS通用白值!J34,35,AS通用白值!J35,36,AS通用白值!J36,37,AS通用白值!J37,38,AS通用白值!J38,39,AS通用白值!J39,40,AS通用白值!J40,41,AS通用白值!J41,42,AS通用白值!J42,43,AS通用白值!J43,44,AS通用白值!J44,45,AS通用白值!J45,46,AS通用白值!J46,47,AS通用白值!J47,48,AS通用白值!J48,49,AS通用白值!J49,50,AS通用白值!J50,51,AS通用白值!J51,52,AS通用白值!J52,53,AS通用白值!J53,54,AS通用白值!J54,55,AS通用白值!J55,56,AS通用白值!J56,57,AS通用白值!J57,58,AS通用白值!J58,59,AS通用白值!J59,60,AS通用白值!J60,61,AS通用白值!J61,62,AS通用白值!J62,63,AS通用白值!J63,64,AS通用白值!J64,65,AS通用白值!J65,66,AS通用白值!J66,67,AS通用白值!J67,68,AS通用白值!J68,69,AS通用白值!J69,70,AS通用白值!J70,71,AS通用白值!J71)} -> 0
C11: SS Gen | D11: Power | E11: Dexterity | F11: Toughness | G11: Spirit | H11: Wisdom | I11: Luck
D12: {=_xlfn.SWITCH(D5,2,SS通用白值!E2,3,SS通用白值!E3,4,SS通用白值!E4,5,SS通用白值!E5,6,SS通用白值!E6,7,SS通用白值!E7,8,SS通用白值!E8,9,SS通用白值!E9,10,SS通用白值!E10,11,SS通用白值!E11,12,SS通用白值!E12,13,SS通用白值!E13,14,SS通用白值!E14,15,SS通用白值!E15,16,SS通用白值!E16,17,SS通用白值!E17,18,SS通用白值!E18,19,SS通用白值!E19,20,SS通用白值!E20,21,SS通用白值!E21,22,SS通用白值!E22,23,SS通用白值!E23,24,SS通用白值!E24,25,SS通用白值!E25,26,SS通用白值!E26,27,SS通用白值!E27,28,SS通用白值!E28,29,SS通用白值!E29,30,SS通用白值!E30,31,SS通用白值!E31,32,SS通用白值!E32,33,SS通用白值!E33,34,SS通用白值!E34,35,SS通用白值!E35,36,SS通用白值!E36,37,SS通用白值!E37,38,SS通用白值!E38,39,SS通用白值!E39,40,SS通用白值!E40,41,SS通用白值!E41,42,SS通用白值!E42,43,SS通用白值!E43,44,SS通用白值!E44,45,SS通用白值!E45,46,SS通用白值!E46,47,SS通用白值!E47,48,SS通用白值!E48,49,SS通用白值!E49,50,SS通用白值!E50,51,SS通用白值!E51,52,SS通用白值!E52,53,SS通用白值!E53,54,SS通用白值!E54,55,SS通用白值!E55,56,SS通用白值!E56,57,SS通用白值!E57,58,SS通用白值!E58,59,SS通用白值!E59,60,SS通用白值!E60,61,SS通用白值!E61,62,SS通用白值!E62,63,SS通用白值!E63,64,SS通用白值!E64,65,SS通用白值!E65,66,SS通用白值!E66,67,SS通用白值!E67,68,SS通用白值!E68,69,SS通用白值!E69,70,SS通用白值!E70,71,SS通用白值!E71)} -> 3 | E12: {=_xlfn.SWITCH(D5,2,SS通用白值!F2,3,SS通用白值!F3,4,SS通用白值!F4,5,SS通用白值!F5,6,SS通用白值!F6,7,SS通用白值!F7,8,SS通用白值!F8,9,SS通用白值!F9,10,SS通用白值!F10,11,SS通用白值!F11,12,SS通用白值!F12,13,SS通用白值!F13,14,SS通用白值!F14,15,SS通用白值!F15,16,SS通用白值!F16,17,SS通用白值!F17,18,SS通用白值!F18,19,SS通用白值!F19,20,SS通用白值!F20,21,SS通用白值!F21,22,SS通用白值!F22,23,SS通用白值!F23,24,SS通用白值!F24,25,SS通用白值!F25,26,SS通用白值!F26,27,SS通用白值!F27,28,SS通用白值!F28,29,SS通用白值!F29,30,SS通用白值!F30,31,SS通用白值!F31,32,SS通用白值!F32,33,SS通用白值!F33,34,SS通用白值!F34,35,SS通用白值!F35,36,SS通用白值!F36,37,SS通用白值!F37,38,SS通用白值!F38,39,SS通用白值!F39,40,SS通用白值!F40,41,SS通用白值!F41,42,SS通用白值!F42,43,SS通用白值!F43,44,SS通用白值!F44,45,SS通用白值!F45,46,SS通用白值!F46,47,SS通用白值!F47,48,SS通用白值!F48,49,SS通用白值!F49,50,SS通用白值!F50,51,SS通用白值!F51,52,SS通用白值!F52,53,SS通用白值!F53,54,SS通用白值!F54,55,SS通用白值!F55,56,SS通用白值!F56,57,SS通用白值!F57,58,SS通用白值!F58,59,SS通用白值!F59,60,SS通用白值!F60,61,SS通用白值!F61,62,SS通用白值!F62,63,SS通用白值!F63,64,SS通用白值!F64,65,SS通用白值!F65,66,SS通用白值!F66,67,SS通用白值!F67,68,SS通用白值!F68,69,SS通用白值!F69,70,SS通用白值!F70,71,SS通用白值!F71)} -> 0 | F12: {=_xlfn.SWITCH(D5,2,SS通用白值!G2,3,SS通用白值!G3,4,SS通用白值!G4,5,SS通用白值!G5,6,SS通用白值!G6,7,SS通用白值!G7,8,SS通用白值!G8,9,SS通用白值!G9,10,SS通用白值!G10,11,SS通用白值!G11,12,SS通用白值!G12,13,SS通用白值!G13,14,SS通用白值!G14,15,SS通用白值!G15,16,SS通用白值!G16,17,SS通用白值!G17,18,SS通用白值!G18,19,SS通用白值!G19,20,SS通用白值!G20,21,SS通用白值!G21,22,SS通用白值!G22,23,SS通用白值!G23,24,SS通用白值!G24,25,SS通用白值!G25,26,SS通用白值!G26,27,SS通用白值!G27,28,SS通用白值!G28,29,SS通用白值!G29,30,SS通用白值!G30,31,SS通用白值!G31,32,SS通用白值!G32,33,SS通用白值!G33,34,SS通用白值!G34,35,SS通用白值!G35,36,SS通用白值!G36,37,SS通用白值!G37,38,SS通用白值!G38,39,SS通用白值!G39,40,SS通用白值!G40,41,SS通用白值!G41,42,SS通用白值!G42,43,SS通用白值!G43,44,SS通用白值!G44,45,SS通用白值!G45,46,SS通用白值!G46,47,SS通用白值!G47,48,SS通用白值!G48,49,SS通用白值!G49,50,SS通用白值!G50,51,SS通用白值!G51,52,SS通用白值!G52,53,SS通用白值!G53,54,SS通用白值!G54,55,SS通用白值!G55,56,SS通用白值!G56,57,SS通用白值!G57,58,SS通用白值!G58,59,SS通用白值!G59,60,SS通用白值!G60,61,SS通用白值!G61,62,SS通用白值!G62,63,SS通用白值!G63,64,SS通用白值!G64,65,SS通用白值!G65,66,SS通用白值!G66,67,SS通用白值!G67,68,SS通用白值!G68,69,SS通用白值!G69,70,SS通用白值!G70,71,SS通用白值!G71)} -> 2 | G12: {=_xlfn.SWITCH(D5,2,SS通用白值!H2,3,SS通用白值!H3,4,SS通用白值!H4,5,SS通用白值!H5,6,SS通用白值!H6,7,SS通用白值!H7,8,SS通用白值!H8,9,SS通用白值!H9,10,SS通用白值!H10,11,SS通用白值!H11,12,SS通用白值!H12,13,SS通用白值!H13,14,SS通用白值!H14,15,SS通用白值!H15,16,SS通用白值!H16,17,SS通用白值!H17,18,SS通用白值!H18,19,SS通用白值!H19,20,SS通用白值!H20,21,SS通用白值!H21,22,SS通用白值!H22,23,SS通用白值!H23,24,SS通用白值!H24,25,SS通用白值!H25,26,SS通用白值!H26,27,SS通用白值!H27,28,SS通用白值!H28,29,SS通用白值!H29,30,SS通用白值!H30,31,SS通用白值!H31,32,SS通用白值!H32,33,SS通用白值!H33,34,SS通用白值!H34,35,SS通用白值!H35,36,SS通用白值!H36,37,SS通用白值!H37,38,SS通用白值!H38,39,SS通用白值!H39,40,SS通用白值!H40,41,SS通用白值!H41,42,SS通用白值!H42,43,SS通用白值!H43,44,SS通用白值!H44,45,SS通用白值!H45,46,SS通用白值!H46,47,SS通用白值!H47,48,SS通用白值!H48,49,SS通用白值!H49,50,SS通用白值!H50,51,SS通用白值!H51,52,SS通用白值!H52,53,SS通用白值!H53,54,SS通用白值!H54,55,SS通用白值!H55,56,SS通用白值!H56,57,SS通用白值!H57,58,SS通用白值!H58,59,SS通用白值!H59,60,SS通用白值!H60,61,SS通用白值!H61,62,SS通用白值!H62,63,SS通用白值!H63,64,SS通用白值!H64,65,SS通用白值!H65,66,SS通用白值!H66,67,SS通用白值!H67,68,SS通用白值!H68,69,SS通用白值!H69,70,SS通用白值!H70,71,SS通用白值!H71)} -> 0 | H12: {=_xlfn.SWITCH(D5,2,SS通用白值!I2,3,SS通用白值!I3,4,SS通用白值!I4,5,SS通用白值!I5,6,SS通用白值!I6,7,SS通用白值!I7,8,SS通用白值!I8,9,SS通用白值!I9,10,SS通用白值!I10,11,SS通用白值!I11,12,SS通用白值!I12,13,SS通用白值!I13,14,SS通用白值!I14,15,SS通用白值!I15,16,SS通用白值!I16,17,SS通用白值!I17,18,SS通用白值!I18,19,SS通用白值!I19,20,SS通用白值!I20,21,SS通用白值!I21,22,SS通用白值!I22,23,SS通用白值!I23,24,SS通用白值!I24,25,SS通用白值!I25,26,SS通用白值!I26,27,SS通用白值!I27,28,SS通用白值!I28,29,SS通用白值!I29,30,SS通用白值!I30,31,SS通用白值!I31,32,SS通用白值!I32,33,SS通用白值!I33,34,SS通用白值!I34,35,SS通用白值!I35,36,SS通用白值!I36,37,SS通用白值!I37,38,SS通用白值!I38,39,SS通用白值!I39,40,SS通用白值!I40,41,SS通用白值!I41,42,SS通用白值!I42,43,SS通用白值!I43,44,SS通用白值!I44,45,SS通用白值!I45,46,SS通用白值!I46,47,SS通用白值!I47,48,SS通用白值!I48,49,SS通用白值!I49,50,SS通用白值!I50,51,SS通用白值!I51,52,SS通用白值!I52,53,SS通用白值!I53,54,SS通用白值!I54,55,SS通用白值!I55,56,SS通用白值!I56,57,SS通用白值!I57,58,SS通用白值!I58,59,SS通用白值!I59,60,SS通用白值!I60,61,SS通用白值!I61,62,SS通用白值!I62,63,SS通用白值!I63,64,SS通用白值!I64,65,SS通用白值!I65,66,SS通用白值!I66,67,SS通用白值!I67,68,SS通用白值!I68,69,SS通用白值!I69,70,SS通用白值!I70,71,SS通用白值!I71)} -> 0 | I12: {=_xlfn.SWITCH(D5,2,SS通用白值!J2,3,SS通用白值!J3,4,SS通用白值!J4,5,SS通用白值!J5,6,SS通用白值!J6,7,SS通用白值!J7,8,SS通用白值!J8,9,SS通用白值!J9,10,SS通用白值!J10,11,SS通用白值!J11,12,SS通用白值!J12,13,SS通用白值!J13,14,SS通用白值!J14,15,SS通用白值!J15,16,SS通用白值!J16,17,SS通用白值!J17,18,SS通用白值!J18,19,SS通用白值!J19,20,SS通用白值!J20,21,SS通用白值!J21,22,SS通用白值!J22,23,SS通用白值!J23,24,SS通用白值!J24,25,SS通用白值!J25,26,SS通用白值!J26,27,SS通用白值!J27,28,SS通用白值!J28,29,SS通用白值!J29,30,SS通用白值!J30,31,SS通用白值!J31,32,SS通用白值!J32,33,SS通用白值!J33,34,SS通用白值!J34,35,SS通用白值!J35,36,SS通用白值!J36,37,SS通用白值!J37,38,SS通用白值!J38,39,SS通用白值!J39,40,SS通用白值!J40,41,SS通用白值!J41,42,SS通用白值!J42,43,SS通用白值!J43,44,SS通用白值!J44,45,SS通用白值!J45,46,SS通用白值!J46,47,SS通用白值!J47,48,SS通用白值!J48,49,SS通用白值!J49,50,SS通用白值!J50,51,SS通用白值!J51,52,SS通用白值!J52,53,SS通用白值!J53,54,SS通用白值!J54,55,SS通用白值!J55,56,SS通用白值!J56,57,SS通用白值!J57,58,SS通用白值!J58,59,SS通用白值!J59,60,SS通用白值!J60,61,SS通用白值!J61,62,SS通用白值!J62,63,SS通用白值!J63,64,SS通用白值!J64,65,SS通用白值!J65,66,SS通用白值!J66,67,SS通用白值!J67,68,SS通用白值!J68,69,SS通用白值!J69,70,SS通用白值!J70,71,SS通用白值!J71)} -> 0
A14: 若缺少该角色SS战型 请输入缺少的数量： | D14: 力体型 | E14: 器运型 | F14: 智精型 | G14: 力器型
H15: 请在SS偏向统计中查询强化偏向
C17: Level | D17: 200
C18: 徽章等级 | D18: 13 | E18: 请输入1-15
C19: 转生次数 | D19: 20 | E19: 请输入0-20
B21: 基础值-修正行
B23: OutPut1-基础状态值 | D23: {=ROUND((E8-D8)/199*(D17-1),0)+D8+D10+D12-3*D15-3*G15+_xlfn.SWITCH(D18,1,0,2,1,3,2,4,3,5,3,6,4,7,5,8,6,9,6,10,6,11,7,12,8,13,9,14,9,15,9)+D19+D21} -> 246 | E23: {=ROUND((G8-F8)/199*(D17-1),0)+F8+E10+E12-3*E15-2*G15+_xlfn.SWITCH(D18,1,0,2,1,3,2,4,3,5,3,6,4,7,5,8,6,9,6,10,6,11,7,12,8,13,9,14,9,15,9)+D19+E21} -> 235 | F23: {=ROUND((I8-H8)/199*(D17-1),0)+H8+F10+F12-2*D15+_xlfn.SWITCH(D18,1,0,2,1,3,2,4,3,5,3,6,4,7,5,8,6,9,6,10,6,11,7,12,8,13,9,14,9,15,9)+D19+F21} -> 241 | G23: {=ROUND((K8-J8)/199*(D17-1),0)+J8+G10+G12-2*F15+_xlfn.SWITCH(D18,1,0,2,1,3,2,4,3,5,3,6,4,7,5,8,6,9,6,10,6,11,7,12,8,13,9,14,9,15,9)+D19+G21} -> 239 | H23: {=ROUND((M8-L8)/199*(D17-1),0)+L8+H10+H12-3*F15+_xlfn.SWITCH(D18,1,0,2,1,3,2,4,3,5,3,6,4,7,5,8,6,9,6,10,6,11,7,12,8,13,9,14,9,15,9)+D19+H21} -> 241 | I23: {=ROUND((O8-N8)/199*(D17-1),0)+N8+I10+I12-2*E15+_xlfn.SWITCH(D18,1,0,2,1,3,2,4,3,5,3,6,4,7,5,8,6,9,6,10,6,11,7,12,8,13,9,14,9,15,9)+D19+I21} -> 237
C25: 强化偏向 | D25: 1 | E25: 力体型输入1，器运型输入2，智精型输入3，力器型输入4
C26: 突破等级 | D26: 5 | E26: 原皮满破与才能开花均记为突破等级+1；请输入0-6
C28: 共鸣
C29: 支援
A31: 模组&晶片&饰品加成 | D31: [对HP+]最优配装 | G31: 请选择预设配装，或选择“裸装”后在下方修正行手动输入配装加成
D32: {=_xlfn.SWITCH(D31,"裸装",预置配装!D5,"减防最优配装",预置配装!D6,"脆弱最优配装",预置配装!D7,"[对HP+]最优配装",预置配装!D8,"[对DP+]最优配装",预置配装!D9,"无偏向攻击最优配装",预置配装!D10,"智力依存最优配装",预置配装!D11,"体力依存最优配装",预置配装!D12,"精神max最优配装",预置配装!D13,"减防最优，但红晶片用完了",预置配装!D14,"脆弱最优，但红晶片用完了",预置配装!D15)} -> 207 | E32: {=_xlfn.SWITCH(D31,"裸装",预置配装!E5,"减防最优配装",预置配装!E6,"脆弱最优配装",预置配装!E7,"[对HP+]最优配装",预置配装!E8,"[对DP+]最优配装",预置配装!E9,"无偏向攻击最优配装",预置配装!E10,"智力依存最优配装",预置配装!E11,"体力依存最优配装",预置配装!E12,"精神max最优配装",预置配装!E13,"减防最优，但红晶片用完了",预置配装!E14,"脆弱最优，但红晶片用完了",预置配装!E15)} -> 102 | F32: {=_xlfn.SWITCH(D31,"裸装",预置配装!F5,"减防最优配装",预置配装!F6,"脆弱最优配装",预置配装!F7,"[对HP+]最优配装",预置配装!F8,"[对DP+]最优配装",预置配装!F9,"无偏向攻击最优配装",预置配装!F10,"智力依存最优配装",预置配装!F11,"体力依存最优配装",预置配装!F12,"精神max最优配装",预置配装!F13,"减防最优，但红晶片用完了",预置配装!F14,"脆弱最优，但红晶片用完了",预置配装!F15)} -> 105 | G32: {=_xlfn.SWITCH(D31,"裸装",预置配装!G5,"减防最优配装",预置配装!G6,"脆弱最优配装",预置配装!G7,"[对HP+]最优配装",预置配装!G8,"[对DP+]最优配装",预置配装!G9,"无偏向攻击最优配装",预置配装!G10,"智力依存最优配装",预置配装!G11,"体力依存最优配装",预置配装!G12,"精神max最优配装",预置配装!G13,"减防最优，但红晶片用完了",预置配装!G14,"脆弱最优，但红晶片用完了",预置配装!G15)} -> 105 | H32: {=_xlfn.SWITCH(D31,"裸装",预置配装!H5,"减防最优配装",预置配装!H6,"脆弱最优配装",预置配装!H7,"[对HP+]最优配装",预置配装!H8,"[对DP+]最优配装",预置配装!H9,"无偏向攻击最优配装",预置配装!H10,"智力依存最优配装",预置配装!H11,"体力依存最优配装",预置配装!H12,"精神max最优配装",预置配装!H13,"减防最优，但红晶片用完了",预置配装!H14,"脆弱最优，但红晶片用完了",预置配装!H15)} -> 118 | I32: {=_xlfn.SWITCH(D31,"裸装",预置配装!I5,"减防最优配装",预置配装!I6,"脆弱最优配装",预置配装!I7,"[对HP+]最优配装",预置配装!I8,"[对DP+]最优配装",预置配装!I9,"无偏向攻击最优配装",预置配装!I10,"智力依存最优配装",预置配装!I11,"体力依存最优配装",预置配装!I12,"精神max最优配装",预置配装!I13,"减防最优，但红晶片用完了",预置配装!I14,"脆弱最优，但红晶片用完了",预置配装!I15)} -> 108
B33: 灵魂（专武）+值 | D33: 5 | E33: 请输入0-5 | H33: 坠链运气加成 | J33: 0 | K33: 0或48 | L33: 若选择“裸装”，本行将失效
C35: 打分buff | E35: 请输入0或15或30 | L35: 注 除“[对DP+]最优配装”外，戒指默认为力量偏向 除“脆弱最优配装”及“脆弱最优，但红晶片用完了”外，戒指额外词条默认为智力
B37: 合计值-修正行
B39: OutPut2 | C39: 合计 状态值 | D39: Power | E39: Dexterity | F39: Toughness | G39: Spirit | H39: Wisdom | I39: Luck
D40: {=_xlfn.SWITCH(D25,1,ROUNDUP(D23*(1.7+0.1*D26),0)+39+D28+D29+D32,2,ROUNDUP(D23*(1.4+0.1*D26),0)+35+D28+D29+D32,3,ROUNDUP(D23*(1.55+0.1*D26),0)+37+D28+D29+D32,4,ROUNDUP(D23*(1.7+0.1*D26),0)+39+D28+D29+D32)+IF(D31="裸装",0,_xlfn.SWITCH(D33,0,0,1,4,2,8,3,12,4,16,5,20))+D35+D37} -> 808 | E40: {=_xlfn.SWITCH(D25,1,ROUNDUP(E23*(1.4+0.1*D26),0)+35+D28+E29+E32,2,ROUNDUP(E23*(1.7+0.1*D26),0)+39+D28+E29+E32,3,ROUNDUP(E23*(1.55+0.1*D26),0)+37+D28+E29+E32,4,ROUNDUP(E23*(1.6+0.1*D26),0)+39+D28+E29+E32)+IF(D31="裸装",0,_xlfn.SWITCH(D33,0,0,1,4,2,8,3,12,4,16,5,20))+D35+E37} -> 604 | F40: {=_xlfn.SWITCH(D25,1,ROUNDUP(F23*(1.6+0.1*D26),0)+39+D28+F29+F32,2,ROUNDUP(F23*(1.55+0.1*D26),0)+37+D28+F29+F32,3,ROUNDUP(F23*(1.4+0.1*D26),0)+35+D28+F29+F32,4,ROUNDUP(F23*(1.5+0.1*D26),0)+37+D28+F29+F32)+IF(D31="裸装",0,_xlfn.SWITCH(D33,0,0,1,4,2,8,3,12,4,16,5,20))+D35+F37} -> 671 | G40: {=_xlfn.SWITCH(D25,1,ROUNDUP(G23*(1.55+0.1*D26),0)+37+D28+G29+G32,2,ROUNDUP(G23*(1.5+0.1*D26),0)+35+D28+G29+G32,3,ROUNDUP(G23*(1.6+0.1*D26),0)+39+D28+G29+G32,4,ROUNDUP(G23*(1.5+0.1*D26),0)+35+D28+G29+G32)+IF(D31="裸装",0,_xlfn.SWITCH(D33,0,0,1,4,2,8,3,12,4,16,5,20))+D35+G37} -> 652 | H40: {=_xlfn.SWITCH(D25,1,ROUNDUP(H23*(1.5+0.1*D26),0)+35+D28+H29+H32,2,ROUNDUP(H23*(1.55+0.1*D26),0)+37+D28+H29+H32,3,ROUNDUP(H23*(1.7+0.1*D26),0)+39+D28+H29+H32,4,ROUNDUP(H23*(1.45+0.1*D26),0)+35+D28+H29+H32)+IF(D31="裸装",0,_xlfn.SWITCH(D33,0,0,1,4,2,8,3,12,4,16,5,20))+D35+H37} -> 655 | I40: {=_xlfn.SWITCH(D25,1,ROUNDUP(I23*(1.55+0.1*D26),0)+37+D28+I29+I32,2,ROUNDUP(I23*(1.6+0.1*D26),0)+39+D28+I29+I32,3,ROUNDUP(I23*(1.5+0.1*D26),0)+35+D28+I29+I32,4,ROUNDUP(I23*(1.55+0.1*D26),0)+37+D28+I29+I32)+IF(D31="裸装",0,_xlfn.SWITCH(D33,0,0,1,4,2,8,3,12,4,16,5,20))+D35+I37+IF(D31="裸装",0,J33-48)} -> 603
B42: OutPut3 | D42: HP偏有效值 | F42: DP偏有效值 | H42: 无偏有效值
D43: =(D40*2+E40)/3 -> 740 | F43: =(E40*2+D40)/3 -> 672 | H43: =0.5*D40+0.5*E40 -> 706
D44: 减防有效值 | F44: 脆弱有效值
D45: =(H40*2+I40)/3 -> 637.66667 | F45: =(I40*2+H40)/3 -> 620.33333

Sheet SS偏向统计
A1: ID | B1: Label | C1: 角色 | E1: 力体型 | F1: 器运型 | G1: 智精型 | H1: 力器型 | I1: 备注
A2: 44000002 | B2: BaseParameter.Character.RKayamori | C2: 茅森 月歌 | E2: 6 | G2: 2 | I2: 闪光为特殊力体型；diva和冰为智精型
A3: 44000003 | B3: BaseParameter.Character.YIzumi | C3: 和泉 由希 | F3: 6
A4: 44000004 | B4: BaseParameter.Character.TTojo | C4: 東城 司 | G4: 6
A5: 44000005 | B5: BaseParameter.Character.KAsakura | C5: 朝倉 可憐-1 | E5: 5 | H5: 1 | I5: 双人格齐奏为力器型
A6: 44000006 | B6: BaseParameter.Character.Karen | C6: 朝倉 可憐-2 | E6: 5 | H6: 1
A7: 44000007 | B7: BaseParameter.Character.TKunimi | C7: 國見 玉 | G7: 6
A8: 44000008 | B8: BaseParameter.Character.MAikawa | C8: 逢川 惠 | F8: 3 | G8: 3 | I8: 原皮，雷皮，齐奏皮为智精型
A9: 44000009 | B9: BaseParameter.Character.EAoi | C9: 蒼井 繪梨花 | E9: 1 | G9: 5 | I9: 雷皮为力体型
A10: 44000010 | B10: BaseParameter.Character.IMinase | C10: 水瀨 莓 | E10: 3 | G10: 1 | I10: 棒球皮为智精型
A11: 44000011 | B11: BaseParameter.Character.SMinase | C11: 水瀨 李 | E11: 2 | F11: 2 | I11: 原皮及万圣皮为器运型
A12: 44000012 | B12: BaseParameter.Character.SHiguchi | C12: 樋口 聖華 | G12: 4
A13: 44000013 | B13: BaseParameter.Character.KHiiragi | C13: 柊木 梢 | E13: 1 | F13: 2 | G13: 1 | I13: 红梢为智精型，暗梢为力体型
A15: 44000015 | B15: BaseParameter.Character.Byakko | C15: 白虎 | E15: 2 | F15: 1 | I15: 暗皮为器运型
A16: 44000016 | B16: BaseParameter.Character.YShirakawa | C16: 白河 結奈 | E16: 5 | G16: 1 | I16: 火皮为智精型
A17: 44000017 | B17: BaseParameter.Character.MTsukishiro | C17: 月城 最中 | E17: 3
A18: 44000018 | B18: BaseParameter.Character.MKiryu | C18: 桐生 美也 | E18: 1 | F18: 2 | G18: 1 | I18: 冰美也为智精型
A19: 44000019 | B19: BaseParameter.Character.CSugahara | C19: 菅原 千惠 | E19: 2 | G19: 2 | I19: 光暗皮为力体型
A20: 44000020 | B20: BaseParameter.Character.HOgasawara | C20: 小笠原 緋雨 | E20: 1 | F20: 2 | G20: 2 | I20: 冰火皮为智精型，暗皮为力体型
A21: 44000021 | B21: BaseParameter.Character.SKura | C21: 藏 里見 | E21: 2 | F21: 1 | I21: 暗皮为力体型
A22: 44000022 | B22: BaseParameter.Character.MSatsuki | C22: 佐月 麻里 | E22: 2 | G22: 3 | I22: ATK为力体型
A23: 44000023 | B23: BaseParameter.Character.SSakuraba | C23: 櫻庭 星羅 | E23: 1 | G23: 3 | I23: 火皮为力体型
A24: 44000024 | B24: BaseParameter.Character.BIYamawaki | C24: 山脇・波昂・伊瓦爾 | E24: 5 | F24: 1 | I24: 白送的器运型
A25: 44000025 | B25: BaseParameter.Character.AKanzaki | C25: 神崎 阿黛爾海德 | E25: 4 | G25: 1 | I25: 魔兽-智精型
A26: 44000026 | B26: BaseParameter.Character.MTenne | C26: 天音 巫呼 | F26: 1 | G26: 3 | I26: 原皮为器运型
A34: 44000034 | B34: BaseParameter.Character.STezuka | C34: *手冢 咲 | E34: 1
A35: 44000035 | B35: BaseParameter.Character.NNanase | C35: 七瀨 七海 | E35: 1 | G35: 1 | I35: ADM智精型
A36: 44000036 | B36: BaseParameter.Character.YBungo | C36: 豐後 彌生 | E36: 1 | F36: 3 | I36: 原皮为力体型
A37: 44000037 | B37: BaseParameter.Character.MAsami | C37: *浅见 真纪子
A38: 44000038 | B38: BaseParameter.Character.MNikaido | C38: 二階堂 三鄉 | E38: 2 | G38: 2 | I38: 火皮，ADM为智精型
A39: 44000039 | B39: BaseParameter.Character.IIshii | C39: 石井 色葉 | G39: 3
A40: 44000040 | B40: BaseParameter.Character.FMikoto | C40: 命 吹雪 | E40: 1 | F40: 1
A41: 44000041 | B41: BaseParameter.Character.RMurohushi | C41: 室伏 理沙 | G41: 3
A42: 44000042 | B42: BaseParameter.Character.ADate | C42: 伊達 朱里 | F42: 3 | G42: 1 | I42: 光皮智精型
A43: 44000043 | B43: BaseParameter.Character.AMizuhara | C43: 瑞原 藍娜 | F43: 1 | G43: 3 | I43: 原皮为器运型
A44: 44000044 | B44: BaseParameter.Character.IcOhshima | C44: 大島 一千子 | E44: 1 | G44: 2 | I44: 婚皮为力体型
A45: 44000045 | B45: BaseParameter.Character.NiOhshima | C45: 大島 二以奈 | E45: 2 | F45: 1 | I45: 原皮为器运型
A46: 44000046 | B46: BaseParameter.Character.MiOhshima | C46: 大島 三野里 | E46: 1 | F46: 1 | G46: 1 | I46: 原皮为力体型，光皮为器运型
A47: 44000047 | B47: BaseParameter.Character.YoOhshima | C47: 大島 四葉草 | G47: 3
A48: 44000048 | B48: BaseParameter.Character.IrOhshima | C48: 大島 五十鈴 | F48: 1 | G48: 3 | I48: 原皮为器运型
...

Sheet AS通用白值
A1: ID | B1: Label | C1: 角色 | E1: Power | F1: Dexterity | G1: Toughness | H1: Spirit | I1: Wisdom | J1: Luck
A2: 44000002 | B2: BaseParameter.Character.RKayamori | C2: 茅森 月歌 | F2: 4 | I2: 2 | J2: 4
A3: 44000003 | B3: BaseParameter.Character.YIzumi | C3: 和泉 由希 | E3: 3 | G3: 2 | H3: 2 | I3: 3
A4: 44000004 | B4: BaseParameter.Character.TTojo | C4: 東城 司 | E4: 2 | F4: 3 | H4: 2 | I4: 1 | J4: 2
A5: 44000005 | B5: BaseParameter.Character.KAsakura | C5: 朝倉 可憐-1 | F5: 3 | H5: 2 | I5: 5 | J5: 2
A6: 44000006 | B6: BaseParameter.Character.Karen | C6: 朝倉 可憐-2 | F6: 3 | H6: 2 | I6: 5 | J6: 2
A7: 44000007 | B7: BaseParameter.Character.TKunimi | C7: 國見 玉 | E7: 5 | F7: 3 | G7: 2 | H7: 2 | I7: 1 | J7: 2
A8: 44000008 | B8: BaseParameter.Character.MAikawa | C8: 逢川 惠 | E8: 3 | F8: 2 | G8: 2
A9: 44000009 | B9: BaseParameter.Character.EAoi | C9: 蒼井 繪梨花 | E9: 1 | F9: 2 | G9: 2 | H9: 2 | I9: 3
A10: 44000010 | B10: BaseParameter.Character.IMinase | C10: 水瀨 莓 | E10: 1 | F10: 1 | G10: 2 | I10: 2 | J10: 2
A11: 44000011 | B11: BaseParameter.Character.SMinase | C11: 水瀨 李 | E11: 3 | F11: 2 | G11: 2 | H11: 2 | I11: 3
A12: 44000012 | B12: BaseParameter.Character.SHiguchi | C12: 樋口 聖華 | E12: 3 | F12: 3 | G12: 2 | J12: 2
A13: 44000013 | B13: BaseParameter.Character.KHiiragi | C13: 柊木 梢 | E13: 4 | H13: 4 | I13: 2
A15: 44000015 | B15: BaseParameter.Character.Byakko | C15: 白虎 | E15: 3 | F15: 1 | G15: 2 | I15: 2 | J15: 2
A16: 44000016 | B16: BaseParameter.Character.YShirakawa | C16: 白河 結奈 | E16: 3 | F16: 1 | G16: 2 | H16: 2 | I16: 5 | J16: 2
A17: 44000017 | B17: BaseParameter.Character.MTsukishiro | C17: 月城 最中 | E17: 3 | F17: 2 | G17: 2 | H17: 4 | I17: 2
A18: 44000018 | B18: BaseParameter.Character.MKiryu | C18: 桐生 美也 | E18: 3 | F18: 1 | G18: 2 | I18: 2 | J18: 2
A19: 44000019 | B19: BaseParameter.Character.CSugahara | C19: 菅原 千惠 | E19: 2 | F19: 3 | H19: 2 | I19: 1 | J19: 2
A20: 44000020 | B20: BaseParameter.Character.HOgasawara | C20: 小笠原 緋雨 | F20: 3 | H20: 4 | I20: 4 | J20: 2
A21: 44000021 | B21: BaseParameter.Character.SKura | C21: 藏 里見 | E21: 3 | G21: 2 | H21: 4 | I21: 4
A22: 44000022 | B22: BaseParameter.Character.MSatsuki | C22: 佐月 麻里 | E22: 2 | F22: 1 | H22: 2 | I22: 3 | J22: 2
A23: 44000023 | B23: BaseParameter.Character.SSakuraba | C23: 櫻庭 星羅 | E23: 3 | F23: 3 | G23: 2 | J23: 2
A24: 44000024 | B24: BaseParameter.Character.BIYamawaki | C24: 山脇・波昂・伊瓦爾 | F24: 3 | H24: 2 | I24: 3 | J24: 2
A25: 44000025 | B25: BaseParameter.Character.AKanzaki | C25: 神崎 阿黛爾海德 | F25: 1 | I25: 2 | J25: 2
A26: 44000026 | B26: BaseParameter.Character.MTenne | C26: 天音 巫呼 | E26: 3 | G26: 2 | H26: 2 | I26: 3
A34: 44000034 | B34: BaseParameter.Character.STezuka
A35: 44000035 | B35: BaseParameter.Character.NNanase | C35: 七瀨 七海
A36: 44000036 | B36: BaseParameter.Character.YBungo | C36: 豐後 彌生 | F36: 3 | H36: 2 | I36: 3 | J36: 2
A37: 44000037 | B37: BaseParameter.Character.MAsami
A38: 44000038 | B38: BaseParameter.Character.MNikaido | C38: 二階堂 三鄉 | E38: 3 | F38: 3 | G38: 2 | I38: 2 | J38: 2
A39: 44000039 | B39: BaseParameter.Character.IIshii | C39: 石井 色葉 | E39: 3 | F39: 5 | G39: 2 | J39: 2
A40: 44000040 | B40: BaseParameter.Character.FMikoto | C40: 命 吹雪 | E40: 1 | G40: 2 | I40: 2
A41: 44000041 | B41: BaseParameter.Character.RMurohushi | C41: 室伏 理沙 | E41: 5 | F41: 3 | G41: 2 | H41: 2 | I41: 1 | J41: 2
A42: 44000042 | B42: BaseParameter.Character.ADate | C42: 伊達 朱里 | E42: 1 | G42: 2 | I42: 2
A43: 44000043 | B43: BaseParameter.Character.AMizuhara | C43: 瑞原 藍娜 | E43: 3 | G43: 2 | H43: 2 | I43: 3
A44: 44000044 | B44: BaseParameter.Character.IcOhshima | C44: 大島 一千子 | E44: 3 | F44: 2 | G44: 2 | H44: 2 | I44: 1
A45: 44000045 | B45: BaseParameter.Character.NiOhshima | C45: 大島 二以奈 | E45: 3 | G45: 2 | H45: 2 | I45: 3
A46: 44000046 | B46: BaseParameter.Character.MiOhshima | C46: 大島 三野里 | E46: 2 | F46: 3 | H46: 2 | I46: 3 | J46: 2
A47: 44000047 | B47: BaseParameter.Character.YoOhshima | C47: 大島 四葉草 | E47: 2 | F47: 1 | H47: 2 | I47: 1 | J47: 2
A48: 44000048 | B48: BaseParameter.Character.IrOhshima | C48: 大島 五十鈴 | E48: 2 | H48: 2 | I48: 3
...

Sheet SS通用白值
A1: ID | B1: Label | C1: 角色 | E1: Power | F1: Dexterity | G1: Toughness | H1: Spirit | I1: Wisdom | J1: Luck
A2: 44000002 | B2: BaseParameter.Character.RKayamori | C2: 茅森 月歌 | E2: =SS偏向统计!E2*3+SS偏向统计!H2*3 -> 18 | F2: =SS偏向统计!F2*3+SS偏向统计!H2*2 -> 0 | G2: =SS偏向统计!E2*2 -> 12 | H2: =SS偏向统计!G2*2 -> 4 | I2: =SS偏向统计!G2*3 -> 6 | J2: =SS偏向统计!F2*2 -> 0
A3: 44000003 | B3: BaseParameter.Character.YIzumi | C3: 和泉 由希 | E3: =SS偏向统计!E3*3+SS偏向统计!H3*3 -> 0 | F3: =SS偏向统计!F3*3+SS偏向统计!H3*2 -> 18 | G3: =SS偏向统计!E3*2 -> 0 | H3: =SS偏向统计!G3*2 -> 0 | I3: =SS偏向统计!G3*3 -> 0 | J3: =SS偏向统计!F3*2 -> 12
A4: 44000004 | B4: BaseParameter.Character.TTojo | C4: 東城 司 | E4: =SS偏向统计!E4*3+SS偏向统计!H4*3 -> 0 | F4: =SS偏向统计!F4*3+SS偏向统计!H4*2 -> 0 | G4: =SS偏向统计!E4*2 -> 0 | H4: =SS偏向统计!G4*2 -> 12 | I4: =SS偏向统计!G4*3 -> 18 | J4: =SS偏向统计!F4*2 -> 0
A5: 44000005 | B5: BaseParameter.Character.KAsakura | C5: 朝倉 可憐-1 | E5: =SS偏向统计!E5*3+SS偏向统计!H5*3 -> 18 | F5: =SS偏向统计!F5*3+SS偏向统计!H5*2 -> 2 | G5: =SS偏向统计!E5*2 -> 10 | H5: =SS偏向统计!G5*2 -> 0 | I5: =SS偏向统计!G5*3 -> 0 | J5: =SS偏向统计!F5*2 -> 0
A6: 44000006 | B6: BaseParameter.Character.Karen | C6: 朝倉 可憐-2 | E6: =SS偏向统计!E6*3+SS偏向统计!H6*3 -> 18 | F6: =SS偏向统计!F6*3+SS偏向统计!H6*2 -> 2 | G6: =SS偏向统计!E6*2 -> 10 | H6: =SS偏向统计!G6*2 -> 0 | I6: =SS偏向统计!G6*3 -> 0 | J6: =SS偏向统计!F6*2 -> 0
A7: 44000007 | B7: BaseParameter.Character.TKunimi | C7: 國見 玉 | E7: =SS偏向统计!E7*3+SS偏向统计!H7*3 -> 0 | F7: =SS偏向统计!F7*3+SS偏向统计!H7*2 -> 0 | G7: =SS偏向统计!E7*2 -> 0 | H7: =SS偏向统计!G7*2 -> 12 | I7: =SS偏向统计!G7*3 -> 18 | J7: =SS偏向统计!F7*2 -> 0
A8: 44000008 | B8: BaseParameter.Character.MAikawa | C8: 逢川 惠 | E8: =SS偏向统计!E8*3+SS偏向统计!H8*3 -> 0 | F8: =SS偏向统计!F8*3+SS偏向统计!H8*2 -> 9 | G8: =SS偏向统计!E8*2 -> 0 | H8: =SS偏向统计!G8*2 -> 6 | I8: =SS偏向统计!G8*3 -> 9 | J8: =SS偏向统计!F8*2 -> 6
A9: 44000009 | B9: BaseParameter.Character.EAoi | C9: 蒼井 繪梨花 | E9: =SS偏向统计!E9*3+SS偏向统计!H9*3 -> 3 | F9: =SS偏向统计!F9*3+SS偏向统计!H9*2 -> 0 | G9: =SS偏向统计!E9*2 -> 2 | H9: =SS偏向统计!G9*2 -> 10 | I9: =SS偏向统计!G9*3 -> 15 | J9: =SS偏向统计!F9*2 -> 0
A10: 44000010 | B10: BaseParameter.Character.IMinase | C10: 水瀨 莓 | E10: =SS偏向统计!E10*3+SS偏向统计!H10*3 -> 9 | F10: =SS偏向统计!F10*3+SS偏向统计!H10*2 -> 0 | G10: =SS偏向统计!E10*2 -> 6 | H10: =SS偏向统计!G10*2 -> 2 | I10: =SS偏向统计!G10*3 -> 3 | J10: =SS偏向统计!F10*2 -> 0
A11: 44000011 | B11: BaseParameter.Character.SMinase | C11: 水瀨 李 | E11: =SS偏向统计!E11*3+SS偏向统计!H11*3 -> 6 | F11: =SS偏向统计!F11*3+SS偏向统计!H11*2 -> 6 | G11: =SS偏向统计!E11*2 -> 4 | H11: =SS偏向统计!G11*2 -> 0 | I11: =SS偏向统计!G11*3 -> 0 | J11: =SS偏向统计!F11*2 -> 4
A12: 44000012 | B12: BaseParameter.Character.SHiguchi | C12: 樋口 聖華 | E12: =SS偏向统计!E12*3+SS偏向统计!H12*3 -> 0 | F12: =SS偏向统计!F12*3+SS偏向统计!H12*2 -> 0 | G12: =SS偏向统计!E12*2 -> 0 | H12: =SS偏向统计!G12*2 -> 8 | I12: =SS偏向统计!G12*3 -> 12 | J12: =SS偏向统计!F12*2 -> 0
A13: 44000013 | B13: BaseParameter.Character.KHiiragi | C13: 柊木 梢 | E13: =SS偏向统计!E13*3+SS偏向统计!H13*3 -> 3 | F13: =SS偏向统计!F13*3+SS偏向统计!H13*2 -> 6 | G13: =SS偏向统计!E13*2 -> 2 | H13: =SS偏向统计!G13*2 -> 2 | I13: =SS偏向统计!G13*3 -> 3 | J13: =SS偏向统计!F13*2 -> 4
E14: =SS偏向统计!E14*3+SS偏向统计!H14*3 -> 0 | F14: =SS偏向统计!F14*3+SS偏向统计!H14*2 -> 0 | G14: =SS偏向统计!E14*2 -> 0 | H14: =SS偏向统计!G14*2 -> 0 | I14: =SS偏向统计!G14*3 -> 0 | J14: =SS偏向统计!F14*2 -> 0
A15: 44000015 | B15: BaseParameter.Character.Byakko | C15: 白虎 | E15: =SS偏向统计!E15*3+SS偏向统计!H15*3 -> 6 | F15: =SS偏向统计!F15*3+SS偏向统计!H15*2 -> 3 | G15: =SS偏向统计!E15*2 -> 4 | H15: =SS偏向统计!G15*2 -> 0 | I15: =SS偏向统计!G15*3 -> 0 | J15: =SS偏向统计!F15*2 -> 2
A16: 44000016 | B16: BaseParameter.Character.YShirakawa | C16: 白河 結奈 | E16: =SS偏向统计!E16*3+SS偏向统计!H16*3 -> 15 | F16: =SS偏向统计!F16*3+SS偏向统计!H16*2 -> 0 | G16: =SS偏向统计!E16*2 -> 10 | H16: =SS偏向统计!G16*2 -> 2 | I16: =SS偏向统计!G16*3 -> 3 | J16: =SS偏向统计!F16*2 -> 0
A17: 44000017 | B17: BaseParameter.Character.MTsukishiro | C17: 月城 最中 | E17: =SS偏向统计!E17*3+SS偏向统计!H17*3 -> 9 | F17: =SS偏向统计!F17*3+SS偏向统计!H17*2 -> 0 | G17: =SS偏向统计!E17*2 -> 6 | H17: =SS偏向统计!G17*2 -> 0 | I17: =SS偏向统计!G17*3 -> 0 | J17: =SS偏向统计!F17*2 -> 0
A18: 44000018 | B18: BaseParameter.Character.MKiryu | C18: 桐生 美也 | E18: =SS偏向统计!E18*3+SS偏向统计!H18*3 -> 3 | F18: =SS偏向统计!F18*3+SS偏向统计!H18*2 -> 6 | G18: =SS偏向统计!E18*2 -> 2 | H18: =SS偏向统计!G18*2 -> 2 | I18: =SS偏向统计!G18*3 -> 3 | J18: =SS偏向统计!F18*2 -> 4
A19: 44000019 | B19: BaseParameter.Character.CSugahara | C19: 菅原 千惠 | E19: =SS偏向统计!E19*3+SS偏向统计!H19*3 -> 6 | F19: =SS偏向统计!F19*3+SS偏向统计!H19*2 -> 0 | G19: =SS偏向统计!E19*2 -> 4 | H19: =SS偏向统计!G19*2 -> 4 | I19: =SS偏向统计!G19*3 -> 6 | J19: =SS偏向统计!F19*2 -> 0
A20: 44000020 | B20: BaseParameter.Character.HOgasawara | C20: 小笠原 緋雨 | E20: =SS偏向统计!E20*3+SS偏向统计!H20*3 -> 3 | F20: =SS偏向统计!F20*3+SS偏向统计!H20*2 -> 6 | G20: =SS偏向统计!E20*2 -> 2 | H20: =SS偏向统计!G20*2 -> 4 | I20: =SS偏向统计!G20*3 -> 6 | J20: =SS偏向统计!F20*2 -> 4
A21: 44000021 | B21: BaseParameter.Character.SKura | C21: 藏 里見 | E21: =SS偏向统计!E21*3+SS偏向统计!H21*3 -> 6 | F21: =SS偏向统计!F21*3+SS偏向统计!H21*2 -> 3 | G21: =SS偏向统计!E21*2 -> 4 | H21: =SS偏向统计!G21*2 -> 0 | I21: =SS偏向统计!G21*3 -> 0 | J21: =SS偏向统计!F21*2 -> 2
A22: 44000022 | B22: BaseParameter.Character.MSatsuki | C22: 佐月 麻里 | E22: =SS偏向统计!E22*3+SS偏向统计!H22*3 -> 6 | F22: =SS偏向统计!F22*3+SS偏向统计!H22*2 -> 0 | G22: =SS偏向统计!E22*2 -> 4 | H22: =SS偏向统计!G22*2 -> 6 | I22: =SS偏向统计!G22*3 -> 9 | J22: =SS偏向统计!F22*2 -> 0
A23: 44000023 | B23: BaseParameter.Character.SSakuraba | C23: 櫻庭 星羅 | E23: =SS偏向统计!E23*3+SS偏向统计!H23*3 -> 3 | F23: =SS偏向统计!F23*3+SS偏向统计!H23*2 -> 0 | G23: =SS偏向统计!E23*2 -> 2 | H23: =SS偏向统计!G23*2 -> 6 | I23: =SS偏向统计!G23*3 -> 9 | J23: =SS偏向统计!F23*2 -> 0
A24: 44000024 | B24: BaseParameter.Character.BIYamawaki | C24: 山脇・波昂・伊瓦爾 | E24: =SS偏向统计!E24*3+SS偏向统计!H24*3 -> 15 | F24: =SS偏向统计!F24*3+SS偏向统计!H24*2 -> 3 | G24: =SS偏向统计!E24*2 -> 10 | H24: =SS偏向统计!G24*2 -> 0 | I24: =SS偏向统计!G24*3 -> 0 | J24: =SS偏向统计!F24*2 -> 2
A25: 44000025 | B25: BaseParameter.Character.AKanzaki | C25: 神崎 阿黛爾海德 | E25: =SS偏向统计!E25*3+SS偏向统计!H25*3 -> 12 | F25: =SS偏向统计!F25*3+SS偏向统计!H25*2 -> 0 | G25: =SS偏向统计!E25*2 -> 8 | H25: =SS偏向统计!G25*2 -> 2 | I25: =SS偏向统计!G25*3 -> 3 | J25: =SS偏向统计!F25*2 -> 0
A26: 44000026 | B26: BaseParameter.Character.MTenne | C26: 天音 巫呼 | E26: =SS偏向统计!E26*3+SS偏向统计!H26*3 -> 0 | F26: =SS偏向统计!F26*3+SS偏向统计!H26*2 -> 3 | G26: =SS偏向统计!E26*2 -> 0 | H26: =SS偏向统计!G26*2 -> 6 | I26: =SS偏向统计!G26*3 -> 9 | J26: =SS偏向统计!F26*2 -> 2
E27: =SS偏向统计!E27*3+SS偏向统计!H27*3 -> 0 | F27: =SS偏向统计!F27*3+SS偏向统计!H27*2 -> 0 | G27: =SS偏向统计!E27*2 -> 0 | H27: =SS偏向统计!G27*2 -> 0 | I27: =SS偏向统计!G27*3 -> 0 | J27: =SS偏向统计!F27*2 -> 0
E28: =SS偏向统计!E28*3+SS偏向统计!H28*3 -> 0 | F28: =SS偏向统计!F28*3+SS偏向统计!H28*2 -> 0 | G28: =SS偏向统计!E28*2 -> 0 | H28: =SS偏向统计!G28*2 -> 0 | I28: =SS偏向统计!G28*3 -> 0 | J28: =SS偏向统计!F28*2 -> 0
E29: =SS偏向统计!E29*3+SS偏向统计!H29*3 -> 0 | F29: =SS偏向统计!F29*3+SS偏向统计!H29*2 -> 0 | G29: =SS偏向统计!E29*2 -> 0 | H29: =SS偏向统计!G29*2 -> 0 | I29: =SS偏向统计!G29*3 -> 0 | J29: =SS偏向统计!F29*2 -> 0
E30: =SS偏向统计!E30*3+SS偏向统计!H30*3 -> 0 | F30: =SS偏向统计!F30*3+SS偏向统计!H30*2 -> 0 | G30: =SS偏向统计!E30*2 -> 0 | H30: =SS偏向统计!G30*2 -> 0 | I30: =SS偏向统计!G30*3 -> 0 | J30: =SS偏向统计!F30*2 -> 0
E31: =SS偏向统计!E31*3+SS偏向统计!H31*3 -> 0 | F31: =SS偏向统计!F31*3+SS偏向统计!H31*2 -> 0 | G31: =SS偏向统计!E31*2 -> 0 | H31: =SS偏向统计!G31*2 -> 0 | I31: =SS偏向统计!G31*3 -> 0 | J31: =SS偏向统计!F31*2 -> 0
E32: =SS偏向统计!E32*3+SS偏向统计!H32*3 -> 0 | F32: =SS偏向统计!F32*3+SS偏向统计!H32*2 -> 0 | G32: =SS偏向统计!E32*2 -> 0 | H32: =SS偏向统计!G32*2 -> 0 | I32: =SS偏向统计!G32*3 -> 0 | J32: =SS偏向统计!F32*2 -> 0
E33: =SS偏向统计!E33*3+SS偏向统计!H33*3 -> 0 | F33: =SS偏向统计!F33*3+SS偏向统计!H33*2 -> 0 | G33: =SS偏向统计!E33*2 -> 0 | H33: =SS偏向统计!G33*2 -> 0 | I33: =SS偏向统计!G33*3 -> 0 | J33: =SS偏向统计!F33*2 -> 0
A34: 44000034 | B34: BaseParameter.Character.STezuka | E34: =SS偏向统计!E34*3+SS偏向统计!H34*3 -> 3 | F34: =SS偏向统计!F34*3+SS偏向统计!H34*2 -> 0 | G34: =SS偏向统计!E34*2 -> 2 | H34: =SS偏向统计!G34*2 -> 0 | I34: =SS偏向统计!G34*3 -> 0 | J34: =SS偏向统计!F34*2 -> 0
A35: 44000035 | B35: BaseParameter.Character.NNanase | C35: 七瀨 七海 | E35: =SS偏向统计!E35*3+SS偏向统计!H35*3 -> 3 | F35: =SS偏向统计!F35*3+SS偏向统计!H35*2 -> 0 | G35: =SS偏向统计!E35*2 -> 2 | H35: =SS偏向统计!G35*2 -> 2 | I35: =SS偏向统计!G35*3 -> 3 | J35: =SS偏向统计!F35*2 -> 0
A36: 44000036 | B36: BaseParameter.Character.YBungo | C36: 豐後 彌生 | E36: =SS偏向统计!E36*3+SS偏向统计!H36*3 -> 3 | F36: =SS偏向统计!F36*3+SS偏向统计!H36*2 -> 9 | G36: =SS偏向统计!E36*2 -> 2 | H36: =SS偏向统计!G36*2 -> 0 | I36: =SS偏向统计!G36*3 -> 0 | J36: =SS偏向统计!F36*2 -> 6
A37: 44000037 | B37: BaseParameter.Character.MAsami | E37: =SS偏向统计!E37*3+SS偏向统计!H37*3 -> 0 | F37: =SS偏向统计!F37*3+SS偏向统计!H37*2 -> 0 | G37: =SS偏向统计!E37*2 -> 0 | H37: =SS偏向统计!G37*2 -> 0 | I37: =SS偏向统计!G37*3 -> 0 | J37: =SS偏向统计!F37*2 -> 0
A38: 44000038 | B38: BaseParameter.Character.MNikaido | C38: 二階堂 三鄉 | E38: =SS偏向统计!E38*3+SS偏向统计!H38*3 -> 6 | F38: =SS偏向统计!F38*3+SS偏向统计!H38*2 -> 0 | G38: =SS偏向统计!E38*2 -> 4 | H38: =SS偏向统计!G38*2 -> 4 | I38: =SS偏向统计!G38*3 -> 6 | J38: =SS偏向统计!F38*2 -> 0
A39: 44000039 | B39: BaseParameter.Character.IIshii | C39: 石井 色葉 | E39: =SS偏向统计!E39*3+SS偏向统计!H39*3 -> 0 | F39: =SS偏向统计!F39*3+SS偏向统计!H39*2 -> 0 | G39: =SS偏向统计!E39*2 -> 0 | H39: =SS偏向统计!G39*2 -> 6 | I39: =SS偏向统计!G39*3 -> 9 | J39: =SS偏向统计!F39*2 -> 0
A40: 44000040 | B40: BaseParameter.Character.FMikoto | C40: 命 吹雪 | E40: =SS偏向统计!E40*3+SS偏向统计!H40*3 -> 3 | F40: =SS偏向统计!F40*3+SS偏向统计!H40*2 -> 3 | G40: =SS偏向统计!E40*2 -> 2 | H40: =SS偏向统计!G40*2 -> 0 | I40: =SS偏向统计!G40*3 -> 0 | J40: =SS偏向统计!F40*2 -> 2
...

Sheet 全角色白值成长
A1: ID | B1: Label | C1: 角色 | E1: MinPower | F1: MaxPower | G1: MinDexterity | H1: MaxDexterity | I1: MinToughness | J1: MaxToughness | K1: MinSpirit | L1: MaxSpirit | M1: MinWisdom | N1: MaxWisdom | O1: MinLuck | P1: MaxLuck
A2: 44000002 | B2: BaseParameter.Character.RKayamori | C2: 茅森 月歌 | E2: 8 | F2: 212 | G2: 8 | H2: 210 | I2: 8 | J2: 211 | K2: 9 | L2: 214 | M2: 7 | N2: 206 | O2: 7 | P2: 207
A3: 44000003 | B3: BaseParameter.Character.YIzumi | C3: 和泉 由希 | E3: 8 | F3: 208 | G3: 9 | H3: 214 | I3: 7 | J3: 207 | K3: 9 | L3: 213 | M3: 8 | N3: 212 | O3: 7 | P3: 206
A4: 44000004 | B4: BaseParameter.Character.TTojo | C4: 東城 司 | E4: 8 | F4: 209 | G4: 8 | H4: 211 | I4: 8 | J4: 209 | K4: 7 | L4: 207 | M4: 9 | N4: 213 | O4: 8 | P4: 211
A5: 44000005 | B5: BaseParameter.Character.KAsakura | C5: 朝倉 可憐-1 | E5: 9 | F5: 213 | G5: 8 | H5: 211 | I5: 7 | J5: 207 | K5: 7 | L5: 207 | M5: 7 | N5: 207 | O5: 9 | P5: 215
A6: 44000006 | B6: BaseParameter.Character.Karen | C6: 朝倉 可憐-2 | E6: 9 | F6: 213 | G6: 8 | H6: 211 | I6: 7 | J6: 207 | K6: 7 | L6: 207 | M6: 7 | N6: 207 | O6: 9 | P6: 215
A7: 44000007 | B7: BaseParameter.Character.TKunimi | C7: 國見 玉 | E7: 8 | F7: 209 | G7: 8 | H7: 208 | I7: 8 | J7: 209 | K7: 8 | L7: 211 | M7: 9 | N7: 214 | O7: 8 | P7: 209
A8: 44000008 | B8: BaseParameter.Character.MAikawa | C8: 逢川 惠 | E8: 8 | F8: 210 | G8: 7 | H8: 207 | I8: 7 | J8: 206 | K8: 8 | L8: 211 | M8: 8 | N8: 212 | O8: 9 | P8: 214
A9: 44000009 | B9: BaseParameter.Character.EAoi | C9: 蒼井 繪梨花 | E9: 8 | F9: 210 | G9: 8 | H9: 208 | I9: 9 | J9: 215 | K9: 8 | L9: 212 | M9: 8 | N9: 208 | O9: 7 | P9: 207
A10: 44000010 | B10: BaseParameter.Character.IMinase | C10: 水瀨 莓 | E10: 8 | F10: 211 | G10: 9 | H10: 213 | I10: 7 | J10: 207 | K10: 8 | L10: 211 | M10: 7 | N10: 207 | O10: 8 | P10: 211
A11: 44000011 | B11: BaseParameter.Character.SMinase | C11: 水瀨 李 | E11: 8 | F11: 212 | G11: 8 | H11: 212 | I11: 8 | J11: 208 | K11: 8 | L11: 210 | M11: 8 | N11: 208 | O11: 8 | P11: 210
A12: 44000012 | B12: BaseParameter.Character.SHiguchi | C12: 樋口 聖華 | E12: 8 | F12: 208 | G12: 8 | H12: 211 | I12: 7 | J12: 207 | K12: 8 | L12: 210 | M12: 8 | N12: 212 | O12: 8 | P12: 212
A13: 44000013 | B13: BaseParameter.Character.KHiiragi | C13: 柊木 梢 | E13: 8 | F13: 209 | G13: 8 | H13: 209 | I13: 7 | J13: 206 | K13: 8 | L13: 211 | M13: 9 | N13: 213 | O13: 8 | P13: 212
... A26: 44000026 | B26: BaseParameter.Character.MTenne | C26: 天音 巫呼 | E26: 8 | F26: 208 | G26: 9 | H26: 213 | I26: 8 | J26: 208 | K26: 8 | L26: 208 | M26: 8 | N26: 212 | O26: 8 | P26: 211
A34: 44000034 | B34: BaseParameter.Character.STezuka | E34: 8 | F34: 210 | G34: 8 | H34: 210 | I34: 8 | J34: 210 | K34: 8 | L34: 210 | M34: 8 | N34: 210 | O34: 8 | P34: 210
A35: 44000035 | B35: BaseParameter.Character.NNanase | C35: 七瀨 七海 | E35: 8 | F35: 210 | G35: 8 | H35: 210 | I35: 8 | J35: 210 | K35: 8 | L35: 210 | M35: 8 | N35: 210 | O35: 8 | P35: 210
A36: 44000036 | B36: BaseParameter.Character.YBungo | C36: 豐後 彌生 | E36: 8 | F36: 208 | G36: 9 | H36: 214 | I36: 8 | J36: 209 | K36: 8 | L36: 211 | M36: 7 | N36: 205 | O36: 9 | P36: 213
A37: 44000037 | B37: BaseParameter.Character.MAsami | E37: 8 | F37: 210 | G37: 8 | H37: 210 | I37: 8 | J37: 210 | K37: 8 | L37: 210 | M37: 8 | N37: 210 | O37: 8 | P37: 210
A38: 44000038 | B38: BaseParameter.Character.MNikaido | C38: 二階堂 三鄉 | E38: 8 | F38: 212 | G38: 7 | H38: 207 | I38: 8 | J38: 212 | K38: 8 | L38: 211 | M38: 8 | N38: 212 | O38: 7 | P38: 206
A39: 44000039 | B39: BaseParameter.Character.IIshii | C39: 石井 色葉 | E39: 7 | F39: 207 | G39: 8 | H39: 208 | I39: 8 | J39: 208 | K39: 8 | L39: 211 | M39: 9 | N39: 214 | O39: 8 | P39: 212
A40: 44000040 | B40: BaseParameter.Character.FMikoto | C40: 命 吹雪 | E40: 8 | F40: 211 | G40: 8 | H40: 209 | I40: 8 | J40: 210 | K40: 8 | L40: 209 | M40: 8 | N40: 210 | O40: 8 | P40: 211
A41: 44000041 | B41: BaseParameter.Character.RMurohushi | C41: 室伏 理沙 | E41: 8 | F41: 211 | G41: 8 | H41: 209 | I41: 8 | J41: 212 | K41: 8 | L41: 208 | M41: 9 | N41: 213 | O41: 7 | P41: 207
A42: 44000042 | B42: BaseParameter.Character.ADate | C42: 伊達 朱里 | E42: 8 | F42: 212 | G42: 8 | H42: 208 | I42: 8 | J42: 210 | K42: 7 | L42: 207 | M42: 8 | N42: 211 | O42: 8 | P42: 212
A43: 44000043 | B43: BaseParameter.Character.AMizuhara | C43: 瑞原 藍娜 | E43: 8 | F43: 209 | G43: 8 | H43: 211 | I43: 7 | J43: 207 | K43: 8 | L43: 212 | M43: 9 | N43: 213 | O43: 8 | P43: 208
A44: 44000044 | B44: BaseParameter.Character.IcOhshima | C44: 大島 一千子 | E44: 8 | F44: 209 | G44: 8 | H44: 209 | I44: 8 | J44: 211 | K44: 8 | L44: 212 | M44: 8 | N44: 211 | O44: 8 | P44: 208
A45: 44000045 | B45: BaseParameter.Character.NiOhshima | C45: 大島 二以奈 | E45: 8 | F45: 211 | G45: 8 | H45: 209 | I45: 8 | J45: 212 | K45: 8 | L45: 211 | M45: 8 | N45: 208 | O45: 8 | P45: 209
A46: 44000046 | B46: BaseParameter.Character.MiOhshima | C46: 大島 三野里 | E46: 8 | F46: 211 | G46: 8 | H46: 212 | I46: 8 | J46: 212 | K46: 8 | L46: 208 | M46: 7 | N46: 207 | O46: 8 | P46: 210
A47: 44000047 | B47: BaseParameter.Character.YoOhshima | C47: 大島 四葉草 | E47: 7 | F47: 207 | G47: 8 | H47: 212 | I47: 8 | J47: 211 | K47: 8 | L47: 208 | M47: 8 | N47: 211 | O47: 8 | P47: 211
A48: 44000048 | B48: BaseParameter.Character.IrOhshima | C48: 大島 五十鈴 | E48: 8 | F48: 211 | G48: 8 | H48: 208 | I48: 7 | J48: 207 | K48: 8 | L48: 210 | M48: 8 | N48: 212 | O48: 8 | P48: 212
A49: 44000049 | B49: BaseParameter.Character.MuOhshima | C49: 大島 六宇亞 | E49: 8 | F49: 208 | G49: 8 | H49: 210 | I49: 9 | J49: 213 | K49: 8 | L49: 209 | M49: 8 | N49: 212 | O49: 8 | P49: 208
... A71: 44000071 | B71: BaseParameter.Character.EmaD | C71: VIOLET | E71: 9 | F71: 214 | G71: 7 | H71: 206 | I71: 8 | J71: 210 | K71: 8 | L71: 210 | M71: 8 | N71: 212 | O71: 8 | P71: 208

Sheet 预置配装
B4: 参考配装，默认专武为0级
A5: 裸装 | D5: 0 | E5: 0 | F5: 0 | G5: 0 | H5: 0 | I5: 0 | L5: =55-37 -> 18
A6: 减防最优配装 | D6: 114 | E6: 101 | F6: 104 | G6: 104 | H6: 212 | I6: 107 | L6: 18
A7: 脆弱最优配装 | D7: 114 | E7: 101 | F7: 104 | G7: 104 | H7: 157 | I7: 162 | L7: 5
A8: [对HP+]最优配装 | D8: 207 | E8: 102 | F8: 105 | G8: 105 | H8: 118 | I8: 108 | J8: (-48)
A9: [对DP+]最优配装 | D9: 102 | E9: 207 | F9: 105 | G9: 105 | H9: 118 | I9: 108 | J9: (-48) | L9: 10
A10: 无偏向攻击最优配装 | D10: 191 | E10: 122 | F10: 105 | G10: 105 | H10: 118 | I10: 108 | J10: (-48)
A11: 智力依存最优配装 | D11: 114 | E11: 101 | F11: 104 | G11: 104 | H11: 212 | I11: 107 | J11: (-48)
A12: 体力依存最优配装 | D12: 115 | E12: 102 | F12: 188 | G12: 116 | H12: 118 | I12: 108 | J12: (-48)
A13: 精神max最优配装 | D13: 115 | E13: 102 | F13: 131 | G13: 176 | H13: 118 | I13: 108 | J13: (-48)
A14: 减防最优，但红晶片用完了 | D14: 114 | E14: 101 | F14: 104 | G14: 104 | H14: 204 | I14: 107
A15: 脆弱最优，但红晶片用完了 | D15: 114 | E15: 101 | F15: 104 | G15: 104 | H15: 149 | I15: 162
B19: 参考配装，默认专武为满级
B21: 脆弱最优配装 | D21: =D7+20 -> 134 | E21: =E7+20 -> 121 | F21: =F7+20 -> 124 | G21: =G7+20 -> 124 | H21: =H7+20 -> 177 | I21: =I7+20 -> 182
B22: 减防最优配装 | D22: =D6+20 -> 134 | E22: =E6+20 -> 121 | F22: =F6+20 -> 124 | G22: =G6+20 -> 124 | H22: =H6+20 -> 232 | I22: =I6+20 -> 127
B23: [对HP+]最优配装 | D23: =D8+20 -> 227 | E23: =E8+20 -> 122 | F23: =F8+20 -> 125 | G23: =G8+20 -> 125 | H23: =H8+20 -> 138 | I23: =I8+20 -> 128 | J23: (-48)
B24: [对DP+]最优配装 | D24: =D9+20 -> 122 | E24: =E9+20 -> 227 | F24: =F9+20 -> 125 | G24: =G9+20 -> 125 | H24: =H9+20 -> 138 | I24: =I9+20 -> 128 | J24: (-48)
B25: 无偏向最优配装 | D25: =D10+20 -> 211 | E25: =E10+20 -> 142 | F25: =F10+20 -> 125 | G25: =G10+20 -> 125 | H25: =H10+20 -> 138 | I25: =I10+20 -> 128 | J25: (-48)
B26: 智力依存最优配装 | D26: =D11+20 -> 134 | E26: =E11+20 -> 121 | F26: =F11+20 -> 124 | G26: =G11+20 -> 124 | H26: =H11+20 -> 232 | I26: =I11+20 -> 127 | J26: (-48)
B27: 体力依存最优配装 | D27: =D12+20 -> 135 | E27: =E12+20 -> 122 | F27: =F12+20 -> 208 | G27: =G12+20 -> 136 | H27: =H12+20 -> 138 | I27: =I12+20 -> 128 | J27: (-48)
B28: 精神max最优配装 | D28: =D13+20 -> 135 | E28: =E13+20 -> 122 | F28: =F13+20 -> 151 | G28: =G13+20 -> 196 | H28: =H13+20 -> 138 | I28: =I13+20 -> 128 | J28: (-48)
A29: 脆弱最优，但红晶片用完了 | D29: =D15+20 -> 134 | E29: =E15+20 -> 121 | F29: =F15+20 -> 124 | G29: =G15+20 -> 124 | H29: =H15+20 -> 169 | I29: =I15+20 -> 182
A30: 减防最优，但红晶片用完了 | D30: =D14+20 -> 134 | E30: =E14+20 -> 121 | F30: =F14+20 -> 124 | G30: =G14+20 -> 124 | H30: =H14+20 -> 224 | I30: =I14+20 -> 127

Sheet SS战型统计 废弃
A1: ID | B1: Label | C1: 角色 | E1: Attacker | F1: Breaker | G1: Blaster | H1: Healer | I1: Buffer | J1: Debuffer | K1: Defender | L1: Admiral | M1: Rider
A2: 44000002 | B2: BaseParameter.Character.RKayamori | C2: 茅森 月歌 | E2: 5 | I2: 1
A3: 44000003 | B3: BaseParameter.Character.YIzumi | C3: 和泉 由希 | F3: 6
A4: 44000004 | B4: BaseParameter.Character.TTojo | C4: 東城 司 | I4: 4 | J4: 1
A5: 44000005 | B5: BaseParameter.Character.KAsakura | C5: 朝倉 可憐-1 | F5: 1 | G5: 6
A6: 44000006 | B6: BaseParameter.Character.Karen | C6: 朝倉 可憐-2 | F6: 1 | G6: 6
A7: 44000007 | B7: BaseParameter.Character.TKunimi | C7: 國見 玉 | H7: 4 | I7: 1
A8: 44000008 | B8: BaseParameter.Character.MAikawa | C8: 逢川 惠 | J8: 5
A10: 44000009 | B10: BaseParameter.Character.EAoi | C10: 蒼井 繪梨花 | K10: 3 | L10: 1
A11: 44000010 | B11: BaseParameter.Character.IMinase | C11: 水瀨 莓 | E11: 3
A12: 44000011 | B12: BaseParameter.Character.SMinase | C12: 水瀨 李 | E12: 2 | F12: 1
A13: 44000012 | B13: BaseParameter.Character.SHiguchi | C13: 樋口 聖華 | H13: 1 | I13: 3
A14: 44000013 | B14: BaseParameter.Character.KHiiragi | C14: 柊木 梢 | G14: 1 | I14: 1 | J14: 2
A15: 44000015 | B15: BaseParameter.Character.Byakko | C15: 白虎 | G15: 2
A17: 44000016 | B17: BaseParameter.Character.YShirakawa | C17: 白河 結奈 | E17: 3 | G17: 2
A18: 44000017 | B18: BaseParameter.Character.MTsukishiro | C18: 月城 最中 | E18: 3
A19: 44000018 | B19: BaseParameter.Character.MKiryu | C19: 桐生 美也 | G19: 1 | J19: 3
A20: 44000019 | B20: BaseParameter.Character.CSugahara | C20: 菅原 千惠 | H20: 1 | I20: 1 | K20: 2
A21: 44000020 | B21: BaseParameter.Character.HOgasawara | C21: 小笠原 緋雨 | E21: 1 | F21: 2 | J21: 1
A22: 44000021 | B22: BaseParameter.Character.SKura | C22: 藏 里見 | E22: 1 | G22: 2
A24: 44000022 | B24: BaseParameter.Character.MSatsuki | C24: 佐月 麻里 | E24: 2 | I24: 2 | J24: 1
A25: 44000023 | B25: BaseParameter.Character.SSakuraba | C25: 櫻庭 星羅 | I25: 1 | K25: 3
A26: 44000024 | B26: BaseParameter.Character.BIYamawaki | C26: 山脇・波昂・伊瓦爾 | E26: 3 | G26: 1
A27: 44000025 | B27: BaseParameter.Character.AKanzaki | C27: 神崎 阿黛爾海德 | G27: 4
A28: 44000026 | B28: BaseParameter.Character.MTenne | C28: 天音 巫呼 | H28: 1 | J28: 3
A29: 44000034 | B29: BaseParameter.Character.STezuka
A30: 44000035 | B30: BaseParameter.Character.NNanase | C30: 七瀨 七海 | M30: 1
A31: 44000036 | B31: BaseParameter.Character.YBungo | C31: 豐後 彌生 | F31: 4
A33: 44000037 | B33: BaseParameter.Character.MAsami
A34: 44000038 | B34: BaseParameter.Character.MNikaido | C34: 二階堂 三鄉 | E34: 2 | J34: 1
A35: 44000039 | B35: BaseParameter.Character.IIshii | C35: 石井 色葉 | I35: 3
A36: 44000040 | B36: BaseParameter.Character.FMikoto | C36: 命 吹雪 | E36: 1 | J36: 1
A37: 44000041 | B37: BaseParameter.Character.RMurohushi | C37: 室伏 理沙 | H37: 3
A38: 44000042 | B38: BaseParameter.Character.ADate | C38: 伊達 朱里 | F38: 3
A39: 44000043 | B39: BaseParameter.Character.AMizuhara | C39: 瑞原 藍娜 | J39: 4
A41: 44000044 | B41: BaseParameter.Character.IcOhshima | C41: 大島 一千子 | J41: 1 | K41: 2
A42: 44000045 | B42: BaseParameter.Character.NiOhshima | C42: 大島 二以奈 | E42: 2 | G42: 1
A43: 44000046 | B43: BaseParameter.Character.MiOhshima | C43: 大島 三野里 | E43: 1 | I43: 1
A44: 44000047 | B44: BaseParameter.Character.YoOhshima | C44: 大島 四葉草 | I44: 3
A45: 44000048 | B45: BaseParameter.Character.IrOhshima | C45: 大島 五十鈴 | J45: 3
...

Sheet SS战型分类
D1: Power | E1: Dexterity | F1: Toughness | G1: Spirit | H1: Wisdom | I1: Luck
B2: 力体偏向 | D2: 0.7 | E2: 0.4 | F2: 0.6 | G2: 0.55 | H2: 0.5 | I2: 0.55
D3: 39 | E3: 35 | F3: 39 | G3: 37 | H3: 35 | I3: 37
B4: 器运偏向 | D4: 0.4 | E4: 0.7 | F4: 0.55 | G4: 0.5 | H4: 0.55 | I4: 0.6
D5: 35 | E5: 39 | F5: 37 | G5: 35 | H5: 37 | I5: 39
B6: 智精偏向 | D6: 0.55 | E6: 0.55 | F6: 0.4 | G6: 0.6 | H6: 0.7 | I6: 0.5
D7: 37 | E7: 37 | F7: 35 | G7: 39 | H7: 39 | I7: 35
B8: 力器偏向 | D8: 0.7 | E8: 0.6 | F8: 0.5 | G8: 0.5 | H8: 0.45 | I8: 0.55
D9: 39 | E9: 39 | F9: 37 | G9: 35 | H9: 35 | I9: 37

Sheet Sheet2
A1: ID | B1: Label | C1: 角色 | E1: Power | F1: Dexterity | G1: Toughness | H1: Spirit | I1: Wisdom | J1: Luck
A2: 44000002 | B2: BaseParameter.Character.RKayamori | C2: 茅森 月歌
A3: 44000003 | B3: BaseParameter.Character.YIzumi | C3: 和泉 由希
A4: 44000004 | B4: BaseParameter.Character.TTojo | C4: 東城 司
A5: 44000005 | B5: BaseParameter.Character.KAsakura | C5: 朝倉 可憐-1
A6: 44000006 | B6: BaseParameter.Character.Karen | C6: 朝倉 可憐-2
