Workbook

Sheet 排轴
A1: 回合 | B1: 1 | C1: 行动 | G1: 2 | H1: 行动 | L1: 3 | M1: 行动 | Q1: 4 | S1: 5 | U1: 6 | W1: 牢房 | X1: 被动 OD | Y1: 当前OD（Assist） | Z1: 当前OD | AA1: 本回合DR | AB1: BOSS DR | AC1: 剩余 DR | AD1: helpers
B2: 当前SP | C2: 消耗 | D2: 获得 | E2: OD | F2: DR | G2: 当前SP | H2: 消耗 | I2: 获得 | J2: OD | K2: DR | L2: 当前SP | M2: 消耗 | N2: 获得 | O2: OD | P2: DR | Q2: 当前 | R2: 获得 | S2: 当前 | T2: 获得 | U2: 当前 | V2: 获得 | AC2: =AB2-SUM(AA:AA) -> 0
A3: 入场 | Y3: \ | Z3: \ | AA3: \ | AB3: 请选择OD表达方式 | AD3: =B3 -> 0 | AE3: =G3 -> 0 | AF3: =L3 -> 0 | AG3: =Q3 -> 0 | AH3: =S3 -> 0 | AI3: =U3 -> 0
B4: \ | C4: \ | E4: \ | F4: \ | G4: \ | H4: \ | J4: \ | K4: \ | L4: \ | M4: \ | O4: \ | P4: \ | Q4: \ | S4: \ | U4: \ | AB4: 百分比 | AJ4: =IF(AB4="hit数",120,300) -> 300
A5: 1 | Q5: =IF(OR(COUNTIF(AD3:AI3,0)>0,COUNTIF(AD5:AF5,0)>0),"",INDEX(AD3:AI3,MATCH(TRUE,ISNA(MATCH(AD3:AI3,AD5:AF5,0)),0))) | S5: =IF(OR(COUNTIF(AD3:AI3,0)>0,COUNTIF(AD5:AG5,0)>0),"",INDEX(AD3:AI3,MATCH(TRUE,ISNA(MATCH(AD3:AI3,AD5:AG5,0)),0))) | U5: =IF(OR(COUNTIF(AD3:AI3,0)>0,COUNTIF(AD5:AH5,0)>0),"",INDEX(AD3:AI3,MATCH(TRUE,ISNA(MATCH(AD3:AI3,AD5:AH5,0)),0))) | Y5: =W3+X3 -> 0 | Z5: =IF(Y5<$AJ$4,Y5,$AJ$4) -> 0 | AA5: =F6+K6+P6 -> 0 | AD5: =B5 -> 0 | AE5: =G5 -> 0 | AF5: =L5 -> 0 | AG5: =Q5 | AH5: =S5 | AI5: =U5
B6: =CHOOSE(MATCH(B5,B3:U3,0),D4,0,0,0,0,I4,0,0,0,0,N4,0,0,0,0,R4,0,T4,0,V4) -> #N/A | G6: =CHOOSE(MATCH(G5,B3:U3,0),D4,0,0,0,0,I4,0,0,0,0,N4,0,0,0,0,R4,0,T4,0,V4) -> #N/A | L6: =CHOOSE(MATCH(L5,B3:U3,0),D4,0,0,0,0,I4,0,0,0,0,N4,0,0,0,0,R4,0,T4,0,V4) -> #N/A | Q6: =CHOOSE(MATCH(Q5,B3:U3,0),D4,0,0,0,0,I4,0,0,0,0,N4,0,0,0,0,R4,0,T4,0,V4) -> #N/A | S6: =CHOOSE(MATCH(S5,B3:U3,0),D4,0,0,0,0,I4,0,0,0,0,N4,0,0,0,0,R4,0,T4,0,V4) -> #N/A | U6: =CHOOSE(MATCH(U5,B3:U3,0),D4,0,0,0,0,I4,0,0,0,0,N4,0,0,0,0,R4,0,T4,0,V4) -> #N/A
Q7: =IF(OR(COUNTIF(AD5:AI5,0)>0,COUNTIF(AD7:AF7,0)>0),"",INDEX(AD5:AI5,MATCH(TRUE,ISNA(MATCH(AD5:AI5,AD7:AF7,0)),0))) | S7: =IF(OR(COUNTIF(AD5:AI5,0)>0,COUNTIF(AD7:AG7,0)>0),"",INDEX(AD5:AI5,MATCH(TRUE,ISNA(MATCH(AD5:AI5,AD7:AG7,0)),0))) | U7: =IF(OR(COUNTIF(AD5:AI5,0)>0,COUNTIF(AD7:AH7,0)>0),"",INDEX(AD5:AI5,MATCH(TRUE,ISNA(MATCH(AD5:AI5,AD7:AH7,0)),0))) | Y7: =IF(OR(A5="前置OD1",A5="后置OD1"),AK7,IF(OR(A5="前置OD2",A5="后置OD2"),AL7,IF(OR(A5="前置OD3",A5="后置OD3"),AM7,IF(LEFT(A7,2)="后置",Y5+E6+J6+O6+W5,Y5+E6+J6+O6+W5+X5)))) -> 0 | Z7: =IF(Y7<$AJ$4,Y7,$AJ$4) -> 0 | AA7: =F8+K8+P8 -> 0 | AD7: =B7 -> 0 | AE7: =G7 -> 0 | AF7: =L7 -> 0 | AG7: =Q7 | AH7: =S7 | AI7: =U7 | AK7: =Z5-$AJ$4/3+E6+J6+O6+X5 -> -100 | AL7: =Z5-$AJ$4/3*2+E6+J6+O6+X5 -> -200 | AM7: =Z5-$AJ$4+E6+J6+O6+X5 -> -300
B8: =CHOOSE(MATCH(B7,B5:U5,0),B6-C6+D6,0,0,0,0,G6-H6+I6,0,0,0,0,L6-M6+N6,0,0,0,0,Q6+R6,0,S6+T6,0,U6+V6) -> #N/A | G8: =CHOOSE(MATCH(G7,B5:U5,0),B6-C6+D6,0,0,0,0,G6-H6+I6,0,0,0,0,L6-M6+N6,0,0,0,0,Q6+R6,0,S6+T6,0,U6+V6) -> #N/A | L8: =CHOOSE(MATCH(L7,B5:U5,0),B6-C6+D6,0,0,0,0,G6-H6+I6,0,0,0,0,L6-M6+N6,0,0,0,0,Q6+R6,0,S6+T6,0,U6+V6) -> #N/A | Q8: =CHOOSE(MATCH(Q7,B5:U5,0),B6-C6+D6,0,0,0,0,G6-H6+I6,0,0,0,0,L6-M6+N6,0,0,0,0,Q6+R6,0,S6+T6,0,U6+V6) -> #N/A | S8: =CHOOSE(MATCH(S7,B5:U5,0),B6-C6+D6,0,0,0,0,G6-H6+I6,0,0,0,0,L6-M6+N6,0,0,0,0,Q6+R6,0,S6+T6,0,U6+V6) -> #N/A | U8: =CHOOSE(MATCH(U7,B5:U5,0),B6-C6+D6,0,0,0,0,G6-H6+I6,0,0,0,0,L6-M6+N6,0,0,0,0,Q6+R6,0,S6+T6,0,U6+V6) -> #N/A | AB8: Copy-OD计算表
Q9: =IF(OR(COUNTIF(AD7:AI7,0)>0,COUNTIF(AD9:AF9,0)>0),"",INDEX(AD7:AI7,MATCH(TRUE,ISNA(MATCH(AD7:AI7,AD9:AF9,0)),0))) | S9: =IF(OR(COUNTIF(AD7:AI7,0)>0,COUNTIF(AD9:AG9,0)>0),"",INDEX(AD7:AI7,MATCH(TRUE,ISNA(MATCH(AD7:AI7,AD9:AG9,0)),0))) | U9: =IF(OR(COUNTIF(AD7:AI7,0)>0,COUNTIF(AD9:AH9,0)>0),"",INDEX(AD7:AI7,MATCH(TRUE,ISNA(MATCH(AD7:AI7,AD9:AH9,0)),0))) | Y9: =IF(OR(A7="前置OD1",A7="后置OD1"),AK9,IF(OR(A7="前置OD2",A7="后置OD2"),AL9,IF(OR(A7="前置OD3",A7="后置OD3"),AM9,IF(LEFT(A9,2)="后置",Y7+E8+J8+O8+W7,Y7+E8+J8+O8+W7+X7)))) -> 0 | Z9: =IF(Y9<$AJ$4,Y9,$AJ$4) -> 0 | AA9: =F10+K10+P10 -> 0 | AD9: =B9 -> 0 | AE9: =G9 -> 0 | AF9: =L9 -> 0 | AG9: =Q9 | AH9: =S9 | AI9: =U9 | AK9: =Z7-$AJ$4/3+E8+J8+O8+X7 -> -100 | AL9: =Z7-$AJ$4/3*2+E8+J8+O8+X7 -> -200 | AM9: =Z7-$AJ$4+E8+J8+O8+X7 -> -300
B10: =CHOOSE(MATCH(B9,B7:U7,0),B8-C8+D8,0,0,0,0,G8-H8+I8,0,0,0,0,L8-M8+N8,0,0,0,0,Q8+R8,0,S8+T8,0,U8+V8) -> #N/A | G10: =CHOOSE(MATCH(G9,B7:U7,0),B8-C8+D8,0,0,0,0,G8-H8+I8,0,0,0,0,L8-M8+N8,0,0,0,0,Q8+R8,0,S8+T8,0,U8+V8) -> #N/A | L10: =CHOOSE(MATCH(L9,B7:U7,0),B8-C8+D8,0,0,0,0,G8-H8+I8,0,0,0,0,L8-M8+N8,0,0,0,0,Q8+R8,0,S8+T8,0,U8+V8) -> #N/A | Q10: =CHOOSE(MATCH(Q9,B7:U7,0),B8-C8+D8,0,0,0,0,G8-H8+I8,0,0,0,0,L8-M8+N8,0,0,0,0,Q8+R8,0,S8+T8,0,U8+V8) -> #N/A | S10: =CHOOSE(MATCH(S9,B7:U7,0),B8-C8+D8,0,0,0,0,G8-H8+I8,0,0,0,0,L8-M8+N8,0,0,0,0,Q8+R8,0,S8+T8,0,U8+V8) -> #N/A | U10: =CHOOSE(MATCH(U9,B7:U7,0),B8-C8+D8,0,0,0,0,G8-H8+I8,0,0,0,0,L8-M8+N8,0,0,0,0,Q8+R8,0,S8+T8,0,U8+V8) -> #N/A
Q11: =IF(OR(COUNTIF(AD9:AI9,0)>0,COUNTIF(AD11:AF11,0)>0),"",INDEX(AD9:AI9,MATCH(TRUE,ISNA(MATCH(AD9:AI9,AD11:AF11,0)),0))) | S11: =IF(OR(COUNTIF(AD9:AI9,0)>0,COUNTIF(AD11:AG11,0)>0),"",INDEX(AD9:AI9,MATCH(TRUE,ISNA(MATCH(AD9:AI9,AD11:AG11,0)),0))) | U11: =IF(OR(COUNTIF(AD9:AI9,0)>0,COUNTIF(AD11:AH11,0)>0),"",INDEX(AD9:AI9,MATCH(TRUE,ISNA(MATCH(AD9:AI9,AD11:AH11,0)),0))) | Y11: =IF(OR(A9="前置OD1",A9="后置OD1"),AK11,IF(OR(A9="前置OD2",A9="后置OD2"),AL11,IF(OR(A9="前置OD3",A9="后置OD3"),AM11,IF(LEFT(A11,2)="后置",Y9+E10+J10+O10+W9,Y9+E10+J10+O10+W9+X9)))) -> 0 | Z11: =IF(Y11<$AJ$4,Y11,$AJ$4) -> 0 | AA11: =F12+K12+P12 -> 0 | AD11: =B11 -> 0 | AE11: =G11 -> 0 | AF11: =L11 -> 0 | AG11: =Q11 | AH11: =S11 | AI11: =U11 | AK11: =Z9-$AJ$4/3+E10+J10+O10+X9 -> -100 | AL11: =Z9-$AJ$4/3*2+E10+J10+O10+X9 -> -200 | AM11: =Z9-$AJ$4+E10+J10+O10+X9 -> -300
B12: =CHOOSE(MATCH(B11,B9:U9,0),B10-C10+D10,0,0,0,0,G10-H10+I10,0,0,0,0,L10-M10+N10,0,0,0,0,Q10+R10,0,S10+T10,0,U10+V10) -> #N/A | G12: =CHOOSE(MATCH(G11,B9:U9,0),B10-C10+D10,0,0,0,0,G10-H10+I10,0,0,0,0,L10-M10+N10,0,0,0,0,Q10+R10,0,S10+T10,0,U10+V10) -> #N/A | L12: =CHOOSE(MATCH(L11,B9:U9,0),B10-C10+D10,0,0,0,0,G10-H10+I10,0,0,0,0,L10-M10+N10,0,0,0,0,Q10+R10,0,S10+T10,0,U10+V10) -> #N/A | Q12: =CHOOSE(MATCH(Q11,B9:U9,0),B10-C10+D10,0,0,0,0,G10-H10+I10,0,0,0,0,L10-M10+N10,0,0,0,0,Q10+R10,0,S10+T10,0,U10+V10) -> #N/A | S12: =CHOOSE(MATCH(S11,B9:U9,0),B10-C10+D10,0,0,0,0,G10-H10+I10,0,0,0,0,L10-M10+N10,0,0,0,0,Q10+R10,0,S10+T10,0,U10+V10) -> #N/A | U12: =CHOOSE(MATCH(U11,B9:U9,0),B10-C10+D10,0,0,0,0,G10-H10+I10,0,0,0,0,L10-M10+N10,0,0,0,0,Q10+R10,0,S10+T10,0,U10+V10) -> #N/A
Q13: =IF(OR(COUNTIF(AD11:AI11,0)>0,COUNTIF(AD13:AF13,0)>0),"",INDEX(AD11:AI11,MATCH(TRUE,ISNA(MATCH(AD11:AI11,AD13:AF13,0)),0))) | S13: =IF(OR(COUNTIF(AD11:AI11,0)>0,COUNTIF(AD13:AG13,0)>0),"",INDEX(AD11:AI11,MATCH(TRUE,ISNA(MATCH(AD11:AI11,AD13:AG13,0)),0))) | U13: =IF(OR(COUNTIF(AD11:AI11,0)>0,COUNTIF(AD13:AH13,0)>0),"",INDEX(AD11:AI11,MATCH(TRUE,ISNA(MATCH(AD11:AI11,AD13:AH13,0)),0))) | Y13: =IF(OR(A11="前置OD1",A11="后置OD1"),AK13,IF(OR(A11="前置OD2",A11="后置OD2"),AL13,IF(OR(A11="前置OD3",A11="后置OD3"),AM13,IF(LEFT(A13,2)="后置",Y11+E12+J12+O12+W11,Y11+E12+J12+O12+W11+X11)))) -> 0 | Z13: =IF(Y13<$AJ$4,Y13,$AJ$4) -> 0 | AA13: =F14+K14+P14 -> 0 | AD13: =B13 -> 0 | AE13: =G13 -> 0 | AF13: =L13 -> 0 | AG13: =Q13 | AH13: =S13 | AI13: =U13 | AK13: =Z11-$AJ$4/3+E12+J12+O12+X11 -> -100 | AL13: =Z11-$AJ$4/3*2+E12+J12+O12+X11 -> -200 | AM13: =Z11-$AJ$4+E12+J12+O12+X11 -> -300
B14: =CHOOSE(MATCH(B13,B11:U11,0),B12-C12+D12,0,0,0,0,G12-H12+I12,0,0,0,0,L12-M12+N12,0,0,0,0,Q12+R12,0,S12+T12,0,U12+V12) -> #N/A | G14: =CHOOSE(MATCH(G13,B11:U11,0),B12-C12+D12,0,0,0,0,G12-H12+I12,0,0,0,0,L12-M12+N12,0,0,0,0,Q12+R12,0,S12+T12,0,U12+V12) -> #N/A | L14: =CHOOSE(MATCH(L13,B11:U11,0),B12-C12+D12,0,0,0,0,G12-H12+I12,0,0,0,0,L12-M12+N12,0,0,0,0,Q12+R12,0,S12+T12,0,U12+V12) -> #N/A | Q14: =CHOOSE(MATCH(Q13,B11:U11,0),B12-C12+D12,0,0,0,0,G12-H12+I12,0,0,0,0,L12-M12+N12,0,0,0,0,Q12+R12,0,S12+T12,0,U12+V12) -> #N/A | S14: =CHOOSE(MATCH(S13,B11:U11,0),B12-C12+D12,0,0,0,0,G12-H12+I12,0,0,0,0,L12-M12+N12,0,0,0,0,Q12+R12,0,S12+T12,0,U12+V12) -> #N/A | U14: =CHOOSE(MATCH(U13,B11:U11,0),B12-C12+D12,0,0,0,0,G12-H12+I12,0,0,0,0,L12-M12+N12,0,0,0,0,Q12+R12,0,S12+T12,0,U12+V12) -> #N/A
Q15: =IF(OR(COUNTIF(AD13:AI13,0)>0,COUNTIF(AD15:AF15,0)>0),"",INDEX(AD13:AI13,MATCH(TRUE,ISNA(MATCH(AD13:AI13,AD15:AF15,0)),0))) | S15: =IF(OR(COUNTIF(AD13:AI13,0)>0,COUNTIF(AD15:AG15,0)>0),"",INDEX(AD13:AI13,MATCH(TRUE,ISNA(MATCH(AD13:AI13,AD15:AG15,0)),0))) | U15: =IF(OR(COUNTIF(AD13:AI13,0)>0,COUNTIF(AD15:AH15,0)>0),"",INDEX(AD13:AI13,MATCH(TRUE,ISNA(MATCH(AD13:AI13,AD15:AH15,0)),0))) | Y15: =IF(OR(A13="前置OD1",A13="后置OD1"),AK15,IF(OR(A13="前置OD2",A13="后置OD2"),AL15,IF(OR(A13="前置OD3",A13="后置OD3"),AM15,IF(LEFT(A15,2)="后置",Y13+E14+J14+O14+W13,Y13+E14+J14+O14+W13+X13)))) -> 0 | Z15: =IF(Y15<$AJ$4,Y15,$AJ$4) -> 0 | AA15: =F16+K16+P16 -> 0 | AD15: =B15 -> 0 | AE15: =G15 -> 0 | AF15: =L15 -> 0 | AG15: =Q15 | AH15: =S15 | AI15: =U15 | AK15: =Z13-$AJ$4/3+E14+J14+O14+X13 -> -100 | AL15: =Z13-$AJ$4/3*2+E14+J14+O14+X13 -> -200 | AM15: =Z13-$AJ$4+E14+J14+O14+X13 -> -300
B16: =CHOOSE(MATCH(B15,B13:U13,0),B14-C14+D14,0,0,0,0,G14-H14+I14,0,0,0,0,L14-M14+N14,0,0,0,0,Q14+R14,0,S14+T14,0,U14+V14) -> #N/A | G16: =CHOOSE(MATCH(G15,B13:U13,0),B14-C14+D14,0,0,0,0,G14-H14+I14,0,0,0,0,L14-M14+N14,0,0,0,0,Q14+R14,0,S14+T14,0,U14+V14) -> #N/A | L16: =CHOOSE(MATCH(L15,B13:U13,0),B14-C14+D14,0,0,0,0,G14-H14+I14,0,0,0,0,L14-M14+N14,0,0,0,0,Q14+R14,0,S14+T14,0,U14+V14) -> #N/A | Q16: =CHOOSE(MATCH(Q15,B13:U13,0),B14-C14+D14,0,0,0,0,G14-H14+I14,0,0,0,0,L14-M14+N14,0,0,0,0,Q14+R14,0,S14+T14,0,U14+V14) -> #N/A | S16: =CHOOSE(MATCH(S15,B13:U13,0),B14-C14+D14,0,0,0,0,G14-H14+I14,0,0,0,0,L14-M14+N14,0,0,0,0,Q14+R14,0,S14+T14,0,U14+V14) -> #N/A | U16: =CHOOSE(MATCH(U15,B13:U13,0),B14-C14+D14,0,0,0,0,G14-H14+I14,0,0,0,0,L14-M14+N14,0,0,0,0,Q14+R14,0,S14+T14,0,U14+V14) -> #N/A
A17: 7 | Q17: =IF(OR(COUNTIF(AD15:AI15,0)>0,COUNTIF(AD17:AF17,0)>0),"",INDEX(AD15:AI15,MATCH(TRUE,ISNA(MATCH(AD15:AI15,AD17:AF17,0)),0))) | S17: =IF(OR(COUNTIF(AD15:AI15,0)>0,COUNTIF(AD17:AG17,0)>0),"",INDEX(AD15:AI15,MATCH(TRUE,ISNA(MATCH(AD15:AI15,AD17:AG17,0)),0))) | U17: =IF(OR(COUNTIF(AD15:AI15,0)>0,COUNTIF(AD17:AH17,0)>0),"",INDEX(AD15:AI15,MATCH(TRUE,ISNA(MATCH(AD15:AI15,AD17:AH17,0)),0))) | Y17: =IF(OR(A15="前置OD1",A15="后置OD1"),AK17,IF(OR(A15="前置OD2",A15="后置OD2"),AL17,IF(OR(A15="前置OD3",A15="后置OD3"),AM17,IF(LEFT(A17,2)="后置",Y15+E16+J16+O16+W15,Y15+E16+J16+O16+W15+X15)))) -> 0 | Z17: =IF(Y17<$AJ$4,Y17,$AJ$4) -> 0 | AA17: =F18+K18+P18 -> 0 | AD17: =B17 -> 0 | AE17: =G17 -> 0 | AF17: =L17 -> 0 | AG17: =Q17 | AH17: =S17 | AI17: =U17 | AK17: =Z15-$AJ$4/3+E16+J16+O16+X15 -> -100 | AL17: =Z15-$AJ$4/3*2+E16+J16+O16+X15 -> -200 | AM17: =Z15-$AJ$4+E16+J16+O16+X15 -> -300
B18: =CHOOSE(MATCH(B17,B15:U15,0),B16-C16+D16,0,0,0,0,G16-H16+I16,0,0,0,0,L16-M16+N16,0,0,0,0,Q16+R16,0,S16+T16,0,U16+V16) -> #N/A | G18: =CHOOSE(MATCH(G17,B15:U15,0),B16-C16+D16,0,0,0,0,G16-H16+I16,0,0,0,0,L16-M16+N16,0,0,0,0,Q16+R16,0,S16+T16,0,U16+V16) -> #N/A | L18: =CHOOSE(MATCH(L17,B15:U15,0),B16-C16+D16,0,0,0,0,G16-H16+I16,0,0,0,0,L16-M16+N16,0,0,0,0,Q16+R16,0,S16+T16,0,U16+V16) -> #N/A | Q18: =CHOOSE(MATCH(Q17,B15:U15,0),B16-C16+D16,0,0,0,0,G16-H16+I16,0,0,0,0,L16-M16+N16,0,0,0,0,Q16+R16,0,S16+T16,0,U16+V16) -> #N/A | S18: =CHOOSE(MATCH(S17,B15:U15,0),B16-C16+D16,0,0,0,0,G16-H16+I16,0,0,0,0,L16-M16+N16,0,0,0,0,Q16+R16,0,S16+T16,0,U16+V16) -> #N/A | U18: =CHOOSE(MATCH(U17,B15:U15,0),B16-C16+D16,0,0,0,0,G16-H16+I16,0,0,0,0,L16-M16+N16,0,0,0,0,Q16+R16,0,S16+T16,0,U16+V16) -> #N/A
A19: 8 | Q19: =IF(OR(COUNTIF(AD17:AI17,0)>0,COUNTIF(AD19:AF19,0)>0),"",INDEX(AD17:AI17,MATCH(TRUE,ISNA(MATCH(AD17:AI17,AD19:AF19,0)),0))) | S19: =IF(OR(COUNTIF(AD17:AI17,0)>0,COUNTIF(AD19:AG19,0)>0),"",INDEX(AD17:AI17,MATCH(TRUE,ISNA(MATCH(AD17:AI17,AD19:AG19,0)),0))) | U19: =IF(OR(COUNTIF(AD17:AI17,0)>0,COUNTIF(AD19:AH19,0)>0),"",INDEX(AD17:AI17,MATCH(TRUE,ISNA(MATCH(AD17:AI17,AD19:AH19,0)),0))) | Y19: =IF(OR(A17="前置OD1",A17="后置OD1"),AK19,IF(OR(A17="前置OD2",A17="后置OD2"),AL19,IF(OR(A17="前置OD3",A17="后置OD3"),AM19,IF(LEFT(A19,2)="后置",Y17+E18+J18+O18+W17,Y17+E18+J18+O18+W17+X17)))) -> 0 | Z19: =IF(Y19<$AJ$4,Y19,$AJ$4) -> 0 | AA19: =F20+K20+P20 -> 0 | AD19: =B19 -> 0 | AE19: =G19 -> 0 | AF19: =L19 -> 0 | AG19: =Q19 | AH19: =S19 | AI19: =U19 | AK19: =Z17-$AJ$4/3+E18+J18+O18+X17 -> -100 | AL19: =Z17-$AJ$4/3*2+E18+J18+O18+X17 -> -200 | AM19: =Z17-$AJ$4+E18+J18+O18+X17 -> -300
B20: =CHOOSE(MATCH(B19,B17:U17,0),B18-C18+D18,0,0,0,0,G18-H18+I18,0,0,0,0,L18-M18+N18,0,0,0,0,Q18+R18,0,S18+T18,0,U18+V18) -> #N/A | G20: =CHOOSE(MATCH(G19,B17:U17,0),B18-C18+D18,0,0,0,0,G18-H18+I18,0,0,0,0,L18-M18+N18,0,0,0,0,Q18+R18,0,S18+T18,0,U18+V18) -> #N/A | L20: =CHOOSE(MATCH(L19,B17:U17,0),B18-C18+D18,0,0,0,0,G18-H18+I18,0,0,0,0,L18-M18+N18,0,0,0,0,Q18+R18,0,S18+T18,0,U18+V18) -> #N/A | Q20: =CHOOSE(MATCH(Q19,B17:U17,0),B18-C18+D18,0,0,0,0,G18-H18+I18,0,0,0,0,L18-M18+N18,0,0,0,0,Q18+R18,0,S18+T18,0,U18+V18) -> #N/A | S20: =CHOOSE(MATCH(S19,B17:U17,0),B18-C18+D18,0,0,0,0,G18-H18+I18,0,0,0,0,L18-M18+N18,0,0,0,0,Q18+R18,0,S18+T18,0,U18+V18) -> #N/A | U20: =CHOOSE(MATCH(U19,B17:U17,0),B18-C18+D18,0,0,0,0,G18-H18+I18,0,0,0,0,L18-M18+N18,0,0,0,0,Q18+R18,0,S18+T18,0,U18+V18) -> #N/A
A21: 9 | Q21: =IF(OR(COUNTIF(AD19:AI19,0)>0,COUNTIF(AD21:AF21,0)>0),"",INDEX(AD19:AI19,MATCH(TRUE,ISNA(MATCH(AD19:AI19,AD21:AF21,0)),0))) | S21: =IF(OR(COUNTIF(AD19:AI19,0)>0,COUNTIF(AD21:AG21,0)>0),"",INDEX(AD19:AI19,MATCH(TRUE,ISNA(MATCH(AD19:AI19,AD21:AG21,0)),0))) | U21: =IF(OR(COUNTIF(AD19:AI19,0)>0,COUNTIF(AD21:AH21,0)>0),"",INDEX(AD19:AI19,MATCH(TRUE,ISNA(MATCH(AD19:AI19,AD21:AH21,0)),0))) | Y21: =IF(OR(A19="前置OD1",A19="后置OD1"),AK21,IF(OR(A19="前置OD2",A19="后置OD2"),AL21,IF(OR(A19="前置OD3",A19="后置OD3"),AM21,IF(LEFT(A21,2)="后置",Y19+E20+J20+O20+W19,Y19+E20+J20+O20+W19+X19)))) -> 0 | Z21: =IF(Y21<$AJ$4,Y21,$AJ$4) -> 0 | AA21: =F22+K22+P22 -> 0 | AD21: =B21 -> 0 | AE21: =G21 -> 0 | AF21: =L21 -> 0 | AG21: =Q21 | AH21: =S21 | AI21: =U21 | AK21: =Z19-$AJ$4/3+E20+J20+O20+X19 -> -100 | AL21: =Z19-$AJ$4/3*2+E20+J20+O20+X19 -> -200 | AM21: =Z19-$AJ$4+E20+J20+O20+X19 -> -300
B22: =CHOOSE(MATCH(B21,B19:U19,0),B20-C20+D20,0,0,0,0,G20-H20+I20,0,0,0,0,L20-M20+N20,0,0,0,0,Q20+R20,0,S20+T20,0,U20+V20) -> #N/A | G22: =CHOOSE(MATCH(G21,B19:U19,0),B20-C20+D20,0,0,0,0,G20-H20+I20,0,0,0,0,L20-M20+N20,0,0,0,0,Q20+R20,0,S20+T20,0,U20+V20) -> #N/A | L22: =CHOOSE(MATCH(L21,B19:U19,0),B20-C20+D20,0,0,0,0,G20-H20+I20,0,0,0,0,L20-M20+N20,0,0,0,0,Q20+R20,0,S20+T20,0,U20+V20) -> #N/A | Q22: =CHOOSE(MATCH(Q21,B19:U19,0),B20-C20+D20,0,0,0,0,G20-H20+I20,0,0,0,0,L20-M20+N20,0,0,0,0,Q20+R20,0,S20+T20,0,U20+V20) -> #N/A | S22: =CHOOSE(MATCH(S21,B19:U19,0),B20-C20+D20,0,0,0,0,G20-H20+I20,0,0,0,0,L20-M20+N20,0,0,0,0,Q20+R20,0,S20+T20,0,U20+V20) -> #N/A | U22: =CHOOSE(MATCH(U21,B19:U19,0),B20-C20+D20,0,0,0,0,G20-H20+I20,0,0,0,0,L20-M20+N20,0,0,0,0,Q20+R20,0,S20+T20,0,U20+V20) -> #N/A
A23: 10 | Q23: =IF(OR(COUNTIF(AD21:AI21,0)>0,COUNTIF(AD23:AF23,0)>0),"",INDEX(AD21:AI21,MATCH(TRUE,ISNA(MATCH(AD21:AI21,AD23:AF23,0)),0))) | S23: =IF(OR(COUNTIF(AD21:AI21,0)>0,COUNTIF(AD23:AG23,0)>0),"",INDEX(AD21:AI21,MATCH(TRUE,ISNA(MATCH(AD21:AI21,AD23:AG23,0)),0))) | U23: =IF(OR(COUNTIF(AD21:AI21,0)>0,COUNTIF(AD23:AH23,0)>0),"",INDEX(AD21:AI21,MATCH(TRUE,ISNA(MATCH(AD21:AI21,AD23:AH23,0)),0))) | Y23: =IF(OR(A21="前置OD1",A21="后置OD1"),AK23,IF(OR(A21="前置OD2",A21="后置OD2"),AL23,IF(OR(A21="前置OD3",A21="后置OD3"),AM23,IF(LEFT(A23,2)="后置",Y21+E22+J22+O22+W21,Y21+E22+J22+O22+W21+X21)))) -> 0 | Z23: =IF(Y23<$AJ$4,Y23,$AJ$4) -> 0 | AA23: =F24+K24+P24 -> 0 | AD23: =B23 -> 0 | AE23: =G23 -> 0 | AF23: =L23 -> 0 | AG23: =Q23 | AH23: =S23 | AI23: =U23 | AK23: =Z21-$AJ$4/3+E22+J22+O22+X21 -> -100 | AL23: =Z21-$AJ$4/3*2+E22+J22+O22+X21 -> -200 | AM23: =Z21-$AJ$4+E22+J22+O22+X21 -> -300
B24: =CHOOSE(MATCH(B23,B21:U21,0),B22-C22+D22,0,0,0,0,G22-H22+I22,0,0,0,0,L22-M22+N22,0,0,0,0,Q22+R22,0,S22+T22,0,U22+V22) -> #N/A | G24: =CHOOSE(MATCH(G23,B21:U21,0),B22-C22+D22,0,0,0,0,G22-H22+I22,0,0,0,0,L22-M22+N22,0,0,0,0,Q22+R22,0,S22+T22,0,U22+V22) -> #N/A | L24: =CHOOSE(MATCH(L23,B21:U21,0),B22-C22+D22,0,0,0,0,G22-H22+I22,0,0,0,0,L22-M22+N22,0,0,0,0,Q22+R22,0,S22+T22,0,U22+V22) -> #N/A | Q24: =CHOOSE(MATCH(Q23,B21:U21,0),B22-C22+D22,0,0,0,0,G22-H22+I22,0,0,0,0,L22-M22+N22,0,0,0,0,Q22+R22,0,S22+T22,0,U22+V22) -> #N/A | S24: =CHOOSE(MATCH(S23,B21:U21,0),B22-C22+D22,0,0,0,0,G22-H22+I22,0,0,0,0,L22-M22+N22,0,0,0,0,Q22+R22,0,S22+T22,0,U22+V22) -> #N/A | U24: =CHOOSE(MATCH(U23,B21:U21,0),B22-C22+D22,0,0,0,0,G22-H22+I22,0,0,0,0,L22-M22+N22,0,0,0,0,Q22+R22,0,S22+T22,0,U22+V22) -> #N/A
A25: 11 | Q25: =IF(OR(COUNTIF(AD23:AI23,0)>0,COUNTIF(AD25:AF25,0)>0),"",INDEX(AD23:AI23,MATCH(TRUE,ISNA(MATCH(AD23:AI23,AD25:AF25,0)),0))) | S25: =IF(OR(COUNTIF(AD23:AI23,0)>0,COUNTIF(AD25:AG25,0)>0),"",INDEX(AD23:AI23,MATCH(TRUE,ISNA(MATCH(AD23:AI23,AD25:AG25,0)),0))) | U25: =IF(OR(COUNTIF(AD23:AI23,0)>0,COUNTIF(AD25:AH25,0)>0),"",INDEX(AD23:AI23,MATCH(TRUE,ISNA(MATCH(AD23:AI23,AD25:AH25,0)),0))) | Y25: =IF(OR(A23="前置OD1",A23="后置OD1"),AK25,IF(OR(A23="前置OD2",A23="后置OD2"),AL25,IF(OR(A23="前置OD3",A23="后置OD3"),AM25,IF(LEFT(A25,2)="后置",Y23+E24+J24+O24+W23,Y23+E24+J24+O24+W23+X23)))) -> 0 | Z25: =IF(Y25<$AJ$4,Y25,$AJ$4) -> 0 | AA25: =F26+K26+P26 -> 0 | AD25: =B25 -> 0 | AE25: =G25 -> 0 | AF25: =L25 -> 0 | AG25: =Q25 | AH25: =S25 | AI25: =U25 | AK25: =Z23-$AJ$4/3+E24+J24+O24+X23 -> -100 | AL25: =Z23-$AJ$4/3*2+E24+J24+O24+X23 -> -200 | AM25: =Z23-$AJ$4+E24+J24+O24+X23 -> -300
B26: =CHOOSE(MATCH(B25,B23:U23,0),B24-C24+D24,0,0,0,0,G24-H24+I24,0,0,0,0,L24-M24+N24,0,0,0,0,Q24+R24,0,S24+T24,0,U24+V24) -> #N/A | G26: =CHOOSE(MATCH(G25,B23:U23,0),B24-C24+D24,0,0,0,0,G24-H24+I24,0,0,0,0,L24-M24+N24,0,0,0,0,Q24+R24,0,S24+T24,0,U24+V24) -> #N/A | L26: =CHOOSE(MATCH(L25,B23:U23,0),B24-C24+D24,0,0,0,0,G24-H24+I24,0,0,0,0,L24-M24+N24,0,0,0,0,Q24+R24,0,S24+T24,0,U24+V24) -> #N/A | Q26: =CHOOSE(MATCH(Q25,B23:U23,0),B24-C24+D24,0,0,0,0,G24-H24+I24,0,0,0,0,L24-M24+N24,0,0,0,0,Q24+R24,0,S24+T24,0,U24+V24) -> #N/A | S26: =CHOOSE(MATCH(S25,B23:U23,0),B24-C24+D24,0,0,0,0,G24-H24+I24,0,0,0,0,L24-M24+N24,0,0,0,0,Q24+R24,0,S24+T24,0,U24+V24) -> #N/A | U26: =CHOOSE(MATCH(U25,B23:U23,0),B24-C24+D24,0,0,0,0,G24-H24+I24,0,0,0,0,L24-M24+N24,0,0,0,0,Q24+R24,0,S24+T24,0,U24+V24) -> #N/A
A27: 12 | Q27: =IF(OR(COUNTIF(AD25:AI25,0)>0,COUNTIF(AD27:AF27,0)>0),"",INDEX(AD25:AI25,MATCH(TRUE,ISNA(MATCH(AD25:AI25,AD27:AF27,0)),0))) | S27: =IF(OR(COUNTIF(AD25:AI25,0)>0,COUNTIF(AD27:AG27,0)>0),"",INDEX(AD25:AI25,MATCH(TRUE,ISNA(MATCH(AD25:AI25,AD27:AG27,0)),0))) | U27: =IF(OR(COUNTIF(AD25:AI25,0)>0,COUNTIF(AD27:AH27,0)>0),"",INDEX(AD25:AI25,MATCH(TRUE,ISNA(MATCH(AD25:AI25,AD27:AH27,0)),0))) | Y27: =IF(OR(A25="前置OD1",A25="后置OD1"),AK27,IF(OR(A25="前置OD2",A25="后置OD2"),AL27,IF(OR(A25="前置OD3",A25="后置OD3"),AM27,IF(LEFT(A27,2)="后置",Y25+E26+J26+O26+W25,Y25+E26+J26+O26+W25+X25)))) -> 0 | Z27: =IF(Y27<$AJ$4,Y27,$AJ$4) -> 0 | AA27: =F28+K28+P28 -> 0 | AD27: =B27 -> 0 | AE27: =G27 -> 0 | AF27: =L27 -> 0 | AG27: =Q27 | AH27: =S27 | AI27: =U27 | AK27: =Z25-$AJ$4/3+E26+J26+O26+X25 -> -100 | AL27: =Z25-$AJ$4/3*2+E26+J26+O26+X25 -> -200 | AM27: =Z25-$AJ$4+E26+J26+O26+X25 -> -300
B28: =CHOOSE(MATCH(B27,B25:U25,0),B26-C26+D26,0,0,0,0,G26-H26+I26,0,0,0,0,L26-M26+N26,0,0,0,0,Q26+R26,0,S26+T26,0,U26+V26) -> #N/A | G28: =CHOOSE(MATCH(G27,B25:U25,0),B26-C26+D26,0,0,0,0,G26-H26+I26,0,0,0,0,L26-M26+N26,0,0,0,0,Q26+R26,0,S26+T26,0,U26+V26) -> #N/A | L28: =CHOOSE(MATCH(L27,B25:U25,0),B26-C26+D26,0,0,0,0,G26-H26+I26,0,0,0,0,L26-M26+N26,0,0,0,0,Q26+R26,0,S26+T26,0,U26+V26) -> #N/A | Q28: =CHOOSE(MATCH(Q27,B25:U25,0),B26-C26+D26,0,0,0,0,G26-H26+I26,0,0,0,0,L26-M26+N26,0,0,0,0,Q26+R26,0,S26+T26,0,U26+V26) -> #N/A | S28: =CHOOSE(MATCH(S27,B25:U25,0),B26-C26+D26,0,0,0,0,G26-H26+I26,0,0,0,0,L26-M26+N26,0,0,0,0,Q26+R26,0,S26+T26,0,U26+V26) -> #N/A | U28: =CHOOSE(MATCH(U27,B25:U25,0),B26-C26+D26,0,0,0,0,G26-H26+I26,0,0,0,0,L26-M26+N26,0,0,0,0,Q26+R26,0,S26+T26,0,U26+V26) -> #N/A
A29: 13 | Q29: =IF(OR(COUNTIF(AD27:AI27,0)>0,COUNTIF(AD29:AF29,0)>0),"",INDEX(AD27:AI27,MATCH(TRUE,ISNA(MATCH(AD27:AI27,AD29:AF29,0)),0))) | S29: =IF(OR(COUNTIF(AD27:AI27,0)>0,COUNTIF(AD29:AG29,0)>0),"",INDEX(AD27:AI27,MATCH(TRUE,ISNA(MATCH(AD27:AI27,AD29:AG29,0)),0))) | U29: =IF(OR(COUNTIF(AD27:AI27,0)>0,COUNTIF(AD29:AH29,0)>0),"",INDEX(AD27:AI27,MATCH(TRUE,ISNA(MATCH(AD27:AI27,AD29:AH29,0)),0))) | Y29: =IF(OR(A27="前置OD1",A27="后置OD1"),AK29,IF(OR(A27="前置OD2",A27="后置OD2"),AL29,IF(OR(A27="前置OD3",A27="后置OD3"),AM29,IF(LEFT(A29,2)="后置",Y27+E28+J28+O28+W27,Y27+E28+J28+O28+W27+X27)))) -> 0 | Z29: =IF(Y29<$AJ$4,Y29,$AJ$4) -> 0 | AA29: =F30+K30+P30 -> 0 | AD29: =B29 -> 0 | AE29: =G29 -> 0 | AF29: =L29 -> 0 | AG29: =Q29 | AH29: =S29 | AI29: =U29 | AK29: =Z27-$AJ$4/3+E28+J28+O28+X27 -> -100 | AL29: =Z27-$AJ$4/3*2+E28+J28+O28+X27 -> -200 | AM29: =Z27-$AJ$4+E28+J28+O28+X27 -> -300
B30: =CHOOSE(MATCH(B29,B27:U27,0),B28-C28+D28,0,0,0,0,G28-H28+I28,0,0,0,0,L28-M28+N28,0,0,0,0,Q28+R28,0,S28+T28,0,U28+V28) -> #N/A | G30: =CHOOSE(MATCH(G29,B27:U27,0),B28-C28+D28,0,0,0,0,G28-H28+I28,0,0,0,0,L28-M28+N28,0,0,0,0,Q28+R28,0,S28+T28,0,U28+V28) -> #N/A | L30: =CHOOSE(MATCH(L29,B27:U27,0),B28-C28+D28,0,0,0,0,G28-H28+I28,0,0,0,0,L28-M28+N28,0,0,0,0,Q28+R28,0,S28+T28,0,U28+V28) -> #N/A | Q30: =CHOOSE(MATCH(Q29,B27:U27,0),B28-C28+D28,0,0,0,0,G28-H28+I28,0,0,0,0,L28-M28+N28,0,0,0,0,Q28+R28,0,S28+T28,0,U28+V28) -> #N/A | S30: =CHOOSE(MATCH(S29,B27:U27,0),B28-C28+D28,0,0,0,0,G28-H28+I28,0,0,0,0,L28-M28+N28,0,0,0,0,Q28+R28,0,S28+T28,0,U28+V28) -> #N/A | U30: =CHOOSE(MATCH(U29,B27:U27,0),B28-C28+D28,0,0,0,0,G28-H28+I28,0,0,0,0,L28-M28+N28,0,0,0,0,Q28+R28,0,S28+T28,0,U28+V28) -> #N/A
A31: 14 | Q31: =IF(OR(COUNTIF(AD29:AI29,0)>0,COUNTIF(AD31:AF31,0)>0),"",INDEX(AD29:AI29,MATCH(TRUE,ISNA(MATCH(AD29:AI29,AD31:AF31,0)),0))) | S31: =IF(OR(COUNTIF(AD29:AI29,0)>0,COUNTIF(AD31:AG31,0)>0),"",INDEX(AD29:AI29,MATCH(TRUE,ISNA(MATCH(AD29:AI29,AD31:AG31,0)),0))) | U31: =IF(OR(COUNTIF(AD29:AI29,0)>0,COUNTIF(AD31:AH31,0)>0),"",INDEX(AD29:AI29,MATCH(TRUE,ISNA(MATCH(AD29:AI29,AD31:AH31,0)),0))) | Y31: =IF(OR(A29="前置OD1",A29="后置OD1"),AK31,IF(OR(A29="前置OD2",A29="后置OD2"),AL31,IF(OR(A29="前置OD3",A29="后置OD3"),AM31,IF(LEFT(A31,2)="后置",Y29+E30+J30+O30+W29,Y29+E30+J30+O30+W29+X29)))) -> 0 | Z31: =IF(Y31<$AJ$4,Y31,$AJ$4) -> 0 | AA31: =F32+K32+P32 -> 0 | AD31: =B31 -> 0 | AE31: =G31 -> 0 | AF31: =L31 -> 0 | AG31: =Q31 | AH31: =S31 | AI31: =U31 | AK31: =Z29-$AJ$4/3+E30+J30+O30+X29 -> -100 | AL31: =Z29-$AJ$4/3*2+E30+J30+O30+X29 -> -200 | AM31: =Z29-$AJ$4+E30+J30+O30+X29 -> -300
B32: =CHOOSE(MATCH(B31,B29:U29,0),B30-C30+D30,0,0,0,0,G30-H30+I30,0,0,0,0,L30-M30+N30,0,0,0,0,Q30+R30,0,S30+T30,0,U30+V30) -> #N/A | G32: =CHOOSE(MATCH(G31,B29:U29,0),B30-C30+D30,0,0,0,0,G30-H30+I30,0,0,0,0,L30-M30+N30,0,0,0,0,Q30+R30,0,S30+T30,0,U30+V30) -> #N/A | L32: =CHOOSE(MATCH(L31,B29:U29,0),B30-C30+D30,0,0,0,0,G30-H30+I30,0,0,0,0,L30-M30+N30,0,0,0,0,Q30+R30,0,S30+T30,0,U30+V30) -> #N/A | Q32: =CHOOSE(MATCH(Q31,B29:U29,0),B30-C30+D30,0,0,0,0,G30-H30+I30,0,0,0,0,L30-M30+N30,0,0,0,0,Q30+R30,0,S30+T30,0,U30+V30) -> #N/A | S32: =CHOOSE(MATCH(S31,B29:U29,0),B30-C30+D30,0,0,0,0,G30-H30+I30,0,0,0,0,L30-M30+N30,0,0,0,0,Q30+R30,0,S30+T30,0,U30+V30) -> #N/A | U32: =CHOOSE(MATCH(U31,B29:U29,0),B30-C30+D30,0,0,0,0,G30-H30+I30,0,0,0,0,L30-M30+N30,0,0,0,0,Q30+R30,0,S30+T30,0,U30+V30) -> #N/A
A33: 15 | Q33: =IF(OR(COUNTIF(AD31:AI31,0)>0,COUNTIF(AD33:AF33,0)>0),"",INDEX(AD31:AI31,MATCH(TRUE,ISNA(MATCH(AD31:AI31,AD33:AF33,0)),0))) | S33: =IF(OR(COUNTIF(AD31:AI31,0)>0,COUNTIF(AD33:AG33,0)>0),"",INDEX(AD31:AI31,MATCH(TRUE,ISNA(MATCH(AD31:AI31,AD33:AG33,0)),0))) | U33: =IF(OR(COUNTIF(AD31:AI31,0)>0,COUNTIF(AD33:AH33,0)>0),"",INDEX(AD31:AI31,MATCH(TRUE,ISNA(MATCH(AD31:AI31,AD33:AH33,0)),0))) | Y33: =IF(OR(A31="前置OD1",A31="后置OD1"),AK33,IF(OR(A31="前置OD2",A31="后置OD2"),AL33,IF(OR(A31="前置OD3",A31="后置OD3"),AM33,IF(LEFT(A33,2)="后置",Y31+E32+J32+O32+W31,Y31+E32+J32+O32+W31+X31)))) -> 0 | Z33: =IF(Y33<$AJ$4,Y33,$AJ$4) -> 0 | AA33: =F34+K34+P34 -> 0 | AD33: =B33 -> 0 | AE33: =G33 -> 0 | AF33: =L33 -> 0 | AG33: =Q33 | AH33: =S33 | AI33: =U33 | AK33: =Z31-$AJ$4/3+E32+J32+O32+X31 -> -100 | AL33: =Z31-$AJ$4/3*2+E32+J32+O32+X31 -> -200 | AM33: =Z31-$AJ$4+E32+J32+O32+X31 -> -300
B34: =CHOOSE(MATCH(B33,B31:U31,0),B32-C32+D32,0,0,0,0,G32-H32+I32,0,0,0,0,L32-M32+N32,0,0,0,0,Q32+R32,0,S32+T32,0,U32+V32) -> #N/A | G34: =CHOOSE(MATCH(G33,B31:U31,0),B32-C32+D32,0,0,0,0,G32-H32+I32,0,0,0,0,L32-M32+N32,0,0,0,0,Q32+R32,0,S32+T32,0,U32+V32) -> #N/A | L34: =CHOOSE(MATCH(L33,B31:U31,0),B32-C32+D32,0,0,0,0,G32-H32+I32,0,0,0,0,L32-M32+N32,0,0,0,0,Q32+R32,0,S32+T32,0,U32+V32) -> #N/A | Q34: =CHOOSE(MATCH(Q33,B31:U31,0),B32-C32+D32,0,0,0,0,G32-H32+I32,0,0,0,0,L32-M32+N32,0,0,0,0,Q32+R32,0,S32+T32,0,U32+V32) -> #N/A | S34: =CHOOSE(MATCH(S33,B31:U31,0),B32-C32+D32,0,0,0,0,G32-H32+I32,0,0,0,0,L32-M32+N32,0,0,0,0,Q32+R32,0,S32+T32,0,U32+V32) -> #N/A | U34: =CHOOSE(MATCH(U33,B31:U31,0),B32-C32+D32,0,0,0,0,G32-H32+I32,0,0,0,0,L32-M32+N32,0,0,0,0,Q32+R32,0,S32+T32,0,U32+V32) -> #N/A
A35: 16 | Q35: =IF(OR(COUNTIF(AD33:AI33,0)>0,COUNTIF(AD35:AF35,0)>0),"",INDEX(AD33:AI33,MATCH(TRUE,ISNA(MATCH(AD33:AI33,AD35:AF35,0)),0))) | S35: =IF(OR(COUNTIF(AD33:AI33,0)>0,COUNTIF(AD35:AG35,0)>0),"",INDEX(AD33:AI33,MATCH(TRUE,ISNA(MATCH(AD33:AI33,AD35:AG35,0)),0))) | U35: =IF(OR(COUNTIF(AD33:AI33,0)>0,COUNTIF(AD35:AH35,0)>0),"",INDEX(AD33:AI33,MATCH(TRUE,ISNA(MATCH(AD33:AI33,AD35:AH35,0)),0))) | Y35: =IF(OR(A33="前置OD1",A33="后置OD1"),AK35,IF(OR(A33="前置OD2",A33="后置OD2"),AL35,IF(OR(A33="前置OD3",A33="后置OD3"),AM35,IF(LEFT(A35,2)="后置",Y33+E34+J34+O34+W33,Y33+E34+J34+O34+W33+X33)))) -> 0 | Z35: =IF(Y35<$AJ$4,Y35,$AJ$4) -> 0 | AA35: =F36+K36+P36 -> 0 | AD35: =B35 -> 0 | AE35: =G35 -> 0 | AF35: =L35 -> 0 | AG35: =Q35 | AH35: =S35 | AI35: =U35 | AK35: =Z33-$AJ$4/3+E34+J34+O34+X33 -> -100 | AL35: =Z33-$AJ$4/3*2+E34+J34+O34+X33 -> -200 | AM35: =Z33-$AJ$4+E34+J34+O34+X33 -> -300
B36: =CHOOSE(MATCH(B35,B33:U33,0),B34-C34+D34,0,0,0,0,G34-H34+I34,0,0,0,0,L34-M34+N34,0,0,0,0,Q34+R34,0,S34+T34,0,U34+V34) -> #N/A | G36: =CHOOSE(MATCH(G35,B33:U33,0),B34-C34+D34,0,0,0,0,G34-H34+I34,0,0,0,0,L34-M34+N34,0,0,0,0,Q34+R34,0,S34+T34,0,U34+V34) -> #N/A | L36: =CHOOSE(MATCH(L35,B33:U33,0),B34-C34+D34,0,0,0,0,G34-H34+I34,0,0,0,0,L34-M34+N34,0,0,0,0,Q34+R34,0,S34+T34,0,U34+V34) -> #N/A | Q36: =CHOOSE(MATCH(Q35,B33:U33,0),B34-C34+D34,0,0,0,0,G34-H34+I34,0,0,0,0,L34-M34+N34,0,0,0,0,Q34+R34,0,S34+T34,0,U34+V34) -> #N/A | S36: =CHOOSE(MATCH(S35,B33:U33,0),B34-C34+D34,0,0,0,0,G34-H34+I34,0,0,0,0,L34-M34+N34,0,0,0,0,Q34+R34,0,S34+T34,0,U34+V34) -> #N/A | U36: =CHOOSE(MATCH(U35,B33:U33,0),B34-C34+D34,0,0,0,0,G34-H34+I34,0,0,0,0,L34-M34+N34,0,0,0,0,Q34+R34,0,S34+T34,0,U34+V34) -> #N/A
A37: 17 | Q37: =IF(OR(COUNTIF(AD35:AI35,0)>0,COUNTIF(AD37:AF37,0)>0),"",INDEX(AD35:AI35,MATCH(TRUE,ISNA(MATCH(AD35:AI35,AD37:AF37,0)),0))) | S37: =IF(OR(COUNTIF(AD35:AI35,0)>0,COUNTIF(AD37:AG37,0)>0),"",INDEX(AD35:AI35,MATCH(TRUE,ISNA(MATCH(AD35:AI35,AD37:AG37,0)),0))) | U37: =IF(OR(COUNTIF(AD35:AI35,0)>0,COUNTIF(AD37:AH37,0)>0),"",INDEX(AD35:AI35,MATCH(TRUE,ISNA(MATCH(AD35:AI35,AD37:AH37,0)),0))) | Y37: =IF(OR(A35="前置OD1",A35="后置OD1"),AK37,IF(OR(A35="前置OD2",A35="后置OD2"),AL37,IF(OR(A35="前置OD3",A35="后置OD3"),AM37,IF(LEFT(A37,2)="后置",Y35+E36+J36+O36+W35,Y35+E36+J36+O36+W35+X35)))) -> 0 | Z37: =IF(Y37<$AJ$4,Y37,$AJ$4) -> 0 | AA37: =F38+K38+P38 -> 0 | AD37: =B37 -> 0 | AE37: =G37 -> 0 | AF37: =L37 -> 0 | AG37: =Q37 | AH37: =S37 | AI37: =U37 | AK37: =Z35-$AJ$4/3+E36+J36+O36+X35 -> -100 | AL37: =Z35-$AJ$4/3*2+E36+J36+O36+X35 -> -200 | AM37: =Z35-$AJ$4+E36+J36+O36+X35 -> -300
B38: =CHOOSE(MATCH(B37,B35:U35,0),B36-C36+D36,0,0,0,0,G36-H36+I36,0,0,0,0,L36-M36+N36,0,0,0,0,Q36+R36,0,S36+T36,0,U36+V36) -> #N/A | G38: =CHOOSE(MATCH(G37,B35:U35,0),B36-C36+D36,0,0,0,0,G36-H36+I36,0,0,0,0,L36-M36+N36,0,0,0,0,Q36+R36,0,S36+T36,0,U36+V36) -> #N/A | L38: =CHOOSE(MATCH(L37,B35:U35,0),B36-C36+D36,0,0,0,0,G36-H36+I36,0,0,0,0,L36-M36+N36,0,0,0,0,Q36+R36,0,S36+T36,0,U36+V36) -> #N/A | Q38: =CHOOSE(MATCH(Q37,B35:U35,0),B36-C36+D36,0,0,0,0,G36-H36+I36,0,0,0,0,L36-M36+N36,0,0,0,0,Q36+R36,0,S36+T36,0,U36+V36) -> #N/A | S38: =CHOOSE(MATCH(S37,B35:U35,0),B36-C36+D36,0,0,0,0,G36-H36+I36,0,0,0,0,L36-M36+N36,0,0,0,0,Q36+R36,0,S36+T36,0,U36+V36) -> #N/A | U38: =CHOOSE(MATCH(U37,B35:U35,0),B36-C36+D36,0,0,0,0,G36-H36+I36,0,0,0,0,L36-M36+N36,0,0,0,0,Q36+R36,0,S36+T36,0,U36+V36) -> #N/A
A39: 18 | Q39: =IF(OR(COUNTIF(AD37:AI37,0)>0,COUNTIF(AD39:AF39,0)>0),"",INDEX(AD37:AI37,MATCH(TRUE,ISNA(MATCH(AD37:AI37,AD39:AF39,0)),0))) | S39: =IF(OR(COUNTIF(AD37:AI37,0)>0,COUNTIF(AD39:AG39,0)>0),"",INDEX(AD37:AI37,MATCH(TRUE,ISNA(MATCH(AD37:AI37,AD39:AG39,0)),0))) | U39: =IF(OR(COUNTIF(AD37:AI37,0)>0,COUNTIF(AD39:AH39,0)>0),"",INDEX(AD37:AI37,MATCH(TRUE,ISNA(MATCH(AD37:AI37,AD39:AH39,0)),0))) | Y39: =IF(OR(A37="前置OD1",A37="后置OD1"),AK39,IF(OR(A37="前置OD2",A37="后置OD2"),AL39,IF(OR(A37="前置OD3",A37="后置OD3"),AM39,IF(LEFT(A39,2)="后置",Y37+E38+J38+O38+W37,Y37+E38+J38+O38+W37+X37)))) -> 0 | Z39: =IF(Y39<$AJ$4,Y39,$AJ$4) -> 0 | AA39: =F40+K40+P40 -> 0 | AD39: =B39 -> 0 | AE39: =G39 -> 0 | AF39: =L39 -> 0 | AG39: =Q39 | AH39: =S39 | AI39: =U39 | AK39: =Z37-$AJ$4/3+E38+J38+O38+X37 -> -100 | AL39: =Z37-$AJ$4/3*2+E38+J38+O38+X37 -> -200 | AM39: =Z37-$AJ$4+E38+J38+O38+X37 -> -300
B40: =CHOOSE(MATCH(B39,B37:U37,0),B38-C38+D38,0,0,0,0,G38-H38+I38,0,0,0,0,L38-M38+N38,0,0,0,0,Q38+R38,0,S38+T38,0,U38+V38) -> #N/A | G40: =CHOOSE(MATCH(G39,B37:U37,0),B38-C38+D38,0,0,0,0,G38-H38+I38,0,0,0,0,L38-M38+N38,0,0,0,0,Q38+R38,0,S38+T38,0,U38+V38) -> #N/A | L40: =CHOOSE(MATCH(L39,B37:U37,0),B38-C38+D38,0,0,0,0,G38-H38+I38,0,0,0,0,L38-M38+N38,0,0,0,0,Q38+R38,0,S38+T38,0,U38+V38) -> #N/A | Q40: =CHOOSE(MATCH(Q39,B37:U37,0),B38-C38+D38,0,0,0,0,G38-H38+I38,0,0,0,0,L38-M38+N38,0,0,0,0,Q38+R38,0,S38+T38,0,U38+V38) -> #N/A | S40: =CHOOSE(MATCH(S39,B37:U37,0),B38-C38+D38,0,0,0,0,G38-H38+I38,0,0,0,0,L38-M38+N38,0,0,0,0,Q38+R38,0,S38+T38,0,U38+V38) -> #N/A | U40: =CHOOSE(MATCH(U39,B37:U37,0),B38-C38+D38,0,0,0,0,G38-H38+I38,0,0,0,0,L38-M38+N38,0,0,0,0,Q38+R38,0,S38+T38,0,U38+V38) -> #N/A
...

Sheet 简轴
A1: 【标题】（比如 第xx期打分 xx队 无限od流） | G1: 轴作者
A2: 队伍组成（前 | 后） | C2: =_xlfn.TEXTJOIN(" ",TRUE,排轴!B3,排轴!G3,排轴!L3) | E2: =_xlfn.TEXTJOIN(" ",TRUE,排轴!Q3,排轴!S3,排轴!U3)
A3: 【注意事项】（比如耳环、突破要求等）
A6: 回合 | B6: 行动轴 | H6: 当前OD | I6: P
A7: =排轴!A5 -> 1 | B7: =排轴!B5 -> 0 | C7: =排轴!C5 -> 0 | D7: =排轴!G5 -> 0 | E7: =排轴!H5 -> 0 | F7: =排轴!L5 -> 0 | G7: =排轴!M5 -> 0 | H7: =排轴!Y5 -> 0 | I7: ☐
A8: =排轴!A7 -> 0 | B8: =排轴!B7 -> 0 | C8: =排轴!C7 -> 0 | D8: =排轴!G7 -> 0 | E8: =排轴!H7 -> 0 | F8: =排轴!L7 -> 0 | G8: =排轴!M7 -> 0 | H8: =排轴!Y7 -> 0 | I8: ☐
A9: =排轴!A9 -> 0 | B9: =排轴!B9 -> 0 | C9: =排轴!C9 -> 0 | D9: =排轴!G9 -> 0 | E9: =排轴!H9 -> 0 | F9: =排轴!L9 -> 0 | G9: =排轴!M9 -> 0 | H9: =排轴!Y9 -> 0 | I9: ☐
A10: =排轴!A11 -> 0 | B10: =排轴!B11 -> 0 | C10: =排轴!C11 -> 0 | D10: =排轴!G11 -> 0 | E10: =排轴!H11 -> 0 | F10: =排轴!L11 -> 0 | G10: =排轴!M11 -> 0 | H10: =排轴!Y11 -> 0 | I10: ☐
A11: =排轴!A13 -> 0 | B11: =排轴!B13 -> 0 | C11: =排轴!C13 -> 0 | D11: =排轴!G13 -> 0 | E11: =排轴!H13 -> 0 | F11: =排轴!L13 -> 0 | G11: =排轴!M13 -> 0 | H11: =排轴!Y13 -> 0 | I11: ☐
A12: =排轴!A15 -> 0 | B12: =排轴!B15 -> 0 | C12: =排轴!C15 -> 0 | D12: =排轴!G15 -> 0 | E12: =排轴!H15 -> 0 | F12: =排轴!L15 -> 0 | G12: =排轴!M15 -> 0 | H12: =排轴!Y15 -> 0 | I12: ☐
A13: =排轴!A17 -> 7 | B13: =排轴!B17 -> 0 | C13: =排轴!C17 -> 0 | D13: =排轴!G17 -> 0 | E13: =排轴!H17 -> 0 | F13: =排轴!L17 -> 0 | G13: =排轴!M17 -> 0 | H13: =排轴!Y17 -> 0 | I13: ☐
A14: =排轴!A19 -> 8 | B14: =排轴!B19 -> 0 | C14: =排轴!C19 -> 0 | D14: =排轴!G19 -> 0 | E14: =排轴!H19 -> 0 | F14: =排轴!L19 -> 0 | G14: =排轴!M19 -> 0 | H14: =排轴!Y19 -> 0 | I14: ☐
A15: =排轴!A21 -> 9 | B15: =排轴!B21 -> 0 | C15: =排轴!C21 -> 0 | D15: =排轴!G21 -> 0 | E15: =排轴!H21 -> 0 | F15: =排轴!L21 -> 0 | G15: =排轴!M21 -> 0 | H15: =排轴!Y21 -> 0 | I15: ☐
A16: =排轴!A23 -> 10 | B16: =排轴!B23 -> 0 | C16: =排轴!C23 -> 0 | D16: =排轴!G23 -> 0 | E16: =排轴!H23 -> 0 | F16: =排轴!L23 -> 0 | G16: =排轴!M23 -> 0 | H16: =排轴!Y23 -> 0 | I16: ☐
A17: =排轴!A25 -> 11 | B17: =排轴!B25 -> 0 | C17: =排轴!C25 -> 0 | D17: =排轴!G25 -> 0 | E17: =排轴!H25 -> 0 | F17: =排轴!L25 -> 0 | G17: =排轴!M25 -> 0 | H17: =排轴!Y25 -> 0 | I17: ☐
A18: =排轴!A27 -> 12 | B18: =排轴!B27 -> 0 | C18: =排轴!C27 -> 0 | D18: =排轴!G27 -> 0 | E18: =排轴!H27 -> 0 | F18: =排轴!L27 -> 0 | G18: =排轴!M27 -> 0 | H18: =排轴!Y27 -> 0 | I18: ☐
A19: =排轴!A29 -> 13 | B19: =排轴!B29 -> 0 | C19: =排轴!C29 -> 0 | D19: =排轴!G29 -> 0 | E19: =排轴!H29 -> 0 | F19: =排轴!L29 -> 0 | G19: =排轴!M29 -> 0 | H19: =排轴!Y29 -> 0 | I19: ☐
A20: =排轴!A31 -> 14 | B20: =排轴!B31 -> 0 | C20: =排轴!C31 -> 0 | D20: =排轴!G31 -> 0 | E20: =排轴!H31 -> 0 | F20: =排轴!L31 -> 0 | G20: =排轴!M31 -> 0 | H20: =排轴!Y31 -> 0 | I20: ☐
A21: =排轴!A33 -> 15 | B21: =排轴!B33 -> 0 | C21: =排轴!C33 -> 0 | D21: =排轴!G33 -> 0 | E21: =排轴!H33 -> 0 | F21: =排轴!L33 -> 0 | G21: =排轴!M33 -> 0 | H21: =排轴!Y33 -> 0 | I21: ☐
A22: =排轴!A35 -> 16 | B22: =排轴!B35 -> 0 | C22: =排轴!C35 -> 0 | D22: =排轴!G35 -> 0 | E22: =排轴!H35 -> 0 | F22: =排轴!L35 -> 0 | G22: =排轴!M35 -> 0 | H22: =排轴!Y35 -> 0 | I22: ☐
A23: =排轴!A37 -> 17 | B23: =排轴!B37 -> 0 | C23: =排轴!C37 -> 0 | D23: =排轴!G37 -> 0 | E23: =排轴!H37 -> 0 | F23: =排轴!L37 -> 0 | G23: =排轴!M37 -> 0 | H23: =排轴!Y37 -> 0 | I23: ☐
A24: =排轴!A39 -> 18 | B24: =排轴!B39 -> 0 | C24: =排轴!C39 -> 0 | D24: =排轴!G39 -> 0 | E24: =排轴!H39 -> 0 | F24: =排轴!L39 -> 0 | G24: =排轴!M39 -> 0 | H24: =排轴!Y39 -> 0 | I24: ☐
A25: =排轴!A41 -> 19 | B25: =排轴!B41 -> 0 | C25: =排轴!C41 -> 0 | D25: =排轴!G41 -> 0 | E25: =排轴!H41 -> 0 | F25: =排轴!L41 -> 0 | G25: =排轴!M41 -> 0 | H25: =排轴!Y41 -> 0 | I25: ☐
A26: =排轴!A43 -> 20 | B26: =排轴!B43 -> 0 | C26: =排轴!C43 -> 0 | D26: =排轴!G43 -> 0 | E26: =排轴!H43 -> 0 | F26: =排轴!L43 -> 0 | G26: =排轴!M43 -> 0 | H26: =排轴!Y43 -> 0 | I26: ☐
